File: Module2/HalfSecSinus.txt
SAMPLE PARAMETERS
Gauge length [mm]: 24.1614
Area [mm2]: 72.7888
EXPERIMENTAL PARAMETERS
Time [s]: 2.5
Number of steps: 1000
Displacement (0) or force control (1): 0
Schedule ID: 0
Omega: 12.5664
Amplitude: 0.5
RESULTS
Time [s],Displacement [mm],Force [N]
0.,0.,1.6550257460093738e-11
0.0025,0.00024671981713423225,0.004071937995389363
0.005,0.0009866357858642238,0.016038760140687756
0.0075,0.0022190176984600244,0.03542968077593252
0.01,0.003942649342761033,0.061825157961352704
0.0125,0.006155829702431095,0.09485125217888697
0.015,0.008856374635655698,0.13417521165936805
0.0175,0.012041619030626373,0.17950213182020552
0.02,0.015708419435684493,0.2305725614575895
0.0225,0.019853157161528506,0.287160948957974
0.025,0.02447174185242324,0.3490748219122212
0.0275,0.02955961552288731,0.4161546013550984
0.03,0.03511175705587435,0.48827394978377753
0.0325,0.04112268715800944,0.5653405537700511
0.035,0.04758647376699031,0.6472972419271966
0.0375,0.054496737905816085,0.7341233400051195
0.04,0.06184665997806825,0.8258361675723014
0.0425,0.06962898649802826,0.9224925805111145
0.045,0.0778360372489925,1.0241904686351564
0.0475,0.08645971286271918,1.1310701189672663
0.05,0.09549150281252629,1.2433153605491905
0.0525,0.10492249381215485,1.3611544112128091
0.055,0.1147433786121054,1.484860349401479
0.0575,0.12494446518477025,1.6147511458822814
0.06,0.1355156862892943,1.7511891901142786
0.0625,0.14644660940672627,1.8945802590331766
0.065,0.1577264470356557,2.045371884238389
0.0675,0.16934406733817411,2.2040510795281967
0.07,0.1812880051256552,2.3711414070118133
0.0725,0.19354647317351184,2.5471993663449775
0.075,0.2061073738537635,2.7328101083643572
0.0775,0.2189583110739347,2.928582484515433
0.08,0.23208660251050175,3.135143457731732
0.0825,0.24547929212481442,3.353131915183504
0.085,0.25912316294914245,3.5831919352764388
0.08750000000000001,0.2730047501302266,3.8259655765569582
0.09,0.2871103542174637,4.082085266217957
0.0925,0.3014260546826098,4.352165879483577
0.095,0.31593772365766115,4.636796610149934
0.0975,0.3306310398773544,4.936532740328181
0.1,0.34549150281252633,5.251887422228242
0.10250000000000001,0.3605044469803854,5.5833235922336835
0.105,0.3756550564175727,5.931246130376483
0.1075,0.3909283793017288,6.295994384456617
0.11,0.40630934270713787,6.67783516598968
0.1125,0.4217827674798847,7.076956320862676
0.115,0.437333383217848,7.493460965350928
0.11750000000000001,0.45294584334074295,7.927362465982647
0.12,0.46860474023534343,8.378580225921826
0.1225,0.48429462046093597,8.84693632618316
0.125,0.5000000000000001,9.332153050101933
0.1275,0.5157053795390641,9.833851306771543
0.13,0.5313952597646567,10.351549948190026
0.1325,0.5470541566592573,10.884665961853267
0.135,0.5626666167821522,11.432515505755122
0.1375,0.5782172325201156,11.994315740136644
0.14,0.5936906572928625,12.569187400676302
0.14250000000000002,0.6090716206982714,13.156158051379242
0.145,0.6243449435824275,13.754165947317695
0.1475,0.6394955530196147,14.3620644388675
0.15,0.654508497187474,14.978626845773276
0.1525,0.6693689601226458,15.602551733507584
0.155,0.6840622763423391,16.232468525832985
0.1575,0.6985739453173905,16.86694339479609
0.16,0.7128896457825366,17.50448537428865
0.1625,0.7269952498697735,18.143552649650523
0.165,0.7408768370508578,18.782558983884343
0.1675,0.7545207078751858,19.419880246671642
0.17,0.7679133974894986,20.053861018654246
0.17250000000000001,0.7810416889260654,20.68282125024615
0.17500000000000002,0.7938926261462367,21.305062956716764
0.1775,0.8064535268264884,21.918876937821206
0.18,0.8187119948743449,22.522549509202733
0.1825,0.8306559326618261,23.114369238363576
0.185,0.8422735529643446,23.69263367499633
0.1875,0.8535533905932737,24.255656067627797
0.19,0.864484313710706,24.801772055557404
0.1925,0.8750555348152299,25.329346325527435
0.195,0.885256621387895,25.8367792174043
0.1975,0.8950775061878452,26.322513263005472
0.2,0.9045084971874738,26.78503963938827
0.2025,0.9135402871372811,27.22290451293864
0.20500000000000002,0.9221639627510075,27.63471525085205
0.20750000000000002,0.9303710135019719,28.019146472693173
0.21,0.9381533400219318,28.374945912579175
0.2125,0.9455032620941841,28.70094006173825
0.215,0.9524135262330099,28.996039559395108
0.2175,0.9588773128419906,29.259244299163235
0.22,0.9648882429441258,29.489648218482092
0.2225,0.9704403844771129,29.686443738140113
0.225,0.9755282581475768,29.84892582030257
0.2275,0.9801468428384716,29.976495614584234
0.23,0.9842915805643156,30.06866366321738
0.2325,0.9879583809693738,30.125052638224645
0.23500000000000001,0.9911436253643445,30.145399586577877
0.23750000000000002,0.9938441702975689,30.129557661135056
0.24,0.996057350657239,30.077497319299706
0.2425,0.9977809823015401,29.989306973384753
0.245,0.9990133642141359,29.865193079985747
0.2475,0.9997532801828659,29.705479661105468
0.25,1.,29.510607249921907
0.2525,0.9997532801828659,29.281131261115146
0.255,0.9990133642141359,29.01771978684834
0.2575,0.9977809823015401,28.72115082403694
0.26,0.996057350657239,28.392308942639758
0.2625,0.9938441702975689,28.03218140632708
0.265,0.9911436253643444,27.641853761940194
0.2675,0.9879583809693738,27.222504917266882
0.27,0.9842915805643156,26.80034736200929
0.2725,0.9801468428384715,26.35485908873541
0.275,0.9755282581475768,25.884379444822887
0.2775,0.9704403844771127,25.39037654599857
0.28,0.9648882429441258,24.87438005214056
0.28250000000000003,0.9588773128419905,24.33797373693027
0.28500000000000003,0.9524135262330097,23.782787764733175
0.28750000000000003,0.9455032620941839,23.210490714931943
0.29,0.9381533400219318,22.622781397923454
0.2925,0.9303710135019718,22.021380505785796
0.295,0.9221639627510075,21.408022144320476
0.2975,0.9135402871372809,20.784445294389005
0.3,0.9045084971874736,20.152385250554584
0.3025,0.8950775061878452,19.513565087839293
0.305,0.8852566213878946,18.869687207656405
0.3075,0.8750555348152297,18.222425014605975
0.31,0.8644843137107058,17.57341477786545
0.3125,0.8535533905932737,16.924247729787513
0.315,0.8422735529643444,16.276462456610805
0.3175,0.8306559326618258,15.63153763523635
0.32,0.8187119948743449,14.99088517050964
0.3225,0.8064535268264883,14.355843787706108
0.325,0.7938926261462367,13.727673133674644
0.3275,0.7810416889260651,13.107548439698208
0.33,0.7679133974894983,12.496555797868021
0.3325,0.7545207078751855,11.895688100823367
0.335,0.7408768370508577,11.305841692272208
0.3375,0.7269952498697735,10.72781377259541
0.34,0.7128896457825361,10.16230059972614
0.3425,0.6985739453173901,9.609896521043039
0.34500000000000003,0.684062276342339,9.07109386540726
0.34750000000000003,0.6693689601226457,8.546283717895662
0.35000000000000003,0.6545084971874738,8.035757591693416
0.3525,0.6394955530196144,7.5397100015529475
0.355,0.6243449435824273,7.0582419331515895
0.3575,0.6090716206982713,6.653254445046609
0.36,0.5936906572928623,6.263387913295502
0.3625,0.5782172325201156,5.888685573661112
0.365,0.5626666167821518,5.529270255061854
0.3675,0.5470541566592569,5.185189962042889
0.37,0.5313952597646566,4.856420905905637
0.3725,0.5157053795390641,4.542870916975448
0.375,0.5000000000000001,4.244383206651465
0.3775,0.48429462046093563,3.9607404457869926
0.38,0.46860474023534315,3.691669122643024
0.3825,0.4529458433407428,3.4368441432054375
0.385,0.43733338321784787,3.1958936338398427
0.3875,0.4217827674798847,2.968403905812554
0.39,0.4063093427071374,2.7539245395139598
0.3925,0.3909283793017285,2.5519735463761255
0.395,0.3756550564175725,2.3620425652871986
0.3975,0.3605044469803854,2.1836020515147956
0.4,0.3454915028125264,2.0161064154789106
0.4025,0.3306310398773541,1.8589990705380353
0.405,0.3159377236576609,1.7117173496661904
0.40750000000000003,0.30142605468260963,1.573697252546768
0.41000000000000003,0.2871103542174637,1.4443779865963116
0.41250000000000003,0.2730047501302263,1.3232062681734464
0.41500000000000004,0.2591231629491421,1.209640352120055
0.4175,0.2454792921248142,1.103153761149231
0.42,0.23208660251050162,1.0032386902489825
0.4225,0.2189583110739347,0.909409063529872
0.425,0.20610737385376315,0.8212032265394847
0.4275,0.19354647317351154,0.7381862586690437
0.43,0.18128800512565502,0.6599518965136305
0.4325,0.16934406733817398,0.5861240617511903
0.435,0.15772644703565566,0.5163579917522025
0.4375,0.14644660940672602,0.45466612343637164
0.44,0.13551568628929408,0.4150881154544539
0.4425,0.12494446518477008,0.3780530162398772
0.445,0.11474337861210532,0.3433824765876235
0.4475,0.10492249381215485,0.31091545100557105
0.45,0.09549150281252604,0.280507921323331
0.4525,0.08645971286271892,0.25203244846395145
0.455,0.07783603724899234,0.22537756666813377
0.4575,0.0696289864980281,0.2004470365084165
0.46,0.06184665997806825,0.17715897360083568
0.4625,0.05449673790581592,0.15544487141538435
0.465,0.04758647376699014,0.13524853736668452
0.4675,0.041122687158009354,0.11652496151540323
0.47000000000000003,0.035111757055874264,0.09923913830955064
0.47250000000000003,0.02955961552288731,0.08336486110001863
0.47500000000000003,0.024471741852423158,0.06888350979687576
0.47750000000000004,0.019853157161528422,0.05578285098898299
0.48,0.01570841943568441,0.044055869951559815
0.4825,0.012041619030626288,0.033699652437617494
0.485,0.008856374635655615,0.02471433376734663
0.4875,0.006155829702431095,0.017102131157618584
0.49,0.003942649342761033,0.01086647384883848
0.4925,0.0022190176984600244,0.006011244013222016
0.495,0.0009866357858642238,0.0025423493748521573
0.4975,0.00024671981713423225,0.0005839477668582207
0.5,0.,2.1510980998079795e-12
0.5025000000000001,0.00024671981713423225,0.0005839477568919555
0.505,0.0009866357858642238,0.0025423492127737975
0.5075000000000001,0.0022190176984600244,0.006011242814687453
0.51,0.003942649342761033,0.010866469781752049
0.5125,0.006155829702431179,0.017102121787159873
0.515,0.008856374635655698,0.02471431604225364
0.5175,0.012041619030626373,0.03369962267950056
0.52,0.015708419435684493,0.04405582385791682
0.5225,0.019853157161528506,0.05578278360059084
0.525,0.024471741852423325,0.06888341545024199
0.5275,0.02955961552288731,0.08336473339216488
0.53,0.03511175705587435,0.09923897001266767
0.5325,0.04112268715800952,0.11652474448704182
0.535,0.047586473766990225,0.1352482624144237
0.5375,0.05449673790581625,0.15544452813985438
0.54,0.06184665997806834,0.17715855019514185
0.5425,0.06962898649802826,0.20044651951740683
0.545,0.0778360372489925,0.2253769406922895
0.5475,0.0864597128627191,0.25203169580654206
0.55,0.09549150281252654,0.28050702159177743
0.5525,0.10492249381215493,0.31091438061233595
0.555,0.11474337861210548,0.34338120821068785
0.5575,0.12494446518477025,0.37805151817148974
0.56,0.13551568628929458,0.415086350870509
0.5625,0.14644660940672652,0.4546640495580568
0.5650000000000001,0.15772644703565586,0.5163459933428528
0.5675,0.16934406733817423,0.5860802192533789
0.5700000000000001,0.1812880051256552,0.6598505631198507
0.5725,0.19354647317351212,0.7379994029338736
0.5750000000000001,0.20610737385376374,0.820899507321318
0.5775,0.21895831107393487,0.908952762054766
0.58,0.23208660251050187,1.0025884892934038
0.5825,0.24547929212481442,1.102261359898281
0.585,0.2591231629491427,1.208448904305279
0.5875,0.27300475013022696,1.3216486301416799
0.59,0.2871103542174639,1.4423747609952482
0.5925,0.30142605468260986,1.571154613067161
0.595,0.3159377236576611,1.7085246323522982
0.5975,0.33063103987735476,1.8550261170644373
0.6,0.3454915028125266,2.0112006556874062
0.6025,0.36050444698038564,2.177585313333405
0.605,0.3756550564175728,2.3547076028673426
0.6075,0.3909283793017288,2.5430802804828767
0.61,0.4063093427071381,2.743196007735585
0.6125,0.42178276747988497,2.9555219248206184
0.615,0.43733338321784815,3.180494181468459
0.6175,0.45294584334074306,3.4185124736671924
0.62,0.46860474023534343,3.6699346353948394
0.6225,0.4842946204609363,3.9350713352701336
0.625,0.5000000000000003,4.214180928084058
0.6275000000000001,0.5157053795390645,4.507464511293311
0.63,0.531395259764657,4.815061234728131
0.6325000000000001,0.5470541566592573,5.137043912376999
0.635,0.5626666167821526,5.473414980700427
0.6375000000000001,0.5782172325201158,5.824102848558055
0.64,0.5936906572928625,6.188958678695448
0.6425,0.6090716206982715,6.567753639337565
0.645,0.6243449435824275,6.960332672273479
0.6475,0.6394955530196147,7.427534267909556
0.65,0.6545084971874736,7.906918676607666
0.6525,0.6693689601226464,8.398216419567593
0.655,0.6840622763423396,8.901029262181922
0.6575,0.6985739453173908,9.414829637209333
0.66,0.7128896457825368,9.938961049860822
0.6625,0.7269952498697738,10.472639519067672
0.665,0.7408768370508578,11.014956093721743
0.6675,0.7545207078751859,11.564880466231058
0.67,0.7679133974894984,12.121265688957468
0.6725,0.7810416889260654,12.68285398010372
0.675,0.7938926261462365,13.248283589079092
0.6775,0.806453526826489,13.816096672362201
0.68,0.8187119948743454,14.384748114895599
0.6825,0.8306559326618264,14.952615215757515
0.685,0.8422735529643447,15.51800814380323
0.6875,0.8535533905932741,16.07918105594884
0.6900000000000001,0.864484313710706,16.63434376171856
0.6925,0.8750555348152299,17.18167381087454
0.6950000000000001,0.8852566213878946,17.71932887551518
0.6975,0.8950775061878452,18.24545929702278
0.7000000000000001,0.9045084971874736,18.758220668122725
0.7025,0.9135402871372814,19.255786324261233
0.705,0.9221639627510079,19.736359622741833
0.7075,0.9303710135019722,20.198185895991966
0.71,0.938153340021932,20.63956397369194
0.7125,0.9455032620941841,21.058857177885674
0.715,0.95241352623301,21.454503707062134
0.7175,0.9588773128419908,21.82502633539775
0.72,0.9648882429441258,22.16904136507314
0.7225,0.9704403844771127,22.485266781238412
0.725,0.9755282581475768,22.772529569808277
0.7275,0.9801468428384719,23.029772168784703
0.73,0.9842915805643156,23.256058033705912
0.7325,0.9879583809693738,23.45324403398602
0.735,0.9911436253643445,23.638958433101543
0.7375,0.9938441702975689,23.784995323347356
0.74,0.996057350657239,23.891774817604247
0.7425,0.9977809823015401,23.95974847607424
0.745,0.9990133642141359,23.989414394950117
0.7475,0.9997532801828659,23.981328360912265
0.75,1.,23.936112161665037
0.7525000000000001,0.9997532801828659,23.85445970837939
0.755,0.9990133642141357,23.737141368287524
0.7575000000000001,0.9977809823015401,23.585006761704413
0.76,0.996057350657239,23.39898619116809
0.7625000000000001,0.9938441702975689,23.192813581976164
0.765,0.9911436253643444,22.96084092263581
0.7675000000000001,0.9879583809693737,22.69950913198442
0.77,0.9842915805643156,22.409881098186357
0.7725,0.9801468428384715,22.093111172606335
0.775,0.9755282581475768,21.750437793833626
0.7775,0.9704403844771127,21.38317572911164
0.78,0.9648882429441255,20.992707976452927
0.7825,0.9588773128419905,20.58047737334968
0.785,0.9524135262330097,20.14797795924328
0.7875,0.9455032620941838,19.69674613856335
0.79,0.9381533400219318,19.228351694962747
0.7925,0.9303710135019718,18.744388706773425
0.795,0.9221639627510075,18.246466416430106
0.7975,0.9135402871372811,17.736200107211236
0.8,0.904508497187474,17.21520204297054
0.8025,0.8950775061878449,16.68507252721483
0.805,0.8852566213878943,16.14739113973523
0.8075,0.8750555348152296,15.603708209839182
0.81,0.8644843137107057,15.055536587157746
0.8125,0.8535533905932736,14.504343770169097
0.8150000000000001,0.8422735529643443,13.95154445538185
0.8175,0.830655932661826,13.398493567713443
0.8200000000000001,0.8187119948743449,12.846479834618604
0.8225,0.8064535268264884,12.296719963728274
0.8250000000000001,0.793892626146236,11.75035348289446
0.8275,0.7810416889260648,11.2084382988738
0.8300000000000001,0.7679133974894979,10.671947027191862
0.8325,0.7545207078751853,10.141764141484558
0.835,0.7408768370508574,9.661533823532945
0.8375,0.7269952498697733,9.202566230579546
0.84,0.7128896457825361,8.753109338143375
0.8425,0.6985739453173903,8.31395525955386
0.845,0.684062276342339,7.885817762814623
0.8475,0.6693689601226458,7.469331037830609
0.85,0.6545084971874731,7.0650489925552655
0.8525,0.639495553019614,6.6734450753622285
0.855,0.624344943582427,6.294912617450016
0.8575,0.6090716206982709,5.929765685412094
0.86,0.593690657292862,5.578240430584762
0.8625,0.5782172325201153,5.2404969178015115
0.865,0.562666616782152,4.91662141350594
0.8675,0.5470541566592572,4.6066291092248415
0.87,0.5313952597646567,4.310467253377894
0.8725,0.5157053795390643,4.02801866192357
0.875,0.4999999999999994,3.7591055746655084
0.8775000000000001,0.4842946204609353,3.503493822717238
0.88,0.4686047402353428,3.260897268925951
0.8825000000000001,0.45294584334074245,3.030982482741283
0.885,0.43733338321784754,2.813373607639509
0.8875000000000001,0.42178276747988436,2.6076573795286415
0.89,0.40630934270713753,2.4133882522803853
0.8925000000000001,0.3909283793017287,2.230093586701283
0.895,0.37565505641757263,2.0572788586549438
0.8975,0.36050444698038553,1.8944328426678805
0.9,0.34549150281252566,1.7410327270983086
0.9025,0.33063103987735376,1.596549118938838
0.905,0.3159377236576606,1.4604508969936936
0.9075,0.3014260546826093,1.3322098738862083
0.91,0.2871103542174634,1.211305230235817
0.9125,0.2730047501302264,1.0972276857390524
0.915,0.2591231629491422,0.9894833760465388
0.9175,0.24547929212481429,0.8893914568099865
0.92,0.23208660251050175,0.8210584683688688
0.9225,0.2189583110739348,0.7572844943872143
0.925,0.2061073738537629,0.6977668696634278
0.9275,0.19354647317351129,0.6422151118040296
0.93,0.18128800512565474,0.590352320512266
0.9325,0.16934406733817378,0.541916357937511
0.935,0.15772644703565544,0.4966608081562812
0.9375,0.14644660940672605,0.4543557163151513
0.9400000000000001,0.1355156862892941,0.4147881105974856
0.9425,0.1249444651847702,0.37776231149389405
0.9450000000000001,0.1147433786121054,0.34310003592940685
0.9475,0.10492249381215493,0.31064030537851717
0.9500000000000001,0.09549150281252587,0.28023916909125407
0.9525,0.08645971286271875,0.2517692554606673
0.9550000000000001,0.07783603724899217,0.22511916587361064
0.9575,0.06962898649802793,0.20019272734091992
0.96,0.06184665997806808,0.17690812081247154
0.9625,0.05449673790581592,0.15519690362158847
0.965,0.04758647376699014,0.13500294523363152
0.9675,0.04112268715800944,0.11628129556883983
0.97,0.03511175705587435,0.09899700641408986
0.9725,0.029559615522886978,0.08312392562095573
0.975,0.024471741852422988,0.06864348443860929
0.9775,0.01985315716152834,0.055543497366043394
0.98,0.015708419435684327,0.043816993868794174
0.9825,0.012041619030626205,0.033461099949486574
0.985,0.008856374635655615,0.02447598697265203
0.9875,0.006155829702431095,0.01686390381613809
0.99,0.003942649342761033,0.010628306828764193
0.9925,0.0022190176984600244,0.005773100565635513
0.995,0.0009866357858642238,0.002473327207319169
0.9975,0.00024671981713423225,0.0005656526792349542
1.,0.,2.1510980998079795e-12
1.0025,0.00024671981713423225,0.0005656526792349542
1.0050000000000001,0.0009866357858643077,0.002473327100035088
1.0075,0.0022190176984600244,0.0057730999250365286
1.01,0.003942649342761117,0.010628304272345497
1.0125,0.006155829702431179,0.0168638969031083
1.0150000000000001,0.008856374635655698,0.024475972652735805
1.0175,0.012041619030626373,0.033461074557119955
1.02,0.01570841943568441,0.043816953109163496
1.0225,0.019853157161528672,0.05554343627998053
1.025,0.024471741852423408,0.0686433973929389
1.0275,0.02955961552288748,0.08312380623786511
1.03,0.035111757055874514,0.09899684750406663
1.0325,0.0411226871580096,0.1162810890328426
1.035,0.04758647376699039,0.13500268194239876
1.0375,0.05449673790581617,0.15519657324891697
1.04,0.06184665997806825,0.17690771164680802
1.0425,0.06962898649802818,0.20019222603902825
1.045,0.0778360372489925,0.2251185571715424
1.0475,0.08645971286271951,0.2517685218224117
1.05,0.0954915028125267,0.28023829031109254
1.0525,0.10492249381215518,0.310639258096533
1.055,0.11474337861210573,0.3430987930772049
1.0575,0.1249444651847705,0.3777608416648286
1.06,0.13551568628929447,0.4147863773044764
1.0625,0.1464466094067264,0.45435367717656405
1.065,0.15772644703565575,0.49665841393261717
1.0675000000000001,0.16934406733817411,0.5419135514820917
1.07,0.18128800512565516,0.5903490355559735
1.0725,0.19354647317351237,0.6422112716197749
1.075,0.206107373853764,0.6977623855456968
1.0775000000000001,0.21895831107393518,0.7572792640201857
1.08,0.23208660251050212,0.8210523739004227
1.0825,0.2454792921248147,0.8893843628481262
1.085,0.2591231629491426,0.9894618382427285
1.0875000000000001,0.2730047501302268,1.097163308938904
1.09,0.2871103542174638,1.2111665804217198
1.0925,0.30142605468260975,1.3319620958997267
1.095,0.315937723657661,1.4600543106773543
1.0975,0.33063103987735504,1.595957670440792
1.1,0.34549150281252694,1.740192285458278
1.1025,0.3605044469803859,1.8932793320380426
1.105,0.3756550564175731,2.055736215505373
1.1075,0.39092837930172913,2.2280715325841562
1.11,0.40630934270713803,2.4107798734056476
1.1125,0.4217827674798848,2.6043365062721144
1.115,0.43733338321784804,2.8091919897631232
1.1175,0.4529458433407429,3.0257667590033916
1.12,0.46860474023534415,3.2544457340575876
1.1225,0.48429462046093663,3.495572999071623
1.125,0.5000000000000007,3.7494466011021825
1.1275,0.5157053795390648,4.0163135183761085
1.1300000000000001,0.5313952597646572,4.296364845656183
1.1325,0.5470541566592575,4.589731245174096
1.135,0.5626666167821525,4.896478708297504
1.1375,0.5782172325201156,5.216604673035563
1.1400000000000001,0.5936906572928625,5.550034538548408
1.1425,0.6090716206982713,5.896618615813147
1.145,0.6243449435824283,6.256129550489429
1.1475,0.6394955530196154,6.6282602498373615
1.1500000000000001,0.6545084971874744,7.012622342246718
1.1525,0.6693689601226462,7.408745193265067
1.155,0.6840622763423395,7.816075497379357
1.1575,0.6985739453173907,8.233977461003395
1.16,0.7128896457825367,8.661733585526958
1.1625,0.7269952498697736,9.098546055847697
1.165,0.7408768370508578,9.543538733753586
1.1675,0.7545207078751858,10.008298024441535
1.17,0.767913397489499,10.52107213122663
1.1725,0.7810416889260661,11.037851445280479
1.175,0.7938926261462372,11.55764969032139
1.1775,0.8064535268264887,12.0793780776268
1.18,0.8187119948743452,12.601852284649267
1.1825,0.8306559326618264,13.123800208636927
1.185,0.8422735529643446,13.643870456266107
1.1875,0.853553390593274,14.160641518034954
1.19,0.864484313710706,14.672631562090578
1.1925000000000001,0.8750555348152299,15.178308771268467
1.195,0.8852566213878953,15.676102137449014
1.1975,0.8950775061878458,16.164412618083418
1.2,0.9045084971874742,16.64162455463536
1.2025000000000001,0.9135402871372812,17.10611724671538
1.205,0.9221639627510079,17.55627657493416
1.2075,0.9303710135019719,17.99050656376013
1.21,0.938153340021932,18.40724077775339
1.2125000000000001,0.9455032620941841,18.80495344758046
1.215,0.9524135262330099,19.182170227150834
1.2175,0.9588773128419906,19.537478489531054
1.22,0.9648882429441261,19.869537076219043
1.2225,0.970440384477113,20.177085423702394
1.225,0.9755282581475772,20.458951999129308
1.2275,0.9801468428384719,20.714061986856386
1.23,0.9842915805643156,20.941444177657793
1.2325,0.9879583809693738,21.140237020986245
1.235,0.9911436253643445,21.309693811505515
1.2375,0.9938441702975689,21.449186988508902
1.24,0.996057350657239,21.56215504131397
1.2425,0.9977809823015401,21.65280520585104
1.245,0.999013364214136,21.707054828687344
1.2475,0.9997532801828659,21.7254477454219
1.25,1.,21.708573024005815
1.2525,0.9997532801828659,21.65707458553331
1.2550000000000001,0.9990133642141359,21.571658295446987
1.2575,0.9977809823015401,21.453097019478815
1.26,0.996057350657239,21.314535181934758
1.2625,0.9938441702975689,21.14737552978308
1.2650000000000001,0.9911436253643444,20.951555240298173
1.2675,0.9879583809693738,20.727893845230906
1.27,0.9842915805643153,20.477308893052125
1.2725,0.9801468428384715,20.20080939343168
1.2750000000000001,0.9755282581475767,19.899488767777598
1.2775,0.970440384477113,19.574517355773708
1.28,0.9648882429441257,19.227134530794146
1.2825,0.9588773128419902,18.858640477863556
1.285,0.9524135262330097,18.4703876895533
1.2875,0.9455032620941834,18.063772237047274
1.29,0.9381533400219318,17.640224873770144
1.2925,0.9303710135019715,17.201202032420635
1.295,0.9221639627510075,16.748176775958136
1.2975,0.9135402871372805,16.282629765129343
1.3,0.904508497187474,15.806040306767342
1.3025,0.8950775061878451,15.319877547735373
1.305,0.885256621387894,14.825591880690817
1.3075,0.8750555348152297,14.32460662859877
1.31,0.864484313710705,13.818310075962613
1.3125,0.8535533905932737,13.308047913572397
1.315,0.8422735529643437,12.795116164515795
1.3175000000000001,0.830655932661826,12.280754657728291
1.32,0.8187119948743444,11.766141113074932
1.3225,0.8064535268264884,11.292153407549813
1.325,0.7938926261462361,10.831201699637234
1.3275000000000001,0.7810416889260657,10.37437359595125
1.33,0.7679133974894979,9.92275775027122
1.3325,0.7545207078751847,9.47737997546336
1.335,0.7408768370508575,9.039199547501973
1.3375000000000001,0.7269952498697726,8.609105997955773
1.34,0.7128896457825363,8.187916410334646
1.3425,0.6985739453173896,7.776373232381711
1.345,0.6840622763423392,7.375142612847084
1.3475,0.6693689601226451,6.984813267357421
1.35,0.6545084971874741,6.6058958746542045
1.3525,0.6394955530196141,6.23882300024586
1.355,0.6243449435824262,5.883949541097591
1.3575,0.609071620698271,5.541553680928202
1.36,0.5936906572928612,5.211838342480547
1.3625,0.5782172325201154,4.894933118525357
1.365,0.5626666167821512,4.5908966611204916
1.3675,0.5470541566592572,4.29971950408884
1.37,0.531395259764656,4.02132729102064
1.3725,0.5157053795390644,3.755584378227647
1.375,0.49999999999999944,3.502297778379605
1.3775,0.4842946204609363,3.261221409375704
1.3800000000000001,0.46860474023534293,3.032060609028412
1.3825,0.4529458433407417,2.8144768757125047
1.385,0.43733338321784765,2.608092792223599
1.3875,0.42178276747988364,2.4124970896694746
1.3900000000000001,0.4063093427071377,2.2272498067499176
1.3925,0.39092837930172797,2.0518874989731244
1.395,0.3756550564175728,1.8859284532084437
1.3975,0.36050444698038475,1.7288778620500176
1.4000000000000001,0.34549150281252744,1.5802329137681463
1.4025,0.3306310398773547,1.439487754557992
1.405,0.31593772365766065,1.3100979371970045
1.4075,0.30142605468260864,1.214157437633765
1.41,0.2871103542174619,1.1244067216643305
1.4125,0.2730047501302273,1.0405104661547686
1.415,0.2591231629491424,0.9621354807733598
1.4175,0.24547929212481362,0.8889530937033563
1.42,0.23208660251050028,0.8206413622051998
1.4225,0.21895831107393562,0.7568870941730295
1.425,0.20610737385376374,0.6973876704066552
1.4275,0.19354647317351137,0.6418526582342469
1.43,0.18128800512565418,0.5900052104752503
1.4325,0.16934406733817248,0.5415832454636175
1.435,0.15772644703565616,0.49634040609959795
1.4375,0.14644660940672619,0.45404679882359916
1.44,0.1355156862892936,0.41448951500715964
1.4425000000000001,0.12494446518476912,0.37747293995881187
1.445,0.11474337861210608,0.3428188566362463
1.4475,0.10492249381215493,0.31036635339213614
1.45,0.09549150281252596,0.27997154679680886
1.4525000000000001,0.08645971286271834,0.25150713262465046
1.455,0.07783603724899134,0.2248617793036684
1.4575,0.06962898649802843,0.1999393801759771
1.46,0.06184665997806808,0.17665818143193507
1.4625000000000001,0.054496737905815586,0.15494980417567908
1.465,0.04758647376698947,0.13475817981614613
1.4675,0.04112268715800985,0.11603841804253356
1.47,0.03511175705587435,0.09875562788299876
1.4725,0.02955961552288706,0.08288371160752452
1.475,0.02447174185242282,0.06840415172700383
1.4775,0.019853157161527836,0.055304810563226496
1.48,0.015708419435684576,0.04357876171154149
1.4825,0.012041619030626205,0.0332231713356237
1.485,0.008856374635655447,0.024238246801921867
1.4875,0.006155829702430843,0.01662626859767395
1.49,0.003942649342761201,0.01039072012304001
1.4925,0.0022190176984600244,0.005666302037062541
1.495,0.0009866357858641399,0.002404347488415963
1.4975,0.00024671981713423225,0.0005656526792349542
1.5,0.,2.1510980998079795e-12
1.5025,0.00024671981713423225,0.0005656526792349542
1.5050000000000001,0.0009866357858642238,0.0024043474153384575
1.5075,0.002219017698460108,0.0056663015994405175
1.51,0.003942649342761368,0.010390718375357615
1.5125,0.006155829702431011,0.016626263437287958
1.5150000000000001,0.008856374635655615,0.024238235180270726
1.5175,0.01204161903062654,0.03322314959444951
1.52,0.01570841943568483,0.04357872555728119
1.5225,0.01985315716152817,0.05530475505889033
1.5250000000000001,0.024471741852423158,0.06840407124959696
1.5275,0.02955961552288748,0.08288359980830777
1.53,0.035111757055874764,0.0987554776043072
1.5325,0.041122687158010277,0.11603822122891352
1.5350000000000001,0.047586473766989976,0.13475792739945186
1.5375,0.054496737905816085,0.1549494859007766
1.54,0.06184665997806867,0.1766577856756761
1.5425,0.0696289864980291,0.1999388937045533
1.545,0.07783603724899192,0.22486118698636678
1.5475,0.08645971286271892,0.25150641708045496
1.55,0.09549150281252662,0.27997068800924796
1.5525,0.1049224938121556,0.31036532821584595
1.555,0.11474337861210675,0.3428176382521835
1.5575,0.12494446518476983,0.37747149725307105
1.56,0.13551568628929433,0.41448781183094174
1.5625,0.14644660940672694,0.45404479317181023
1.565,0.157726447035657,0.4963380491786497
1.5675000000000001,0.1693440673381733,0.5415804805915978
1.57,0.18128800512565502,0.5900019719850804
1.5725,0.19354647317351228,0.6418488700091466
1.575,0.20610737385376462,0.697383244448701
1.5775000000000001,0.21895831107393654,0.7568819289627324
1.58,0.23208660251050126,0.8206353407841868
1.5825,0.2454792921248146,0.8889460816672388
1.585,0.2591231629491433,0.9621273240034719
1.5875000000000001,0.2730047501302283,1.0405009883570733
1.59,0.2871103542174629,1.1243957216450722
1.5925,0.30142605468260963,1.2141446863591425
1.595,0.3159377236576617,1.3100831745891794
1.5975000000000001,0.33063103987735576,1.4394573781133921
1.6,0.34549150281252516,1.5801572750852242
1.6025,0.36050444698038503,1.728723064523175
1.605,0.37565505641757296,1.8856568162316871
1.6075,0.39092837930172986,2.051455956264
1.61,0.4063093427071396,2.2266081848928883
1.6125,0.4217827674798838,2.4115862594810364
1.615,0.43733338321784787,2.606842685554171
1.6175,0.4529458433407436,2.8128043621749304
1.62,0.46860474023534493,3.0298672278385044
1.6225,0.4842946204609347,3.2583909553978168
1.625,0.4999999999999997,3.498693743378962
1.6275,0.5157053795390646,3.751047253197251
1.6300000000000001,0.531395259764658,4.015671739301244
1.6325,0.5470541566592593,4.292731420063459
1.635,0.5626666167821515,4.582330135030356
1.6375,0.5782172325201156,4.884507332828097
1.6400000000000001,0.5936906572928632,5.199234431844575
1.6425,0.6090716206982729,5.526411592838331
1.645,0.6243449435824264,5.8658649404765635
1.6475,0.6394955530196144,6.217344266205132
1.6500000000000001,0.6545084971874743,6.580521242546314
1.6525,0.669368960122647,6.95498817366299
1.655,0.684062276342341,7.340257303448139
1.6575,0.6985739453173898,7.7357606976706546
1.6600000000000001,0.7128896457825366,8.140850711870147
1.6625,0.7269952498697743,8.554801051510276
1.665,0.7408768370508593,8.976808427015593
1.6675,0.7545207078751848,9.4059947995259
1.67,0.7679133974894983,9.84141020973822
1.6725,0.7810416889260658,10.28203617625253
1.675,0.7938926261462377,10.726789645261661
1.6775,0.8064535268264901,11.174527468727204
1.68,0.8187119948743445,11.634045391421113
1.6825,0.8306559326618261,12.132566146008939
1.685,0.842273552964345,12.628913466487257
1.6875,0.8535533905932751,13.121864241448241
1.69,0.8644843137107051,13.610128315870266
1.6925000000000001,0.8750555348152297,14.092358130019498
1.695,0.8852566213878953,14.567158799375674
1.6975,0.8950775061878461,15.033098564052754
1.7,0.9045084971874752,15.488719529322562
1.7025000000000001,0.9135402871372807,15.932548610509384
1.705,0.9221639627510078,16.363108591681115
1.7075,0.9303710135019725,16.77892920384236
1.71,0.9381533400219328,17.17855812656333
1.7125000000000001,0.9455032620941838,17.56057181717482
1.715,0.9524135262330097,17.92358607355534
1.7175,0.9588773128419908,18.266266240307882
1.72,0.9648882429441263,18.5873369713036
1.7225000000000001,0.9704403844771123,18.885591469492656
1.725,0.9755282581475768,19.159900129984926
1.7275,0.9801468428384719,19.409218520735294
1.73,0.984291580564316,19.632594643311307
1.7325,0.9879583809693742,19.829175424856242
1.735,0.9911436253643442,19.99821240057084
1.7375,0.9938441702975689,20.139066555918486
1.74,0.996057350657239,20.251212304580392
1.7425,0.9977809823015402,20.33491911106709
1.745,0.9990133642141357,20.39773299498786
1.7475,0.9997532801828659,20.42608158829553
1.75,1.,20.420536212884873
1.7525,0.9997532801828659,20.38171250998261
1.7550000000000001,0.9990133642141357,20.310278870771775
1.7575,0.9977809823015401,20.213092641477996
1.76,0.996057350657239,20.090878224343147
1.7625,0.9938441702975689,19.940552337914312
1.7650000000000001,0.9911436253643442,19.762751442825216
1.7675,0.987958380969374,19.558213064559343
1.77,0.9842915805643156,19.32777018680406
1.7725,0.9801468428384715,19.072345069408524
1.7750000000000001,0.9755282581475765,18.79294254027997
1.7775,0.970440384477112,18.49064281573002
1.78,0.964888242944126,18.166593903929275
1.7825,0.9588773128419905,17.822003648506502
1.7850000000000001,0.9524135262330093,17.458131472797515
1.7875,0.9455032620941831,17.076279884580032
1.79,0.9381533400219323,16.67778580523888
1.7925,0.9303710135019719,16.26401178714791
1.795,0.9221639627510072,15.836337186339948
1.7975,0.9135402871372801,15.396149357013766
1.8,0.9045084971874725,14.944834937675624
1.8025,0.8950775061878455,14.483771298243598
1.805,0.8852566213878946,14.014318219247622
1.8075,0.875055534815229,13.537809873966518
1.81,0.8644843137107044,13.055547184965373
1.8125,0.8535533905932744,12.58100007457117
1.815,0.8422735529643444,12.136710796929345
1.8175000000000001,0.8306559326618255,11.691593150765806
1.82,0.8187119948743438,11.246892161877712
1.8225,0.8064535268264864,10.803810013064666
1.825,0.793892626146237,10.363500707084954
1.8275000000000001,0.7810416889260651,9.927065122813216
1.83,0.7679133974894974,9.495546493047586
1.8325,0.754520707875184,9.069926330003963
1.835,0.7408768370508584,8.65112082030662
1.8375000000000001,0.7269952498697735,8.23997770931913
1.84,0.7128896457825357,7.837273690036125
1.8425,0.6985739453173889,7.443712309026132
1.845,0.6840622763423401,7.059922397770265
1.8475000000000001,0.6693689601226461,6.68645703388195
1.85,0.6545084971874733,6.323793033624167
1.8525,0.6394955530196135,5.972330972255624
1.855,0.6243449435824254,5.6323957255738275
1.8575,0.6090716206982719,5.304237522015814
1.86,0.5936906572928622,4.9880334908370685
1.8625,0.5782172325201146,4.683889688050423
1.865,0.5626666167821505,4.391843578458129
1.8675,0.5470541566592582,4.111866948468911
1.87,0.531395259764657,3.8438692210231844
1.8725,0.5157053795390636,3.5877011410828645
1.875,0.4999999999999987,3.343158796866108
1.8775,0.4842946204609337,3.109987939966772
1.8800000000000001,0.46860474023534393,2.8878885643779015
1.8825,0.4529458433407427,2.6765197032905754
1.885,0.437333383217847,2.4755043999634148
1.8875,0.42178276747988286,2.2844348086095896
1.8900000000000001,0.4063093427071387,2.102877379300986
1.8925,0.39092837930172897,1.9303780811723834
1.895,0.375655056417572,1.7664676176020857
1.8975,0.36050444698038403,1.6377239574865536
1.9000000000000001,0.34549150281252416,1.5212545045800943
1.9025,0.3306310398773548,1.4119656928299937
1.905,0.3159377236576608,1.3095316397581978
1.9075,0.30142605468260875,1.213620551418157
1.9100000000000001,0.287110354217462,1.123897536204737
1.9125,0.27300475013022746,1.0400272942098947
1.915,0.25912316294914245,0.961676663385455
1.9175,0.24547929212481376,0.8885170050121248
1.92,0.23208660251050042,0.8202264140161503
1.9225,0.21895831107393277,0.7564917402510676
1.925,0.2061073738537638,0.697010410486869
1.9275,0.1935464731735115,0.6414920417525597
1.93,0.18128800512565424,0.5896598399038782
1.9325,0.1693440673381726,0.5412517793959399
1.935,0.15772644703565625,0.4960215619334476
1.9375,0.1464466094067262,0.453739355125083
1.94,0.13551568628929367,0.4141923134692132
1.9425000000000001,0.12494446518476916,0.37718488700715114
1.945,0.1147433786121039,0.3425389246477945
1.9475,0.10492249381215502,0.31009358152731265
1.95,0.09549150281252604,0.2797050414299052
1.9525000000000001,0.08645971286271834,0.2512460674205319
1.955,0.07783603724899134,0.2246053948718255
1.9575,0.0696289864980286,0.19968698334998367
1.96,0.061846659978068166,0.176409144194538
1.9625000000000001,0.05449673790581567,0.15470356217706888
1.965,0.04758647376698955,0.13451423055273978
1.9675,0.04112268715800985,0.11579631868696948
1.97,0.03511175705587435,0.09851499276392918
1.9725000000000001,0.029559615522887144,0.08264420937573819
1.975,0.02447174185242282,0.06816550221042761
1.9775,0.019853157161527836,0.05506678134981105
1.98,0.015708419435684576,0.04334116442828502
1.9825000000000002,0.012041619030626288,0.03298585772058657
1.985,0.008856374635655447,0.024001104525891753
1.9875,0.006155829702430843,0.016389216890329156
1.99,0.003942649342761201,0.01016003528228939
1.9925,0.0022190176984600244,0.0055973623127167195
1.995,0.0009866357858641399,0.0023354100809932664
1.9975,0.00024671981713423225,0.0005656526792349542
2.,0.,2.1510980998079795e-12
2.0025,0.00024671981713423225,0.0005656526792349542
2.005,0.0009866357858642238,0.002335410042458998
2.0075,0.002219017698460108,0.005597361979996334
2.0100000000000002,0.003942649342761368,0.010160034125733486
2.0125,0.006155829702431011,0.016389213250169836
2.015,0.008856374635655615,0.024001095365852376
2.0175,0.012041619030626456,0.032985839388730905
2.02,0.01570841943568483,0.043341132636478354
2.0225,0.019853157161529092,0.055066731171181195
2.025,0.02447174185242307,0.06816542804411153
2.0275,0.029559615522887397,0.08264410489370048
2.0300000000000002,0.03511175705587468,0.09851485083994453
2.0325,0.04112268715801019,0.11579613131126772
2.035,0.04758647376698989,0.13451398871283007
2.0375,0.054496737905816085,0.15470325568290588
2.04,0.06184665997806859,0.17640876151698381
2.0425,0.06962898649802893,0.19968651136399176
2.045,0.07783603724899377,0.224604818565036
2.0475,0.08645971286271883,0.25124536957759996
2.05,0.09549150281252654,0.2797042022077011
2.0525,0.1049224938121556,0.3100925779958688
2.055,0.11474337861210666,0.3425377302409293
2.0575,0.12494446518476979,0.37718347089136534
2.06,0.1355156862892943,0.41419063983037085
2.0625,0.14644660940672685,0.4537373823380367
2.065,0.15772644703565689,0.49601924162568056
2.0675,0.16934406733817325,0.5412490553981417
2.07,0.1812880051256549,0.5896566470650043
2.0725000000000002,0.19354647317351217,0.6414883046001436
2.075,0.2061073738537645,0.6970060417293659
2.0775,0.21895831107393646,0.7564866391377737
2.08,0.23208660251050112,0.8202204644732634
2.0825,0.24547929212481445,0.8885100736174797
2.085,0.2591231629491432,0.9616685971172945
2.0875,0.2730047501302282,1.0400179179862694
2.09,0.2871103542174628,1.123886650177638
2.0925000000000002,0.3014260546826095,1.2136079280417733
2.095,0.3159377236576616,1.3095170206040323
2.0975,0.33063103987735565,1.411948785151556
2.1,0.3454915028125284,1.5212349776201939
2.1025,0.36050444698038486,1.6377014385209616
2.105,0.37565505641757285,1.7664393323321175
2.1075,0.3909283793017298,1.9303252557604709
2.11,0.40630934270713953,2.102766577461462
2.1125,0.4217827674798837,2.2842297721897498
2.115,0.4373333832178478,2.475164429707743
2.1175,0.45294584334074356,2.6759979541063803
2.12,0.4686047402353448,2.887130249448805
2.1225,0.48429462046093813,3.1089284385342646
2.125,0.49999999999999956,3.341721662340383
2.1275,0.5157053795390645,3.5857960080926867
2.13,0.5313952597646578,3.8413896132637104
2.1325,0.5470541566592592,4.108687992623571
2.1350000000000002,0.5626666167821514,4.387819633378632
2.1375,0.5782172325201155,4.678851903184668
2.14,0.5936906572928631,4.981787312319548
2.1425,0.6090716206982728,5.296560170362333
2.145,0.6243449435824296,5.623033673437872
2.1475,0.6394955530196144,5.960997456128804
2.15,0.6545084971874742,6.310165637972934
2.1525,0.6693689601226468,6.670175390438787
2.1550000000000002,0.6840622763423408,7.040586046656501
2.1575,0.6985739453173896,7.420878771563457
2.16,0.7128896457825364,7.810456805210739
2.1625,0.7269952498697742,8.20864628756414
2.165,0.7408768370508592,8.614697668260867
2.1675,0.7545207078751879,9.027787699749785
2.17,0.767913397489498,9.447022006943824
2.1725,0.7810416889260657,9.871438222187306
2.1750000000000003,0.7938926261462377,10.300009668994909
2.1775,0.80645352682649,10.73164957374368
2.18,0.8187119948743444,11.165215779232216
2.1825,0.8306559326618261,11.599515930481436
2.185,0.842273552964345,12.03331309850204
2.1875,0.8535533905932751,12.465331804532791
2.19,0.8644843137107051,12.92642115650401
2.1925,0.8750555348152297,13.393732337320378
2.195,0.885256621387895,13.853706065093924
2.1975000000000002,0.8950775061878461,14.305030381081904
2.2,0.904508497187475,14.746361309425145
2.2025,0.9135402871372807,15.176333456296321
2.205,0.9221639627510078,15.593570735366633
2.2075,0.9303710135019724,15.99669713664641
2.21,0.9381533400219328,16.38434745173567
2.2125,0.9455032620941836,16.755177868046438
2.215,0.9524135262330097,17.10787634357461
2.2175000000000002,0.9588773128419908,17.441172676483
2.22,0.9648882429441263,17.75384818556275
2.2225,0.9704403844771137,18.04474492266817
2.225,0.9755282581475768,18.312774343777015
2.2275,0.9801468428384716,18.556925370400517
2.23,0.984291580564316,18.776271781424914
2.2325,0.9879583809693742,18.969978882667057
2.235,0.9911436253643442,19.13730940864859
2.2375000000000003,0.9938441702975689,19.277628620688535
2.24,0.996057350657239,19.390408571941872
2.2425,0.9977809823015402,19.475231520136358
2.245,0.999013364214136,19.534942788705926
2.2475,0.9997532801828659,19.568219122131474
2.25,1.,19.568590914451978
2.2525,0.9997532801828659,19.53665739795577
2.255,0.9990133642141357,19.473332598248128
2.2575,0.9977809823015401,19.388024215638065
2.2600000000000002,0.996057350657239,19.275025624261556
2.2625,0.9938441702975689,19.13482051008417
2.265,0.9911436253643442,18.967995400558475
2.2675,0.9879583809693732,18.775234994665166
2.27,0.9842915805643156,18.557316854889432
2.2725,0.9801468428384715,18.315105508038844
2.275,0.9755282581475765,18.049546007593637
2.2775,0.970440384477112,17.76165701022997
2.2800000000000002,0.964888242944126,17.452523423792822
2.2825,0.9588773128419905,17.123288685924116
2.285,0.9524135262330093,16.775146734520305
2.2875,0.9455032620941832,16.40933373352538
2.29,0.9381533400219306,16.02711961965336
2.2925,0.9303710135019719,15.62979953808611
2.295,0.9221639627510072,15.218685234678285
2.2975,0.9135402871372802,14.795096476878244
2.3000000000000003,0.9045084971874726,14.360352574353552
2.3025,0.8950775061878455,13.915764071690193
2.305,0.8852566213878946,13.462624687362984
2.3075,0.8750555348152292,13.039067854111439
2.31,0.8644843137107047,12.615388901061916
2.3125,0.8535533905932744,12.188311059948015
2.315,0.8422735529643446,11.759107638792653
2.3175,0.8306559326618257,11.32902118044597
2.32,0.8187119948743439,10.899257520689037
2.3225000000000002,0.8064535268264865,10.47098017370478
2.325,0.7938926261462372,10.045305079112014
2.3275,0.7810416889260651,9.623295742255989
2.33,0.7679133974894976,9.205958796514924
2.3325,0.7545207078751841,8.794240013437545
2.335,0.7408768370508585,8.389020783208341
2.3375,0.7269952498697735,7.991115085125513
2.34,0.7128896457825358,7.601266963305025
2.3425000000000002,0.6985739453173889,7.220148520320847
2.345,0.6840622763423369,6.848358436793224
2.3475,0.6693689601226461,6.486421021587851
2.35,0.6545084971874735,6.13478579362664
2.3525,0.6394955530196136,5.793827591731899
2.355,0.6243449435824255,5.4638472053655995
2.3575,0.6090716206982721,5.145072515457423
2.36,0.5936906572928624,4.837660130196853
2.3625000000000003,0.5782172325201147,4.541697497045941
2.365,0.5626666167821506,4.25720546859081
2.3675,0.5470541566592548,3.9841412963043488
2.37,0.5313952597646571,3.7224020230077492
2.3725,0.5157053795390638,3.471828241408296
2.375,0.4999999999999988,3.2322081833033343
2.3775,0.48429462046093386,3.00328210166273
2.38,0.4686047402353441,2.7847469048568105
2.3825,0.4529458433407428,2.576261000802482
2.3850000000000002,0.43733338321784704,2.3774493067921516
2.3875,0.42178276747988297,2.1879083797330665
2.39,0.4063093427071353,2.032549023251845
2.3925,0.390928379301729,1.8927253934621902
2.395,0.37565505641757213,1.7609932878576608
2.3975,0.36050444698038414,1.6370623604115162
2.4,0.3454915028125243,1.5206273827040973
2.4025,0.3306310398773549,1.4113713028426904
2.4050000000000002,0.31593772365766093,1.3089682453365503
2.4075,0.30142605468260886,1.2130864288211676
2.41,0.2871103542174621,1.123390979696168
2.4125,0.27300475013022435,1.039546621330185
2.415,0.25912316294914256,0.9612202199072504
2.4175,0.24547929212481387,0.8880831698652996
2.42,0.23208660251050053,0.819813603759798
2.4225,0.2189583110739329,0.7560984133895403
2.4250000000000003,0.2061073738537639,0.6966350714582372
2.4275,0.19354647317351162,0.6411332446368267
2.43,0.18128800512565435,0.5893161917885258
2.4325,0.16934406733817273,0.5409219434175272
2.435,0.15772644703565636,0.4957042599840417
2.4375,0.14644660940672635,0.45343337017408086
2.44,0.13551568628929378,0.41389649154198016
2.4425,0.12494446518476929,0.3768981387744346
2.445,0.11474337861210399,0.3422602266422903
2.4475000000000002,0.1049224938121551,0.30982197696944946
2.45,0.09549150281252612,0.2794396406686975
2.4525,0.0864597128627185,0.2509860479887572
2.455,0.07783603724899142,0.2243500011491588
2.4575,0.0696289864980286,0.19943552585056032
2.46,0.06184665997806825,0.17616099846569863
2.4625,0.05449673790581575,0.15445816734639262
2.465,0.04758647376698955,0.13427108750214609
2.4675000000000002,0.041122687158008514,0.11555498786842103
2.47,0.03511175705587443,0.098275091703512
2.4725,0.029559615522887144,0.08240540983325031
2.475,0.02447174185242282,0.06792752703841118
2.4775,0.01985315716152792,0.054829401076930295
2.48,0.015708419435684663,0.04310419356485166
2.4825,0.012041619030626288,0.03274915081404602
2.485,0.008856374635655532,0.023764551998194283
2.4875000000000003,0.0061558297024309275,0.016152740676969226
2.49,0.003942649342760782,0.010091130574956265
2.4925,0.0022190176984600244,0.005528465260459733
2.495,0.0009866357858641399,0.002266514858833515
2.4975,0.00024671981713423225,0.0005656526792349542
2.5,0.,2.1510980998079795e-12