File: Module2/strain16.txt
SAMPLE PARAMETERS
Gauge length [mm]: 23.4558
Area [mm2]: 65.7071
EXPERIMENTAL PARAMETERS
Time [s]: 1.76
Number of steps: 1000
Displacement (0) or force control (1): 0
Schedule ID: 0
Point 1,0.,0.
Point 2,1.6,1.
Point 3,1.76,1.
RESULTS
Time [s],Displacement [mm],Force [N]
0.,0.,0.
0.00176,0.0011,0.015754974136358613
0.00352,0.0022,0.03088978818961271
0.00528,0.0033,0.04545453214431074
0.00704,0.0044,0.059495146897231496
0.0088,0.0055,0.07305378324317634
0.01056,0.0066,0.0861691266014023
0.012320000000000001,0.0077,0.09887669048466229
0.01408,0.0088,0.11120908370854173
0.01584,0.009899999999999999,0.12319625353080331
0.0176,0.011,0.13486570673900433
0.019360000000000002,0.012100000000000001,0.14624271211337198
0.02112,0.0132,0.15735048538118995
0.02288,0.014299999999999998,0.16821035811422808
0.024640000000000002,0.0154,0.17884193273641913
0.0264,0.016499999999999997,0.1892632245369085
0.02816,0.0176,0.19949079143276016
0.029920000000000002,0.0187,0.20953985358932453
0.03168,0.019799999999999998,0.2194244029313148
0.033440000000000004,0.020900000000000002,0.2291573033617298
0.0352,0.022,0.2387503832140056
0.03696,0.0231,0.24821451953340498
0.038720000000000004,0.024200000000000003,0.2575597163421164
0.04048,0.0253,0.26679517561181276
0.04224,0.0264,0.27592936275396707
0.044000000000000004,0.027500000000000004,0.28497006710939937
0.04576,0.028599999999999997,0.2939244569027698
0.04752,0.0297,0.3027991302321706
0.049280000000000004,0.0308,0.3116001613368969
0.05104,0.031900000000000005,0.3203331437263614
0.0528,0.032999999999999995,0.3290032292432823
0.054560000000000004,0.034100000000000005,0.3376151643642565
0.05632,0.0352,0.3461733229437652
0.05808,0.0363,0.35468173708668194
0.059840000000000004,0.0374,0.36314412474399854
0.0616,0.0385,0.37156391557668866
0.06336,0.039599999999999996,0.37994427424779065
0.06512,0.04069999999999999,0.38828812238396193
0.06688000000000001,0.041800000000000004,0.39659815805813375
0.06864,0.0429,0.4048768743592461
0.0704,0.044,0.4131265757146398
0.07216,0.0451,0.421349393736421
0.07392,0.0462,0.42954730092218185
0.07568,0.047299999999999995,0.4377221236648517
0.07744000000000001,0.048400000000000006,0.4458755544094686
0.0792,0.049499999999999995,0.45400916225245475
0.08096,0.0506,0.46212440295507673
0.08272,0.0517,0.4702226285244423
0.08448,0.0528,0.4783050951758143
0.08624,0.05389999999999999,0.4863729712342251
0.08800000000000001,0.05500000000000001,0.4944273445200737
0.08976,0.056100000000000004,0.5024692284415141
0.09152,0.057199999999999994,0.5104995682983933
0.09328,0.0583,0.5185192466662822
0.09504,0.0594,0.5265290884735389
0.0968,0.0605,0.534529865693129
0.09856000000000001,0.0616,0.5425223014593497
0.10032,0.0627,0.5505070741045164
0.10208,0.06380000000000001,0.5584848207655536
0.10384,0.0649,0.566456140504284
0.1056,0.06599999999999999,0.5744215975659747
0.10736,0.06709999999999999,0.5823817240860015
0.10912000000000001,0.06820000000000001,0.5903370223485327
0.11088,0.0693,0.5982879677957696
0.11264,0.0704,0.6062350104349279
0.1144,0.0715,0.6141785773085685
0.11616,0.0726,0.6221190740779998
0.11792000000000001,0.0737,0.6300568869475371
0.11968000000000001,0.0748,0.6379923837329043
0.12144,0.07590000000000001,0.6459259158388261
0.1232,0.077,0.6538578190859413
0.12496,0.0781,0.6617884151834322
0.12672,0.07919999999999999,0.6697180126305062
0.12848,0.0803,0.6776469079654567
0.13024,0.08139999999999999,0.6855753863229126
0.132,0.0825,0.6935037227042411
0.13376000000000002,0.08360000000000001,0.7014321824726828
0.13552,0.0847,0.7093610220300268
0.13728,0.0858,0.7172904897147044
0.13904,0.08689999999999999,0.7252208262551396
0.1408,0.088,0.7331522654270651
0.14256,0.08909999999999998,0.7410850343227584
0.14432,0.0902,0.7490193541936494
0.14608000000000002,0.0913,0.7569554405338155
0.14784,0.0924,0.7648935037117823
0.1496,0.09350000000000001,0.7728337492332384
0.15136,0.09459999999999999,0.7807763781385165
0.15312,0.0957,0.7887215872082761
0.15488000000000002,0.09680000000000001,0.7966695695058974
0.15664,0.0979,0.804620514213437
0.1584,0.09899999999999999,0.8125746073350888
0.16016,0.1001,0.820532031604554
0.16192,0.1012,0.8284929668875924
0.16368,0.10229999999999997,0.8364575902117205
0.16544,0.1034,0.8444260760756911
0.16720000000000002,0.10450000000000001,0.8523985965311747
0.16896,0.1056,0.8603753213292119
0.17072,0.1067,0.8683564182962494
0.17248,0.10779999999999998,0.8763420529152298
0.17424,0.10890000000000001,0.8843323890205939
0.17600000000000002,0.11000000000000001,0.8923275888013668
0.17776,0.11109999999999999,0.900327812474744
0.17952,0.11220000000000001,0.9083332189249211
0.18128,0.1133,0.9163439654517307
0.18304,0.11439999999999999,0.924360207924463
0.18480000000000002,0.11550000000000002,0.9323821010134782
0.18656,0.1166,0.9404097980487178
0.18832000000000002,0.1177,0.9484434512615385
0.19008,0.1188,0.956483211624545
0.19184,0.11989999999999999,0.9645292290783254
0.1936,0.121,0.9725816526939608
0.19536,0.1221,0.980640630412078
0.19712000000000002,0.1232,0.988706309327341
0.19888,0.12430000000000001,0.9967788356545901
0.20064,0.1254,1.004858354731135
0.2024,0.12649999999999997,1.0129450112038476
0.20416,0.12760000000000002,1.0210389487731877
0.20592000000000002,0.1287,1.0291403105663253
0.20768,0.1298,1.0372492390132935
0.20944000000000002,0.13090000000000002,1.0453658757395883
0.2112,0.13199999999999998,1.0534903618908327
0.21296,0.1331,1.0616228379226296
0.21472,0.13419999999999999,1.0697634436517711
0.21648,0.1353,1.077912318351227
0.21824000000000002,0.13640000000000002,1.0860696009024184
0.22,0.13749999999999998,1.0942354293031855
0.22176,0.1386,1.102409941446132
0.22352,0.1397,1.1105932745573794
0.22528,0.1408,1.1187855652184244
0.22704000000000002,0.1419,1.126986949922186
0.2288,0.143,1.1351975643805632
0.23056000000000001,0.1441,1.1434175440839922
0.23232,0.1452,1.151647024020655
0.23408,0.1463,1.1598861388197945
0.23584000000000002,0.1474,1.1681350227152476
0.2376,0.1485,1.1763938095860778
0.23936000000000002,0.1496,1.1846626329194887
0.24112,0.1507,1.192941625759082
0.24288,0.15180000000000002,1.201230921044775
0.24464,0.15289999999999998,1.2095306512047999
0.2464,0.154,1.2178409483689072
0.24816000000000002,0.15510000000000002,1.2261619443296976
0.24992,0.1562,1.2344937707675565
0.25168,0.1573,1.2428365588097168
0.25344,0.15839999999999999,1.2511904394375886
0.2552,0.15949999999999998,1.2595555433710337
0.25696,0.1606,1.2679320009543615
0.25872,0.1617,1.2763199423908347
0.26048,0.16279999999999997,1.2847194974510627
0.26224000000000003,0.1639,1.2931307958961284
0.264,0.165,1.3015539670952978
0.26576,0.16609999999999997,1.3099891401210682
0.26752000000000004,0.16720000000000002,1.3184364439912188
0.26928,0.1683,1.3268960073044616
0.27104,0.1694,1.335367958612409
0.2728,0.17049999999999998,1.3438524261343898
0.27456,0.1716,1.3523495379227144
0.27632,0.1727,1.3608594218086751
0.27808,0.17379999999999998,1.3693822053878892
0.27984000000000003,0.1749,1.3779180161971
0.2816,0.176,1.3864669813426036
0.28336,0.1771,1.3950292280150673
0.28512,0.17819999999999997,1.4036048829755776
0.28688,0.17930000000000001,1.4121940730260785
0.28864,0.1804,1.4207969246456793
0.2904,0.18149999999999997,1.4294135640886012
0.29216000000000003,0.1826,1.4380441176078178
0.29392,0.1837,1.4466887111123468
0.29568,0.1848,1.455347470584259
0.29744000000000004,0.1859,1.4640205215543984
0.2992,0.18700000000000003,1.4727079896040836
0.30096,0.18810000000000002,1.481410000113162
0.30272,0.18919999999999998,1.4901266781869569
0.30448000000000003,0.1903,1.4988581489718928
0.30624,0.1914,1.5076045373283857
0.308,0.19249999999999998,1.5163659680660801
0.30976000000000004,0.19360000000000002,1.5251425656926132
0.31152,0.1947,1.5339344547866427
0.31328,0.1958,1.5427417595449955
0.31504,0.19689999999999996,1.5515646042975406
0.3168,0.19799999999999998,1.5604031129892524
0.31856,0.19910000000000003,1.5692574096453196
0.32032,0.2002,1.5781276179198473
0.32208000000000003,0.2013,1.5870138615426317
0.32384,0.2024,1.5959162639973963
0.3256,0.2035,1.604834948656538
0.32736,0.20459999999999995,1.6137700387759206
0.32912,0.20570000000000002,1.622721657495819
0.33088,0.2068,1.631689927814685
0.33264,0.20789999999999997,1.6406749726271543
0.33440000000000003,0.20900000000000002,1.649676914622624
0.33616,0.21009999999999998,1.6586958764593238
0.33792,0.2112,1.6677319806987676
0.33968000000000004,0.21230000000000002,1.6767853495359333
0.34144,0.2134,1.6858561053731633
0.3432,0.2145,1.6949443702638651
0.34496,0.21559999999999996,1.7040502662529065
0.34672000000000003,0.2167,1.7131739151953755
0.34848,0.21780000000000002,1.722315438764537
0.35024,0.21889999999999998,1.7314749587564424
0.35200000000000004,0.22000000000000003,1.7406525965475785
0.35376,0.2211,1.7498484736186444
0.35552,0.22219999999999998,1.7590627111712132
0.35728,0.2233,1.7682954303984513
0.35904,0.22440000000000002,1.777546752239122
0.3608,0.2255,1.7868167976716767
0.36256,0.2266,1.7961056874882522
0.36432000000000003,0.2277,1.8054135422686293
0.36608,0.22879999999999998,1.8147404825917128
0.36784,0.2299,1.8240866287849704
0.36960000000000004,0.23100000000000004,1.8334521011937548
0.37136,0.2321,1.8428370199877424
0.37312,0.2332,1.8522415051429901
0.37488,0.23429999999999998,1.8616656765162827
0.37664000000000003,0.2354,1.871109654002158
0.3784,0.23650000000000002,1.8805735571001039
0.38016,0.2376,1.8900575054692632
0.38192000000000004,0.23870000000000002,1.8995616183769253
0.38368,0.23979999999999999,1.9090860151133426
0.38544,0.24089999999999998,1.9186308147822286
0.3872,0.242,1.9281961364067195
0.38896000000000003,0.2431,1.9377820988431838
0.39072,0.2442,1.947388820719524
0.39248,0.2453,1.9570164207307832
0.39424000000000003,0.2464,1.9666650172824158
0.396,0.24749999999999997,1.9763347286579158
0.39776,0.24860000000000002,1.9860256730624861
0.39952000000000004,0.24970000000000003,1.9957379684539278
0.40128,0.2508,2.005471732828465
0.40304,0.2519,2.015227083874349
0.4048,0.25299999999999995,2.0250041391107927
0.40656000000000003,0.2541,2.0348030161615314
0.40832,0.25520000000000004,2.044623832180193
0.41008,0.2563,2.0544667043698044
0.41184000000000004,0.2574,2.0643317497243086
0.4136,0.2585,2.074219085152525
0.41536,0.2596,2.084128827342662
0.41712,0.2607,2.0940610927961116
0.41888000000000003,0.26180000000000003,2.1040159979782187
0.42064,0.2629,2.113993659028287
0.4224,0.26399999999999996,2.123994192143873
0.42416000000000004,0.2651,2.1340177130951914
0.42592,0.2662,2.1440643377986404
0.42768,0.2673,2.1541341817730575
0.42944,0.26839999999999997,2.164227360455987
0.4312,0.2695,2.174343989065125
0.43296,0.2706,2.184484182724075
0.43472,0.27169999999999994,2.1946480563576247
0.43648000000000003,0.27280000000000004,2.2048357247315895
0.43824,0.27390000000000003,2.2150473024485575
0.44,0.27499999999999997,2.22528290382895
0.44176000000000004,0.2761,2.235542643174165
0.44352,0.2772,2.245826634487576
0.44528,0.2783,2.256134991640396
0.44704,0.2794,2.2664678284481337
0.44880000000000003,0.2805,2.276825258223532
0.45056,0.2816,2.2872073943215576
0.45232,0.28269999999999995,2.297614350037572
0.45408000000000004,0.2838,2.308046238144584
0.45584,0.28490000000000004,2.318503171497188
0.4576,0.286,2.3289852625692853
0.45936,0.28709999999999997,2.3394926238319713
0.46112000000000003,0.2882,2.3500253673940925
0.46288,0.2893,2.36058360523362
0.46464,0.2904,2.371167449116035
0.46640000000000004,0.29150000000000004,2.3817770107045257
0.46816,0.2926,2.3924124012504313
0.46992,0.2937,2.40307373202213
0.47168000000000004,0.2948,2.413761113931587
0.47344,0.2959,2.4244746577794776
0.4752,0.297,2.435214474073403
0.47696,0.2981,2.4459806731488283
0.47872000000000003,0.2992,2.4567733651397035
0.48048,0.3003,2.467592659971236
0.48224,0.3014,2.4784386673216683
0.48400000000000004,0.3025,2.489311496671756
0.48576,0.30360000000000004,2.500211257274631
0.48752,0.3047,2.5111380581335783
0.48928,0.30579999999999996,2.5220920080549125
0.49104000000000003,0.3069,2.5330732156678537
0.4928,0.308,2.5440817893337284
0.49456,0.3091,2.5551178371346692
0.49632000000000004,0.31020000000000003,2.5661814670042506
0.49808,0.3113,2.5772727865846217
0.49984,0.3124,2.588391903373668
0.5016,0.3135,2.59953892444709
0.50336,0.3146,2.610713956843013
0.50512,0.31570000000000004,2.6219171073291987
0.50688,0.31679999999999997,2.6331484823080933
0.50864,0.31789999999999996,2.64440818806526
0.5104,0.31899999999999995,2.6556963306074155
0.5121600000000001,0.3201,2.667013015628772
0.51392,0.3212,2.6783583487445712
0.51568,0.32230000000000003,2.68973243504574
0.51744,0.3234,2.7011353797271482
0.5192,0.32449999999999996,2.712567287413574
0.52096,0.32559999999999995,2.7240282626582855
0.5227200000000001,0.32670000000000005,2.735518409703104
0.5244800000000001,0.3278,2.7470378325761877
0.52624,0.3289,2.758586634950112
0.528,0.33,2.7701649203793166
0.52976,0.3311,2.781772792055735
0.53152,0.33219999999999994,2.793410352902615
0.53328,0.3333,2.8050777056812275
0.5350400000000001,0.33440000000000003,2.8167749527553934
0.5368,0.3355,2.8285021962346977
0.53856,0.3366,2.8402595382022118
0.54032,0.3377,2.8520470802225706
0.54208,0.3388,2.863864923460761
0.54384,0.3399,2.8757131692794267
0.5456,0.34099999999999997,2.887591918340195
0.5473600000000001,0.3421,2.899501271187546
0.54912,0.3432,2.911441328068111
0.55088,0.3443,2.9234121890797353
0.55264,0.3454,2.9354139538530277
0.5544,0.3465,2.9474467217476454
0.55616,0.34759999999999996,2.9595105920337503
0.55792,0.34869999999999995,2.9716056635677996
0.5596800000000001,0.3498,2.9837320348876144
0.56144,0.3509,2.995889804315703
0.5632,0.352,3.0080790698550097
0.56496,0.3531,3.0202999292251955
0.56672,0.3542,3.0325524799558634
0.56848,0.35529999999999995,3.0448368191068425
0.57024,0.35639999999999994,3.0571530435787047
0.5720000000000001,0.35750000000000004,3.0695012499194543
0.57376,0.35860000000000003,3.0818815344635695
0.57552,0.3597,3.094293993119855
0.57728,0.3608,3.1067387216934943
0.57904,0.3619,3.11921581551364
0.5808,0.36299999999999993,3.1317253696906286
0.58256,0.3641,3.144267479073603
0.5843200000000001,0.3652,3.156842238143744
0.58608,0.3663,3.1694497411066207
0.58784,0.3674,3.1820900818947773
0.5896,0.3685,3.194763354086746
0.59136,0.3696,3.2074696510789966
0.59312,0.3706999999999999,3.2202090657868245
0.5948800000000001,0.3718,3.2329816910162092
0.5966400000000001,0.3729,3.2457876190513697
0.5984,0.37400000000000005,3.2586269421554253
0.60016,0.37510000000000004,3.2714997519347824
0.60192,0.37620000000000003,3.2844061400390507
0.60368,0.37729999999999997,3.2973461976114993
0.60544,0.37839999999999996,3.310320015448397
0.6072000000000001,0.37950000000000006,3.3233276842184214
0.6089600000000001,0.3806,3.336369294130664
0.61072,0.3817,3.349444935152942
0.61248,0.3828,3.3625546969433846
0.61424,0.38389999999999996,3.37569866876159
0.616,0.38499999999999995,3.388876939733892
0.61776,0.3861,3.4020895985699657
0.6195200000000001,0.38720000000000004,3.4153367335700042
0.62128,0.38830000000000003,3.4286184328952416
0.62304,0.3894,3.441934784283897
0.6248,0.3905,3.455285875257871
0.62656,0.3916,3.468671792847156
0.62832,0.3927,3.482092624021587
0.63008,0.39379999999999993,3.495548455212847
0.6318400000000001,0.39490000000000003,3.5090393726459297
0.6336,0.39599999999999996,3.5225654621637776
0.63536,0.39709999999999995,3.5361268094206655
0.63712,0.39820000000000005,3.54972349963408
0.63888,0.3993,3.5633556178007835
0.64064,0.4004,3.5770232484359803
0.6424,0.40149999999999997,3.590726475907674
0.6441600000000001,0.4026,3.6044653841719376
0.64592,0.4037,3.6182400570117075
0.64768,0.4048,3.6320505776847374
0.64944,0.4059,3.6458970292594475
0.6512,0.407,3.6597794943654294
0.65296,0.40809999999999996,3.673698055573072
0.65472,0.4091999999999999,3.6876527948391677
0.6564800000000001,0.4103,3.701643793995718
0.65824,0.41140000000000004,3.715671134468037
0.66,0.41250000000000003,3.7297348973687767
0.66176,0.4136,3.7438351635273026
0.66352,0.4147,3.757972013482561
0.66528,0.41579999999999995,3.7721455273534397
0.6670400000000001,0.41690000000000005,3.786355785011668
0.6688000000000001,0.41800000000000004,3.800602865954442
0.67056,0.4191,3.8148868494700534
0.67232,0.42019999999999996,3.8292078144309594
0.67408,0.42129999999999995,3.843565839480404
0.67584,0.4224,3.857961002777601
0.6776,0.4235,3.872393382357275
0.6793600000000001,0.42460000000000003,3.8868630557721837
0.6811200000000001,0.4257,3.9013701004557655
0.68288,0.4268,3.915914593319688
0.68464,0.4279,3.9304966110544046
0.6864,0.429,3.945116229991271
0.68816,0.4301,3.9597735262470275
0.68992,0.4311999999999999,3.9744685755102145
0.6916800000000001,0.4323,3.9892014532566185
0.6934400000000001,0.4334,4.003972234508913
0.6952,0.43449999999999994,4.018780994055743
0.69696,0.43560000000000004,4.033627806376421
0.69872,0.43670000000000003,4.048512745666024
0.70048,0.43779999999999997,4.063435885750133
0.70224,0.43889999999999996,4.078397300119302
0.7040000000000001,0.44000000000000006,4.09339706199063
0.70576,0.4411,4.108435244240919
0.70752,0.4422,4.123511919558026
0.70928,0.44329999999999997,4.1386271601576095
0.71104,0.44439999999999996,4.153781037946304
0.7128,0.44549999999999995,4.168973624618191
0.71456,0.4466,4.184204991501982
0.7163200000000001,0.44770000000000004,4.1994752097244845
0.71808,0.44880000000000003,4.214784349878232
0.71984,0.4499,4.230132482415581
0.7216,0.451,4.2455196774415365
0.72336,0.4521,4.260946004747041
0.72512,0.4532,4.27641153380959
0.72688,0.4542999999999999,4.2919163338891435
0.7286400000000001,0.4554,4.307460473748426
0.7304,0.4565,4.323044021993672
0.73216,0.45759999999999995,4.338667046898496
0.73392,0.45869999999999994,4.354329616433327
0.73568,0.4598,4.370031798261473
0.73744,0.4609,4.38577365972697
0.7392000000000001,0.4620000000000001,4.4015552678299095
0.7409600000000001,0.4631,4.417376689376678
0.74272,0.4642,4.433237990807549
0.74448,0.4653,4.449139238310221
0.74624,0.4664,4.4650804976553475
0.748,0.46749999999999997,4.481061834448068
0.74976,0.46859999999999996,4.49708331388378
0.7515200000000001,0.4697,4.513145001038835
0.7532800000000001,0.4708,4.529246960504493
0.75504,0.47190000000000004,4.545389256641875
0.7568,0.47300000000000003,4.561571953503988
0.75856,0.4741,4.577795114939912
0.76032,0.4752,4.594058804376175
0.76208,0.47629999999999995,4.610363085120064
0.7638400000000001,0.47740000000000005,4.626708019950027
0.7656000000000001,0.47850000000000004,4.643093671552436
0.76736,0.47959999999999997,4.659520102216371
0.76912,0.48069999999999996,4.675987374080309
0.77088,0.48179999999999995,4.692495548788727
0.77264,0.48289999999999994,4.709044687881729
0.7744,0.484,4.725634852488538
0.7761600000000001,0.4851000000000001,4.742266103583503
0.7779200000000001,0.4862,4.758938501744801
0.77968,0.4873,4.77565210734659
0.78144,0.4884,4.792406980432252
0.7832,0.4895,4.809203180721145
0.78496,0.4906,4.826040767798127
0.78672,0.49169999999999997,4.842919800882051
0.7884800000000001,0.4928,4.859840338914129
0.79024,0.4939,4.876802440568366
0.792,0.49499999999999994,4.893806164168675
0.79376,0.49610000000000004,4.910851567942591
0.79552,0.49720000000000003,4.927938709723731
0.79728,0.49829999999999997,4.945067647148896
0.7990400000000001,0.49940000000000007,4.962238437430029
0.8008000000000001,0.5005000000000001,4.979451137647128
0.80256,0.5016,4.9967058045867905
0.80432,0.5027,5.0140024948491035
0.80608,0.5038,5.031341264569174
0.80784,0.5048999999999999,5.048722169835651
0.8096,0.5059999999999999,5.0661452663382285
0.8113600000000001,0.5071,5.08361060950899
0.8131200000000001,0.5082,5.101118254630235
0.81488,0.5093000000000001,5.118668256566549
0.81664,0.5104000000000001,5.136260670081869
0.8184,0.5115,5.153895549561825
0.82016,0.5126,5.1715729492279525
0.82192,0.5136999999999999,5.189292923004668
0.8236800000000001,0.5148,5.207055524610733
0.8254400000000001,0.5159,5.224860807373425
0.8272,0.517,5.242708824556601
0.82896,0.5181,5.2605996290118755
0.83072,0.5192,5.278533273553914
0.83248,0.5203,5.29650981055478
0.83424,0.5214,5.314529292179075
0.8360000000000001,0.5225000000000001,5.332591770381171
0.8377600000000001,0.5236000000000001,5.350697296889499
0.83952,0.5247,5.368845923225171
0.84128,0.5258,5.387037700648756
0.84304,0.5268999999999999,5.405272680032529
0.8448,0.5279999999999999,5.423550912215461
0.84656,0.5290999999999999,5.441872447722503
0.8483200000000001,0.5302,5.460237336905871
0.8500800000000001,0.5313,5.478645629738734
0.85184,0.5324,5.49709737611475
0.8536,0.5335,5.515592625580029
0.85536,0.5346,5.534131427570545
0.85712,0.5357,5.552713831219829
0.85888,0.5367999999999999,5.57133988558021
0.8606400000000001,0.5379,5.590009639160482
0.8624,0.539,5.608723140565269
0.86416,0.5401,5.627480438006362
0.86592,0.5412,5.646281579664879
0.86768,0.5423,5.665126613214438
0.86944,0.5433999999999999,5.684015586382246
0.8712000000000001,0.5445,5.702948546475183
0.8729600000000001,0.5456000000000001,5.721925540766243
0.87472,0.5467000000000001,5.740946616266716
0.87648,0.5478000000000001,5.76001181970198
0.87824,0.5489,5.779121197633726
0.88,0.5499999999999999,5.79827479641704
0.88176,0.5510999999999999,5.817472662221749
0.8835200000000001,0.5522,5.836714841064804
0.8852800000000001,0.5533,5.856001378613261
0.88704,0.5544,5.875332320430721
0.8888,0.5555,5.894707711869699
0.89056,0.5566,5.914127598139957
0.89232,0.5577,5.933592024143965
0.89408,0.5588,5.953101034734948
0.8958400000000001,0.5599000000000001,5.972654674401917
0.8976000000000001,0.561,5.992252987562769
0.89936,0.5621,6.011896018380817
0.90112,0.5632,6.031583810961791
0.90288,0.5643,6.051316409074479
0.90464,0.5653999999999999,6.07109385630764
0.9064,0.5664999999999999,6.0909161961598475
0.9081600000000001,0.5676,6.110783471903687
0.9099200000000001,0.5687,6.130695726701349
0.91168,0.5698000000000001,6.150653003417548
0.91344,0.5709000000000001,6.170655344740102
0.9152,0.572,6.1907027933267145
0.91696,0.5730999999999999,6.21079539151089
0.91872,0.5741999999999999,6.230933181591501
0.9204800000000001,0.5753,6.251116205571698
0.9222400000000001,0.5764,6.271344505310661
0.924,0.5775,6.291618122538641
0.92576,0.5786,6.3119370988335
0.92752,0.5797,6.3323014756259495
0.92928,0.5808,6.352711294113948
0.93104,0.5819,6.3731665953217
0.9328000000000001,0.5830000000000001,6.393667420179011
0.9345600000000001,0.5841000000000001,6.4142138094544645
0.93632,0.5852,6.4348058037577465
0.93808,0.5863,6.45544344354511
0.93984,0.5874,6.476126769043777
0.9416,0.5884999999999999,6.496855820416152
0.9433600000000001,0.5896,6.517630637697509
0.9451200000000001,0.5907,6.538451260691191
0.94688,0.5918,6.559317729173022
0.94864,0.5929,6.580230082632249
0.9504,0.594,6.601188360420614
0.95216,0.5951,6.622192601909428
0.95392,0.5962,6.643242846240957
0.9556800000000001,0.5973,6.664339132389962
0.9574400000000001,0.5984,6.6854814991607405
0.9592,0.5995,6.7066699853275304
0.96096,0.6006,6.7279046294880605
0.96272,0.6017,6.749185470076275
0.96448,0.6028,6.770512545482463
0.96624,0.6038999999999999,6.791885893867927
0.9680000000000001,0.605,6.813305553319929
0.9697600000000001,0.6061,6.834771561756279
0.97152,0.6072000000000001,6.85628395712571
0.97328,0.6083000000000001,6.877842777011158
0.97504,0.6094,6.89944805905991
0.9768,0.6104999999999999,6.921099840762084
0.97856,0.6115999999999999,6.942798159439015
0.9803200000000001,0.6127,6.964543052372341
0.9820800000000001,0.6138,6.9863345566853186
0.98384,0.6149,7.008172709373327
0.9856,0.616,7.030057547321101
0.98736,0.6171,7.051989107363609
0.98912,0.6182,7.07396742619301
0.99088,0.6193,7.095992540447129
0.9926400000000001,0.6204000000000001,7.118064486512721
0.9944000000000001,0.6215,7.1401833008311595
0.99616,0.6226,7.16234901964476
0.99792,0.6237,7.184561679238168
0.99968,0.6248,7.206821315598505
1.00144,0.6259,7.22912796474609
1.0032,0.627,7.251481662554736
1.00496,0.6281,7.273882444906414
1.00672,0.6292,7.296330347414877
1.00848,0.6303,7.3188254058296325
1.01024,0.6314000000000001,7.341367655576491
1.012,0.6325,7.363957132177724
1.01376,0.6335999999999999,7.386593870931427
1.01552,0.6346999999999999,7.4092779072300985
1.01728,0.6357999999999999,7.432009276212819
1.01904,0.6368999999999999,7.454788013008191
1.0208,0.6379999999999999,7.477614152635389
1.0225600000000001,0.6391,7.500487730088685
1.0243200000000001,0.6402,7.523408780297841
1.02608,0.6413,7.546377338112839
1.02784,0.6424,7.569393438185893
1.0296,0.6435000000000001,7.592457115227319
1.03136,0.6446000000000001,7.615568403880755
1.03312,0.6457,7.638727338708611
1.03488,0.6468,7.661933954170317
1.03664,0.6479,7.68518828464354
1.0384,0.6489999999999999,7.708490364485453
1.04016,0.6500999999999999,7.731840228048058
1.04192,0.6511999999999999,7.755237909541599
1.04368,0.6522999999999999,7.7786834431575596
1.0454400000000001,0.6534000000000001,7.802176862924021
1.0472000000000001,0.6545,7.8257182030003545
1.0489600000000001,0.6556,7.8493074973509644
1.05072,0.6567000000000001,7.872944779977149
1.05248,0.6578,7.896630084762709
1.05424,0.6589,7.920363445570722
1.056,0.66,7.944144896158027
1.05776,0.6611,7.967974470369383
1.05952,0.6622,7.991852201902558
1.06128,0.6633,8.01577812447898
1.06304,0.6643999999999999,8.0397522716181
1.0648,0.6654999999999999,8.063774677036735
1.06656,0.6666,8.08784537422782
1.06832,0.6677,8.111964396738866
1.0700800000000001,0.6688000000000001,8.136131778072055
1.0718400000000001,0.6699,8.1603475516609
1.0736,0.671,8.184611750898904
1.07536,0.6721,8.20892440918884
1.07712,0.6732,8.233285559916858
1.07888,0.6743,8.257695236429422
1.08064,0.6754,8.282153471985886
1.0824,0.6765,8.306660299847032
1.08416,0.6776,8.33121575331362
1.08592,0.6787,8.3558198656295
1.08768,0.6798,8.38047266999043
1.08944,0.6809,8.405174199568526
1.0912,0.6819999999999999,8.429924487466902
1.09296,0.6830999999999999,8.454723566942008
1.0947200000000001,0.6842,8.47957147113385
1.0964800000000001,0.6853,8.504468233182676
1.09824,0.6864,8.52941388607258
1.1,0.6875,8.554408463014934
1.10176,0.6886,8.579451997074518
1.10352,0.6897,8.604544521343813
1.10528,0.6908,8.62968606888513
1.10704,0.6919000000000001,8.654876672737334
1.1088,0.693,8.680116365980632
1.11056,0.6940999999999999,8.705405181666404
1.11232,0.6951999999999999,8.730743152879368
1.11408,0.6962999999999999,8.756130312683194
1.11584,0.6973999999999999,8.7815666940995
1.1176000000000001,0.6985000000000001,8.807052330175212
1.1193600000000001,0.6996,8.832587253982608
1.1211200000000001,0.7007,8.858171498638987
1.12288,0.7018,8.88380509715351
1.12464,0.7029,8.909488082606721
1.1264,0.704,8.935220488106237
1.12816,0.7051000000000001,8.96100234667433
1.12992,0.7062,8.986833691536955
1.13168,0.7073,9.012714555788827
1.13344,0.7084,9.038644972466882
1.1352,0.7094999999999999,9.064624974773599
1.13696,0.7105999999999999,9.090654595841075
1.13872,0.7116999999999999,9.116733868912657
1.14048,0.7127999999999999,9.142862827173225
1.1422400000000001,0.7139000000000001,9.169041503761393
1.1440000000000001,0.7150000000000001,9.195269931932462
1.1457600000000001,0.7161,9.221548144945764
1.14752,0.7172000000000001,9.247876176149123
1.14928,0.7183,9.274254058824335
1.15104,0.7194,9.300681826210795
1.1528,0.7205,9.327159511707597
1.15456,0.7216,9.35368714873577
1.15632,0.7227,9.380264770685647
1.15808,0.7238,9.4068924109934
1.15984,0.7249,9.433570103137269
1.1616,0.7259999999999999,9.460297880561477
1.16336,0.7271,9.487075776851677
1.16512,0.7282,9.513903825611118
1.1668800000000001,0.7293000000000001,9.540782060444693
1.1686400000000001,0.7304,9.567710514922211
1.1704,0.7315,9.594689222756553
1.17216,0.7326,9.621718217643627
1.17392,0.7336999999999999,9.648797533426537
1.17568,0.7348,9.67592720387993
1.17744,0.7359000000000001,9.703107262768754
1.1792,0.737,9.730337744003611
1.18096,0.7381,9.757618681554371
1.18272,0.7392,9.78495010937707
1.18448,0.7403,9.812332061539939
1.18624,0.7413999999999998,9.839764572019199
1.188,0.7424999999999999,9.86724767493042
1.1897600000000002,0.7436,9.894781404497829
1.1915200000000001,0.7447,9.922365794944698
1.1932800000000001,0.7458,9.950000880490947
1.19504,0.7469,9.977686695483289
1.1968,0.7480000000000001,10.005423274319462
1.19856,0.7491,10.033210651321388
1.20032,0.7502000000000001,10.061048861073175
1.20208,0.7513,10.088937938101731
1.20384,0.7524000000000001,10.11687791694352
1.2056,0.7535,10.14486883227435
1.20736,0.7545999999999999,10.172910718800713
1.20912,0.7556999999999999,10.201003611324463
1.21088,0.7567999999999999,10.229147544713099
1.21264,0.7579,10.257342553761392
1.2144000000000001,0.7590000000000001,10.285588673467842
1.2161600000000001,0.7601,10.31388593884099
1.2179200000000001,0.7612,10.342234385001001
1.21968,0.7623000000000001,10.370634047107854
1.22144,0.7634,10.399084960337117
1.2232,0.7645000000000001,10.427587159955184
1.22496,0.7656,10.456140681303744
1.22672,0.7667,10.48474555987974
1.22848,0.7677999999999999,10.513401831206538
1.23024,0.7689,10.542109530663845
1.232,0.7699999999999999,10.570868694034475
1.23376,0.7710999999999999,10.599679357022792
1.23552,0.7722,10.62854155534868
1.23728,0.7732999999999999,10.657455324786584
1.2390400000000001,0.7744000000000001,10.686420701410036
1.2408000000000001,0.7755000000000001,10.715437721179184
1.24256,0.7766000000000001,10.744506420140949
1.24432,0.7777,10.773626834456671
1.24608,0.7788,10.802799000348902
1.24784,0.7798999999999999,10.832022954169942
1.2496,0.781,10.861298732277978
1.25136,0.7820999999999999,10.890626371148464
1.25312,0.7832,10.92000590734836
1.25488,0.7843,10.94943737745351
1.25664,0.7854,10.978920818261289
1.2584,0.7865,11.00845626648216
1.26016,0.7875999999999999,11.038043759083862
1.2619200000000002,0.7887000000000001,11.067683332972823
1.2636800000000001,0.7898000000000001,11.097375025231813
1.2654400000000001,0.7909,11.127118872961518
1.2672,0.7919999999999999,11.156914913446458
1.26896,0.7931,11.186763183904084
1.27072,0.7941999999999999,11.216663721857744
1.27248,0.7953,11.24661656468794
1.27424,0.7964000000000001,11.276621749983155
1.276,0.7975,11.306679315459402
1.27776,0.7986,11.336789298851912
1.27952,0.7997,11.366951737926437
1.28128,0.8008,11.397166670780184
1.28304,0.8018999999999998,11.427434135318823
1.2848,0.8029999999999999,11.457754169728297
1.2865600000000001,0.8041,11.4881268122241
1.2883200000000001,0.8052,11.5185521010477
1.2900800000000001,0.8063,11.549030074705344
1.29184,0.8074,11.57956077167313
1.2936,0.8084999999999999,11.610144230457733
1.29536,0.8096,11.640780489819685
1.29712,0.8107000000000001,11.671469588629009
1.29888,0.8118,11.702211565633691
1.30064,0.8129000000000001,11.733006459932257
1.3024,0.814,11.763854310491807
1.30416,0.8150999999999999,11.794755156625014
1.30592,0.8161999999999999,11.825709037499914
1.30768,0.8172999999999999,11.85671599262555
1.30944,0.8183999999999998,11.887776061363425
1.3112000000000001,0.8195000000000001,11.918889283355613
1.3129600000000001,0.8206,11.95005569829909
1.31472,0.8217,11.98127534593292
1.31648,0.8228000000000001,12.012548266250434
1.31824,0.8239,12.0438744991468
1.32,0.8250000000000001,12.075254084757692
1.32176,0.8261,12.1066870632453
1.32352,0.8272,12.138173475019018
1.32528,0.8282999999999999,12.169713360345657
1.32704,0.8294,12.201306759856726
1.3288,0.8304999999999999,12.232953714137272
1.33056,0.8315999999999999,12.26465426390092
1.33232,0.8327,12.296408450013386
1.3340800000000002,0.8338000000000001,12.328216313342544
1.3358400000000001,0.8349000000000001,12.360077895068628
1.3376000000000001,0.8360000000000001,12.39199323623405
1.33936,0.8371000000000001,12.423962378163376
1.34112,0.8382,12.455985362245462
1.34288,0.8393,12.488062229809502
1.34464,0.8403999999999999,12.520193022618848
1.3464,0.8415,12.552377782361415
1.34816,0.8425999999999999,12.584616550715163
1.34992,0.8437,12.616909369756389
1.35168,0.8448,12.64925628146559
1.35344,0.8459,12.681657327903741
1.3552,0.847,12.714112551415381
1.35696,0.8480999999999999,12.74662199433545
1.3587200000000001,0.8492000000000001,12.779185699170004
1.3604800000000001,0.8503000000000001,12.811803708429824
1.3622400000000001,0.8514,12.844476064947386
1.364,0.8525,12.877202811310266
1.36576,0.8536,12.909983990693027
1.36752,0.8546999999999999,12.942819646033332
1.36928,0.8558,12.975709820482718
1.37104,0.8568999999999999,13.008654557242151
1.3728,0.858,13.041653899820565
1.37456,0.8591,13.074707891636514
1.37632,0.8602,13.107816576346384
1.37808,0.8613,13.140979997575785
1.37984,0.8623999999999998,13.174198199254194
1.3816,0.8634999999999999,13.207471225308092
1.3833600000000001,0.8646,13.240799119845812
1.3851200000000001,0.8657,13.27418192692637
1.3868800000000001,0.8668,13.307619690989487
1.38864,0.8679,13.341112456403877
1.3904,0.8689999999999999,13.374660267712237
1.39216,0.8701,13.40826316952778
1.39392,0.8712000000000001,13.441921206678131
1.39568,0.8723,13.475634423958478
1.39744,0.8734000000000001,13.509402866446472
1.3992,0.8744999999999999,13.543226579209755
1.40096,0.8755999999999999,13.577105607553271
1.40272,0.8766999999999999,13.61103999671068
1.40448,0.8777999999999999,13.645029792282804
1.4062400000000002,0.8789,13.679075039702875
1.4080000000000001,0.8800000000000001,13.713175784849444
1.4097600000000001,0.8811,13.747332073391235
1.41152,0.8822,13.78154395136224
1.41328,0.8833000000000001,13.815811464751462
1.41504,0.8844,13.85013465981732
1.4168,0.8855000000000001,13.884513582782168
1.41856,0.8865999999999999,13.918948280094131
1.42032,0.8877,13.9534387982461
1.42208,0.8887999999999999,13.987985183924806
1.42384,0.8899,14.022587483855524
1.4256,0.8909999999999999,14.057245745021671
1.42736,0.8920999999999999,14.091960014324817
1.42912,0.8932,14.126730338881782
1.4308800000000002,0.8943000000000001,14.16155676599677
1.4326400000000001,0.8954000000000001,14.196439343022838
1.4344000000000001,0.8965000000000001,14.231378117358936
1.43616,0.8976000000000001,14.266373136718926
1.43792,0.8986999999999999,14.301424448747936
1.43968,0.8998,14.336532101290397
1.44144,0.9008999999999999,14.371696142378047
1.4432,0.902,14.406916619961438
1.44496,0.9030999999999999,14.442193582303085
1.44672,0.9042,14.477527077734393
1.44848,0.9053,14.512917154573001
1.45024,0.9064,14.548363861511273
1.452,0.9075,14.583867247246593
1.45376,0.9085999999999999,14.61942736033015
1.4555200000000001,0.9097000000000001,14.655044249917308
1.4572800000000001,0.9108,14.690717964879639
1.4590400000000001,0.9119,14.726448554417923
1.4608,0.913,14.762236067802219
1.46256,0.9141,14.798080554396002
1.46432,0.9151999999999999,14.833982063732316
1.46608,0.9163,14.869940645413342
1.46784,0.9173999999999999,14.905956349172639
1.4696,0.9185,14.942029224868714
1.47136,0.9196,14.978159322430816
1.47312,0.9207,15.014346691985114
1.47488,0.9218,15.05059138382788
1.47664,0.9228999999999999,15.086893448142275
1.4784000000000002,0.9240000000000002,15.12325293548743
1.4801600000000001,0.9251,15.159669896404365
1.4819200000000001,0.9262,15.196144381491495
1.48368,0.9273,15.232676441650165
1.48544,0.9284,15.269266127795923
1.4872,0.9294999999999999,15.305913490943444
1.48896,0.9306,15.342618582209361
1.49072,0.9317000000000001,15.379381452934407
1.49248,0.9328,15.416202154436354
1.49424,0.9339000000000001,15.453080738296036
1.496,0.9349999999999999,15.490017256053575
1.49776,0.9360999999999999,15.527011759560395
1.49952,0.9371999999999999,15.564064300559808
1.50128,0.9382999999999999,15.601174931109622
1.5030400000000002,0.9394,15.638343703257883
1.5048000000000001,0.9405000000000001,15.675570669191911
1.5065600000000001,0.9416,15.712855881277337
1.50832,0.9427,15.750199391923898
1.51008,0.9438000000000001,15.787601253670307
1.51184,0.9449,15.825061519247598
1.5136,0.9460000000000001,15.862580241346226
1.51536,0.9470999999999999,15.900157472998592
1.51712,0.9482,15.937793267131338
1.51888,0.9492999999999999,15.975487676839252
1.52064,0.9504,16.013240755462043
1.5224,0.9514999999999999,16.051052556293996
1.52416,0.9525999999999999,16.08892313287296
1.5259200000000002,0.9537,16.12685253867823
1.5276800000000001,0.9548000000000001,16.164840827566806
1.5294400000000001,0.9559,16.202888053079207
1.5312000000000001,0.9570000000000001,16.240994269449033
1.53296,0.9581000000000001,16.279159530623353
1.53472,0.9591999999999999,16.317383890677192
1.53648,0.9603,16.35566740391633
1.53824,0.9613999999999999,16.394010124767696
1.54,0.9625,16.432412107646982
1.54176,0.9635999999999999,16.47087340727159
1.54352,0.9647,16.50939407825329
1.54528,0.9657999999999999,16.547974175416147
1.54704,0.9669,16.586613753777
1.5488,0.968,16.625312868351596
1.5505600000000002,0.9691000000000001,16.664071574215548
1.5523200000000001,0.9702000000000002,16.70288992678444
1.5540800000000001,0.9713,16.74176798136862
1.5558400000000001,0.9724,16.78070579346287
1.5576,0.9735,16.81970341869663
1.55936,0.9746,16.858760912725224
1.56112,0.9756999999999999,16.897878331381584
1.56288,0.9768,16.937055730672462
1.56464,0.9778999999999999,16.976293166563746
1.5664,0.979,17.015590695227896
1.56816,0.9801000000000001,17.05494837288965
1.56992,0.9812,17.094366255940987
1.57168,0.9823,17.133844400840164
1.57344,0.9833999999999999,17.173382864186856
1.5752000000000002,0.9845000000000002,17.212981702610886
1.5769600000000001,0.9856,17.25264097297691
1.5787200000000001,0.9867,17.292360732102207
1.58048,0.9878,17.33214103708637
1.58224,0.9889,17.37198194492971
1.584,0.9899999999999999,17.411883512959733
1.58576,0.9911,17.45184579839899
1.58752,0.9922000000000001,17.491868858768385
1.58928,0.9933,17.5319527514959
1.59104,0.9944000000000001,17.57209753429287
1.5928,0.9954999999999999,17.612303264899783
1.59456,0.9965999999999999,17.65257000106535
1.59632,0.9976999999999999,17.69289780083348
1.5980800000000002,0.9988000000000001,17.733286722177315
1.5998400000000002,0.9999,17.773736823264173
1.6016000000000001,0.9999999999999999,17.755987989303712
1.6033600000000001,0.9999999999999999,17.73306613752521
1.60512,0.9999999999999999,17.710810746138996
1.60688,0.9999999999999999,17.689173863659764
1.60864,0.9999999999999999,17.668111522340553
1.6104,0.9999999999999999,17.647583384960452
1.61216,0.9999999999999999,17.627552426850247
1.61392,0.9999999999999999,17.607984648352424
1.61568,0.9999999999999999,17.58884881506247
1.61744,0.9999999999999999,17.570116221812164
1.6192,0.9999999999999999,17.551760478459716
1.62096,0.9999999999999999,17.533757314800656
1.6227200000000002,0.9999999999999999,17.51608440296644
1.6244800000000001,0.9999999999999999,17.498721195105148
1.6262400000000001,0.9999999999999999,17.481648775734474
1.6280000000000001,0.9999999999999999,17.46484972619121
1.62976,0.9999999999999999,17.448308000945467
1.63152,0.9999999999999999,17.432008814539
1.63328,0.9999999999999999,17.415938537937688
1.63504,0.9999999999999999,17.40008460357825
1.6368,0.9999999999999999,17.384435418465944
1.63856,0.9999999999999999,17.368980284478766
1.64032,0.9999999999999999,17.35370932531704
1.64208,0.9999999999999999,17.338613419524183
1.64384,0.9999999999999999,17.323684138968968
1.6456,0.9999999999999999,17.308913692708312
1.6473600000000002,0.9999999999999999,17.294294875099062
1.6491200000000001,0.9999999999999999,17.279821018387505
1.6508800000000001,0.9999999999999999,17.26548594922417
1.65264,0.9999999999999999,17.25128394879823
1.6544,0.9999999999999999,17.23720971601824
1.65616,0.9999999999999999,17.223258334048953
1.65792,0.9999999999999999,17.20942523906112
1.65968,0.9999999999999999,17.19570619242969
1.66144,0.9999999999999999,17.182097254163065
1.6632,0.9999999999999999,17.168594759379268
1.66496,0.9999999999999999,17.155195296319825
1.66672,0.9999999999999999,17.14189568574685
1.66848,0.9999999999999999,17.12869296312595
1.6702400000000002,0.9999999999999999,17.115584361099856
1.6720000000000002,0.9999999999999999,17.102567294228248
1.6737600000000001,0.9999999999999999,17.089639344350154
1.6755200000000001,0.9999999999999999,17.076798247730007
1.67728,0.9999999999999999,17.06404188265417
1.67904,0.9999999999999999,17.05136825859821
1.6808,0.9999999999999999,17.03877550590627
1.68256,0.9999999999999999,17.02626186629879
1.68432,0.9999999999999999,17.01382568446837
1.68608,0.9999999999999999,17.001465400020503
1.68784,0.9999999999999999,16.989179540279316
1.6896,0.9999999999999999,16.976966713506346
1.69136,0.9999999999999999,16.96482560291772
1.69312,0.9999999999999999,16.952754960844242
1.6948800000000002,0.9999999999999999,16.940753603620905
1.6966400000000001,0.9999999999999999,16.928820406931376
1.6984000000000001,0.9999999999999999,16.916954301172904
1.7001600000000001,0.9999999999999999,16.90515426758523
1.70192,0.9999999999999999,16.89341933468839
1.70368,0.9999999999999999,16.88174857441141
1.70544,0.9999999999999999,16.870141099434434
1.7072,0.9999999999999999,16.858596059913612
1.70896,0.9999999999999999,16.847112641240223
1.71072,0.9999999999999999,16.835690061029172
1.71248,0.9999999999999999,16.824327567434825
1.71424,0.9999999999999999,16.81302443666713
1.716,0.9999999999999999,16.801779971366415
1.71776,0.9999999999999999,16.790593498588237
1.7195200000000002,0.9999999999999999,16.779464368315686
1.7212800000000001,0.9999999999999999,16.768391951962897
1.7230400000000001,0.9999999999999999,16.757375641044387
1.7248,0.9999999999999999,16.746414845669133
1.72656,0.9999999999999999,16.73550899370232
1.72832,0.9999999999999999,16.724657529409406
1.73008,0.9999999999999999,16.71385991256321
1.73184,0.9999999999999999,16.703115617555202
1.7336,0.9999999999999999,16.692424132523676
1.73536,0.9999999999999999,16.681784958407913
1.73712,0.9999999999999999,16.67119760856358
1.73888,0.9999999999999999,16.660661607628867
1.74064,0.9999999999999999,16.65017649139333
1.7424000000000002,0.9999999999999999,16.63974180581089
1.7441600000000002,0.9999999999999999,16.629357106703083
1.7459200000000001,0.9999999999999999,16.61902195919317
1.7476800000000001,0.9999999999999999,16.60873593720841
1.74944,0.9999999999999999,16.59849862307082
1.7512,0.9999999999999999,16.58830960732673
1.75296,0.9999999999999999,16.5781684877125
1.75472,0.9999999999999999,16.56807486974414
1.75648,0.9999999999999999,16.558028365770305
1.75824,0.9999999999999999,16.548028594658525
1.76,0.,0.