File: Module2/strain01.txt
SAMPLE PARAMETERS
Gauge length [mm]: 22.2961
Area [mm2]: 65.6805
EXPERIMENTAL PARAMETERS
Time [s]: 0.11
Number of steps: 1000
Displacement (0) or force control (1): 0
Schedule ID: 0
Point 1,0.,0.
Point 2,0.1,1.
Point 3,0.11,1.
RESULTS
Time [s],Displacement [mm],Force [N]
0.,0.,0.
0.00011,0.0011,0.013713417258223497
0.00022,0.0022,0.027400579656351228
0.00033,0.0033000000000000004,0.041062428520680865
0.00044,0.0044,0.05469989330853764
0.00055,0.0055000000000000005,0.06831389129445724
0.00066,0.006600000000000001,0.08190532857383184
0.0007700000000000001,0.0077,0.09547509938120954
0.00088,0.0088,0.10902408701832629
0.00099,0.0099,0.12255316343411632
0.0011,0.011000000000000001,0.1360631899184194
0.0012100000000000001,0.012100000000000003,0.14955501705427407
0.00132,0.013200000000000002,0.1630294850358942
0.00143,0.0143,0.17648742347736143
0.0015400000000000001,0.0154,0.18992965209495488
0.00165,0.0165,0.20335698043158837
0.00176,0.0176,0.21677020843312195
0.0018700000000000001,0.0187,0.23017012631576123
0.00198,0.0198,0.2435575148667989
0.0020900000000000003,0.020900000000000005,0.2569331453074051
0.0022,0.022000000000000002,0.27029777998951615
0.00231,0.0231,0.2836521721971318
0.0024200000000000003,0.024200000000000006,0.29699706622097855
0.00253,0.0253,0.310333197774943
0.00264,0.026400000000000003,0.3236612939683256
0.0027500000000000003,0.027500000000000004,0.33698207333941327
0.00286,0.0286,0.3502962463426937
0.00297,0.0297,0.3636045150938461
0.0030800000000000003,0.0308,0.3769075738524286
0.00319,0.031900000000000005,0.39020610881134427
0.0033,0.033,0.4035007985945935
0.0034100000000000003,0.034100000000000005,0.4167923140574546
0.00352,0.0352,0.4300813185045257
0.00363,0.0363,0.44336846800947005
0.0037400000000000003,0.0374,0.45665441126159545
0.00385,0.0385,0.4699397898809907
0.00396,0.0396,0.4832252383706342
0.00407,0.0407,0.49651138439767606
0.0041800000000000006,0.04180000000000001,0.5097988487904638
0.00429,0.0429,0.5230882457473417
0.0044,0.044000000000000004,0.5363801827885033
0.00451,0.045099999999999994,0.5496752610561311
0.00462,0.0462,0.5629740753311063
0.00473,0.0473,0.5762772140492155
0.0048400000000000006,0.04840000000000001,0.58958525951862
0.00495,0.0495,0.6028987881936722
0.00506,0.0506,0.6162183702936397
0.00517,0.0517,0.6295445702953983
0.00528,0.05280000000000001,0.6428779471026932
0.00539,0.053899999999999997,0.6562190536833648
0.0055000000000000005,0.05500000000000001,0.6695684376018116
0.00561,0.056100000000000004,0.6829266410317703
0.00572,0.0572,0.6962942005686477
0.00583,0.0583,0.7096716476495372
0.00594,0.0594,0.7230595086330316
0.00605,0.060500000000000005,0.7364583045991463
0.0061600000000000005,0.0616,0.7498685516915682
0.00627,0.0627,0.7632907611650946
0.00638,0.06380000000000001,0.7767254393381156
0.00649,0.0649,0.7901730879286789
0.0066,0.066,0.8036342038637801
0.00671,0.06709999999999999,0.8171092794891712
0.0068200000000000005,0.06820000000000001,0.8305988027599024
0.00693,0.0693,0.8441032571325551
0.00704,0.0704,0.8576231217152609
0.00715,0.07150000000000001,0.871158871295281
0.00726,0.0726,0.8847109765863421
0.007370000000000001,0.0737,0.8982799042599603
0.0074800000000000005,0.0748,0.9118661166363333
0.00759,0.07590000000000001,0.9254700725674433
0.0077,0.077,0.9390922265176675
0.00781,0.0781,0.9527330294900275
0.00792,0.0792,0.9663929285531091
0.00803,0.0803,0.9800723672033058
0.00814,0.0814,0.9937717854570179
0.00825,0.0825,1.0074916194393277
0.008360000000000001,0.08360000000000002,1.0212323022340417
0.00847,0.0847,1.0349942632444977
0.00858,0.0858,1.048777928813092
0.00869,0.0869,1.0625837217363
0.0088,0.08800000000000001,1.0764120617904915
0.00891,0.0891,1.090263365619189
0.00902,0.09019999999999999,1.1041380468503663
0.009130000000000001,0.0913,1.118036515857989
0.00924,0.0924,1.1319591804924831
0.00935,0.0935,1.1459064453919778
0.00946,0.0946,1.1598787124092858
0.00957,0.09570000000000001,1.1738763809203923
0.009680000000000001,0.09680000000000002,1.187899847260458
0.00979,0.09789999999999999,1.2019495054044167
0.0099,0.099,1.2160257465578603
0.01001,0.1001,1.2301289595074254
0.01012,0.1012,1.2442595305668027
0.01023,0.10229999999999999,1.2584178435617308
0.01034,0.1034,1.272604280058496
0.010450000000000001,0.10450000000000001,1.2868192193944168
0.01056,0.10560000000000001,1.301063038374192
0.01067,0.1067,1.315336111931764
0.01078,0.10779999999999999,1.32963881262741
0.01089,0.1089,1.3439715110136903
0.011000000000000001,0.11000000000000001,1.358334575706227
0.01111,0.1111,1.3727283731541187
0.01122,0.11220000000000001,1.3871532679989675
0.01133,0.11330000000000001,1.40160962292739
0.01144,0.1144,1.416097798595051
0.011550000000000001,0.1155,1.4306181543714398
0.01166,0.1166,1.4451710473122288
0.011770000000000001,0.11770000000000001,1.4597568331991906
0.01188,0.1188,1.4743758657589487
0.01199,0.1199,1.4890284974661352
0.0121,0.12100000000000001,1.5037150789105171
0.01221,0.1221,1.5184359593925565
0.012320000000000001,0.1232,1.533191486613435
0.01243,0.1243,1.5479820067737535
0.01254,0.1254,1.5628078648555457
0.01265,0.1265,1.5776694042011348
0.01276,0.12760000000000002,1.5925669670303508
0.012870000000000001,0.1287,1.6075008942294273
0.01298,0.1298,1.6224715254540172
0.013090000000000001,0.13090000000000002,1.6374791990210489
0.0132,0.132,1.6525242521998582
0.01331,0.1331,1.6676070210561136
0.01342,0.13419999999999999,1.6827278406012316
0.01353,0.1353,1.6978870447205436
0.013640000000000001,0.13640000000000002,1.7130849663437449
0.01375,0.13749999999999998,1.7283219372452023
0.01386,0.1386,1.7435982883323857
0.01397,0.1397,1.7589143496084167
0.01408,0.1408,1.7742704500906439
0.014190000000000001,0.14190000000000003,1.7896669179793039
0.0143,0.14300000000000002,1.805104080562821
0.014410000000000001,0.1441,1.8205822642925655
0.01452,0.1452,1.8361017950450453
0.01463,0.1463,1.8516629976586432
0.014740000000000001,0.1474,1.8672661963699346
0.01485,0.1485,1.8829117146942493
0.014960000000000001,0.1496,1.898599875518591
0.01507,0.1507,1.9143310010051484
0.01518,0.15180000000000002,1.9301054126787176
0.01529,0.15289999999999998,1.9459234315553915
0.0154,0.154,1.9617853779317576
0.015510000000000001,0.15510000000000002,1.9776915717010597
0.01562,0.1562,1.9936423320670134
0.01573,0.15730000000000002,2.0096379778365403
0.01584,0.1584,2.0256788272978734
0.01595,0.1595,2.0417651983354563
0.01606,0.1606,2.0578974081957564
0.01617,0.16169999999999998,2.07407577387576
0.01628,0.1628,2.09030061189198
0.016390000000000002,0.16390000000000002,2.1065722382757293
0.0165,0.165,2.122890968990278
0.01661,0.1661,2.1392571192499372
0.016720000000000002,0.16720000000000004,2.1556710042685188
0.01683,0.1683,2.172132938656475
0.01694,0.1694,2.188643236968415
0.01705,0.17049999999999998,2.205202213174661
0.01716,0.1716,2.221810181324499
0.01727,0.17270000000000002,2.238467454965872
0.01738,0.1738,2.2551743474720003
0.017490000000000002,0.1749,2.271931171788758
0.0176,0.17600000000000002,2.2887382411046353
0.01771,0.17709999999999998,2.3055958679197825
0.01782,0.1782,2.3225043647439905
0.01793,0.17930000000000001,2.3394640438394596
0.01804,0.18039999999999998,2.356475217465135
0.01815,0.1815,2.3735381974471523
0.018260000000000002,0.1826,2.3906532956351803
0.01837,0.18370000000000003,2.4078208236192267
0.01848,0.1848,2.4250410929575947
0.018590000000000002,0.18590000000000004,2.4423144149970453
0.0187,0.187,2.4596411009910852
0.01881,0.1881,2.4770214621172433
0.01892,0.1892,2.494455809369303
0.019030000000000002,0.1903,2.511944453585731
0.01914,0.19140000000000001,2.5294877056863814
0.01925,0.19249999999999998,2.5470858763744215
0.019360000000000002,0.19360000000000005,2.564739276233172
0.01947,0.1947,2.582448215874165
0.01958,0.19579999999999997,2.600213005738929
0.01969,0.1969,2.618033956246701
0.0198,0.198,2.6359113777180756
0.01991,0.19910000000000003,2.653845580426692
0.02002,0.2002,2.671836874507679
0.020130000000000002,0.20130000000000003,2.68988557023627
0.02024,0.2024,2.7079919774663357
0.02035,0.20350000000000001,2.7261564063664214
0.02046,0.20459999999999998,2.744379166800298
0.02057,0.2057,2.7626605686785655
0.02068,0.2068,2.7810009218476623
0.02079,0.20789999999999997,2.799400536055756
0.020900000000000002,0.20900000000000002,2.817859720938454
0.02101,0.2101,2.836378786256871
0.02112,0.21120000000000003,2.854958041480722
0.021230000000000002,0.21230000000000002,2.8735977961832964
0.02134,0.2134,2.8922983598608982
0.02145,0.2145,2.9110600418482036
0.02156,0.21559999999999999,2.929883151485725
0.021670000000000002,0.21670000000000003,2.948767998043725
0.02178,0.2178,2.967714890569984
0.02189,0.2189,2.9867241383461716
0.022000000000000002,0.22000000000000003,3.005796050227052
0.02211,0.2211,3.02493093522838
0.02222,0.2222,3.044129102088567
0.02233,0.22329999999999997,3.0633908596780546
0.02244,0.22440000000000002,3.082716516610612
0.02255,0.2255,3.1021063813065313
0.02266,0.22660000000000002,3.121560762379333
0.022770000000000002,0.2277,3.141079967973346
0.02288,0.2288,3.1606643064320026
0.02299,0.2299,3.180314085704124
0.023100000000000002,0.231,3.2000296138211217
0.02321,0.23210000000000003,3.2198111985317293
0.02332,0.2332,3.2396591475370062
0.02343,0.2343,3.2595737682927344
0.023540000000000002,0.23540000000000003,3.279555368228193
0.02365,0.2365,3.299604254387913
0.02376,0.2376,3.3197207339105805
0.023870000000000002,0.23870000000000002,3.33990511356251
0.02398,0.2398,3.360157700032659
0.02409,0.2409,3.380478799799378
0.0242,0.24200000000000002,3.4008687190444453
0.024310000000000002,0.2431,3.42132776375274
0.02442,0.2442,3.4418562398939514
0.02453,0.2453,3.4624544528969388
0.024640000000000002,0.2464,3.4831227082239047
0.02475,0.24750000000000003,3.503861310868524
0.02486,0.2486,3.524670565843323
0.024970000000000003,0.2497,3.5455507775826853
0.02508,0.2508,3.5665022505004167
0.02519,0.2519,3.587525288492394
0.0253,0.253,3.6086201954759503
0.025410000000000002,0.2541,3.629787274776745
0.02552,0.25520000000000004,3.651026829563346
0.02563,0.2563,3.6723391626872934
0.025740000000000002,0.2574,3.693724576562886
0.02585,0.2585,3.7151833734115547
0.02596,0.2596,3.7367158549477604
0.02607,0.2607,3.758322322582914
0.026180000000000002,0.26180000000000003,3.780003077427755
0.02629,0.2629,3.8017584202419212
0.0264,0.264,3.8235886512877535
0.026510000000000002,0.26510000000000006,3.8454940703630682
0.02662,0.2662,3.8674749770552093
0.02673,0.2673,3.8895316704234957
0.02684,0.26839999999999997,3.9116644490679375
0.02695,0.2695,3.9338736112021735
0.02706,0.2706,3.9561594545685446
0.02717,0.2717,3.978522276470096
0.027280000000000002,0.27280000000000004,4.000962373672961
0.02739,0.27390000000000003,4.023480042524409
0.0275,0.27499999999999997,4.046075578826759
0.027610000000000003,0.2761,4.068749277933986
0.02772,0.2772,4.091501434718383
0.02783,0.2783,4.114332343355407
0.02794,0.2794,4.137242297640743
0.028050000000000002,0.2805,4.1602315908304766
0.02816,0.2816,4.183300515460072
0.02827,0.2827,4.206449363636685
0.028380000000000002,0.28380000000000005,4.2296784269297945
0.02849,0.2849,4.252987996213266
0.0286,0.28600000000000003,4.276378361728358
0.02871,0.28709999999999997,4.299849813202832
0.028820000000000002,0.2882,4.323402639782495
0.02893,0.2893,4.347037129821103
0.02904,0.2904,4.370753571116077
0.029150000000000002,0.29150000000000004,4.394552250860604
0.02926,0.2926,4.418433455531198
0.02937,0.2937,4.442397470942379
0.029480000000000003,0.2948,4.466444582153028
0.02959,0.29590000000000005,4.490575073739042
0.0297,0.297,4.514789229180863
0.02981,0.2981,4.539087331747126
0.029920000000000002,0.2992,4.563469663549581
0.03003,0.3003,4.587936506192661
0.03014,0.3014,4.612488140519402
0.030250000000000003,0.30250000000000005,4.637124846523448
0.03036,0.30360000000000004,4.661846903502615
0.03047,0.3047,4.68665458990788
0.03058,0.30579999999999996,4.7115481835355615
0.030690000000000002,0.3069,4.73652796130083
0.0308,0.308,4.761594199254179
0.03091,0.3091,4.786747172823578
0.031020000000000002,0.31020000000000003,4.8119871563734264
0.03113,0.3113,4.837314423607296
0.03124,0.3124,4.862729247273349
0.03135,0.3135,4.888231899352784
0.03146,0.31460000000000005,4.913822650975765
0.03157,0.3157,4.939501772297191
0.03168,0.3168,4.965269532730572
0.03179,0.31789999999999996,4.991126200572703
0.0319,0.319,5.017072043569648
0.032010000000000004,0.32010000000000005,5.043107328219856
0.03212,0.3212,5.069232320300415
0.03223,0.32230000000000003,5.0954472846971814
0.03234,0.32339999999999997,5.121752485096225
0.03245,0.3245,5.148148184565423
0.03256,0.3256,5.174634644974504
0.032670000000000005,0.32670000000000005,5.201212127485116
0.032780000000000004,0.32780000000000004,5.227880892059391
0.03289,0.3289,5.254641197796768
0.033,0.33,5.281493302810167
0.03311,0.3311,5.308437464217436
0.03322,0.3322,5.3354739380360074
0.03333,0.3333,5.3626029794334595
0.033440000000000004,0.3344000000000001,5.389824842486384
0.03355,0.3355,5.4171397803816355
0.03366,0.3366,5.444548045004212
0.03377,0.3377,5.47204988732487
0.03388,0.3388,5.499645557469914
0.03399,0.3399,5.527335304232724
0.0341,0.34099999999999997,5.55511937551095
0.034210000000000004,0.34210000000000007,5.582998018100204
0.03432,0.3432,5.610971477751582
0.03443,0.3443,5.639039999038792
0.03454,0.34540000000000004,5.667203825522027
0.03465,0.3465,5.69546319979398
0.03476,0.3476,5.723818363048361
0.03487,0.3487,5.752269555737452
0.034980000000000004,0.3498,5.7808170168869975
0.03509,0.35090000000000005,5.8094609846364085
0.0352,0.35200000000000004,5.838201695900083
0.03531,0.35309999999999997,5.867039386416746
0.03542,0.35419999999999996,5.895974290993072
0.03553,0.3553,5.925006643071763
0.03564,0.3564,5.9541366750391544
0.035750000000000004,0.35750000000000004,5.9833646182008975
0.03586,0.35860000000000003,6.012690702577644
0.03597,0.3597,6.0421151571305005
0.03608,0.36079999999999995,6.07163820975064
0.03619,0.3619,6.10126008693064
0.0363,0.363,6.130981014097483
0.03641,0.3641,6.160801215624301
0.036520000000000004,0.3652,6.190720914368945
0.03663,0.3663,6.220740332504938
0.03674,0.36740000000000006,6.2508596905116
0.03685,0.3685,6.281079208020188
0.03696,0.3696,6.311399103371208
0.03707,0.3707,6.341819593522636
0.037180000000000005,0.3718000000000001,6.37234089454585
0.037290000000000004,0.3729,6.4029632211103795
0.0374,0.374,6.433686786573146
0.03751,0.37510000000000004,6.46451180339365
0.03762,0.3762,6.495438482478978
0.03773,0.37729999999999997,6.526467033777174
0.03784,0.3784,6.557597665820062
0.037950000000000005,0.37950000000000006,6.588830585929616
0.038060000000000004,0.3806,6.620166000423479
0.03817,0.38170000000000004,6.651604114090434
0.03828,0.38280000000000003,6.683145130576701
0.03839,0.38389999999999996,6.71478925244911
0.0385,0.38499999999999995,6.74653668081275
0.03861,0.3861,6.778387615672112
0.038720000000000004,0.3872000000000001,6.81034225568079
0.03883,0.38830000000000003,6.842400798327955
0.03894,0.3894,6.874563439907688
0.03905,0.3905,6.906830375329874
0.03916,0.39159999999999995,6.939201798210229
0.03927,0.3927,6.971677901155753
0.03938,0.3938,7.004258875221987
0.039490000000000004,0.3949000000000001,7.03694491051673
0.0396,0.396,7.069736195557748
0.03971,0.3971,7.102632917985919
0.03982,0.39820000000000005,7.135635263780259
0.03993,0.39929999999999993,7.168743417846036
0.04004,0.4004,7.201957563947105
0.04015,0.40149999999999997,7.235277884373641
0.040260000000000004,0.40260000000000007,7.268704560299291
0.04037,0.4037,7.30223777149541
0.04048,0.4048,7.3358776967535535
0.04059,0.40590000000000004,7.369624513062912
0.0407,0.40700000000000003,7.403478396779492
0.04081,0.40809999999999996,7.437439522598723
0.04092,0.40919999999999995,7.4715080639407985
0.041030000000000004,0.41030000000000005,7.505684193245416
0.04114,0.4114,7.539968081425833
0.04125,0.41250000000000003,7.57435989822747
0.04136,0.4136,7.608859812121014
0.04147,0.4147,7.643467990294502
0.04158,0.41579999999999995,7.678184598783417
0.041690000000000005,0.41690000000000005,7.713009802134968
0.041800000000000004,0.41800000000000004,7.747943763897299
0.04191,0.4191,7.78298664614511
0.04202,0.4202,7.8181386098522205
0.04213,0.4213,7.853399814632174
0.04224,0.42240000000000005,7.8887704188327135
0.04235,0.4235,7.924250579675732
0.042460000000000005,0.42460000000000003,7.959840452910285
0.042570000000000004,0.4257000000000001,7.995540193269658
0.04268,0.4268,8.031349954132029
0.04279,0.4279,8.067269887630665
0.0429,0.429,8.103300144529006
0.04301,0.43010000000000004,8.139440874570518
0.04312,0.43119999999999997,8.175692226086214
0.043230000000000005,0.4323000000000001,8.212054346306594
0.043340000000000004,0.43340000000000006,8.248527380947694
0.04345,0.4345,8.285111474895695
0.04356,0.4356,8.321806771407447
0.04367,0.43670000000000003,8.35861341280142
0.04378,0.4378,8.395531539995034
0.04389,0.43889999999999996,8.432561292801475
0.044000000000000004,0.44000000000000006,8.46970280955399
0.04411,0.44110000000000005,8.506956227763846
0.04422,0.4422,8.544321683364746
0.04433,0.4433,8.581799311224332
0.04444,0.4444,8.619389245039462
0.04455,0.4455,8.657091617193547
0.04466,0.44659999999999994,8.694906558837857
0.044770000000000004,0.44770000000000004,8.732834200099864
0.04488,0.44880000000000003,8.770874669782673
0.04499,0.44989999999999997,8.809028095417506
0.0451,0.451,8.847294603537133
0.04521,0.4521,8.885674319234738
0.04532,0.45320000000000005,8.924167366619793
0.04543,0.4543,8.962773868561532
0.045540000000000004,0.4554,9.001493946632834
0.04565,0.4565000000000001,9.04032772144396
0.04576,0.4576,9.079275312344498
0.04587,0.4587,9.118336837316704
0.04598,0.4598,9.157512413429197
0.04609,0.46090000000000003,9.196802156608454
0.046200000000000005,0.462,9.236206181392093
0.046310000000000004,0.46310000000000007,9.275724601322437
0.04642,0.46420000000000006,9.315357528768265
0.04653,0.4653,9.355105074959255
0.04664,0.4664,9.394967349953712
0.04675,0.4675,9.434944462674638
0.04686,0.4686,9.475036520968318
0.046970000000000005,0.4697,9.515243631504323
0.047080000000000004,0.47080000000000005,9.555565899866915
0.04719,0.47190000000000004,9.596003430365965
0.0473,0.473,9.636556326531773
0.04741,0.4741,9.677224690495036
0.04752,0.4752,9.718008623265094
0.04763,0.4763,9.758908224939209
0.047740000000000005,0.47740000000000005,9.799923594551215
0.047850000000000004,0.47850000000000004,9.841054829767046
0.04796,0.4796,9.882302027404835
0.04807,0.48069999999999996,9.923665283128129
0.04818,0.4818,9.965144691455984
0.04829,0.4829,10.006740346041425
0.0484,0.48400000000000004,10.048452339274066
0.048510000000000005,0.48510000000000003,10.090280762657574
0.048620000000000003,0.4862,10.132225706325226
0.04873,0.48730000000000007,10.174287259814262
0.04884,0.4884,10.21646551121366
0.04895,0.4895,10.258760547815287
0.04906,0.4906,10.301172455878675
0.04917,0.4917,10.343701320479873
0.049280000000000004,0.4928,10.38634722578438
0.04939,0.49390000000000006,10.429110254930707
0.0495,0.49500000000000005,10.471990490094166
0.04961,0.4961,10.514988012332205
0.04972,0.4972,10.55810290185049
0.04983,0.4983,10.60133523759731
0.049940000000000005,0.4994,10.644685097955264
0.050050000000000004,0.5005000000000001,10.688152559914995
0.05016,0.5016,10.731737699865553
0.05027,0.5027,10.775440592801768
0.05038,0.5038,10.819261313169479
0.05049,0.5049,10.863199934230988
0.0506,0.506,10.907256528323204
0.050710000000000005,0.5071,10.951431166871735
0.050820000000000004,0.5082,10.995723920316358
0.05093,0.5093000000000001,11.040134858295124
0.05104,0.5104000000000001,11.084664049426959
0.05115,0.5115,11.12931156132329
0.05126,0.5126,11.174077460876948
0.05137,0.5137,11.218961813968866
0.051480000000000005,0.5148,11.26396468550844
0.051590000000000004,0.5159,11.30908613969637
0.0517,0.517,11.354326239614215
0.05181,0.5181,11.399685047749617
0.05192,0.5192,11.445162625481805
0.05203,0.5203,11.490759033314873
0.05214,0.5214,11.536474331085438
0.052250000000000005,0.5225,11.582308577716903
0.052360000000000004,0.5236000000000001,11.628261831021447
0.05247,0.5247,11.674334148384304
0.05258,0.5258,11.720525586094093
0.05269,0.5268999999999999,11.766836199638595
0.0528,0.528,11.813266043683102
0.05291,0.5291,11.859815172261124
0.053020000000000005,0.5302000000000001,11.90648363830626
0.053130000000000004,0.5313,11.953271494151997
0.05324,0.5324,12.00017879129153
0.05335,0.5335000000000001,12.04720558036977
0.05346,0.5346,12.094351911333176
0.05357,0.5357,12.141617833261098
0.05368,0.5367999999999999,12.189003394591959
0.053790000000000004,0.5379,12.236508642914279
0.0539,0.539,12.284133624995484
0.05401,0.5401,12.331878387130477
0.05412,0.5412,12.379742974504007
0.05423,0.5423,12.427727431884856
0.05434,0.5434,12.475831803082498
0.054450000000000005,0.5445000000000001,12.52405613129189
0.054560000000000004,0.5456000000000001,12.572400458978485
0.05467,0.5467,12.62086482799832
0.05478,0.5478000000000001,12.669449279293675
0.05489,0.5489,12.718153853351053
0.055,0.5499999999999999,12.766978589789781
0.05511,0.5510999999999999,12.815923527646374
0.055220000000000005,0.5522,12.864988705260869
0.055330000000000004,0.5533000000000001,12.914174160292225
0.05544,0.5544,12.963479929764327
0.05555,0.5555,13.01290605012286
0.05566,0.5566,13.062452556916947
0.05577,0.5577,13.112119485338901
0.05588,0.5588,13.161906869916065
0.055990000000000005,0.5599000000000001,13.21181474434371
0.056100000000000004,0.561,13.2618431419179
0.05621,0.5621,13.311992095281978
0.05632,0.5632,13.362261636327798
0.05643,0.5643,13.41265179657234
0.05654,0.5654,13.463162606750592
0.05665,0.5665,13.51379409731624
0.056760000000000005,0.5676000000000001,13.564546297621511
0.056870000000000004,0.5687000000000001,13.615419236972475
0.05698,0.5698,13.666412943889016
0.05709,0.5709,13.717527446369964
0.0572,0.5720000000000001,13.768762771790763
0.05731,0.5730999999999999,13.820118947088998
0.05742,0.5741999999999999,13.871595998714236
0.057530000000000005,0.5753,13.923193952354454
0.057640000000000004,0.5764,13.974912833524492
0.05775,0.5775,14.026752666853739
0.05786,0.5786,14.078713476871387
0.05797,0.5797,14.130795287156193
0.05808,0.5808,14.182998121204719
0.05819,0.5819,14.235322001786512
0.058300000000000005,0.5830000000000001,14.287766951297613
0.058410000000000004,0.5841000000000001,14.34033299164399
0.05852,0.5852,14.39302014415385
0.05863,0.5863,14.445828429918274
0.05874,0.5874,14.49875786936501
0.05885,0.5884999999999999,14.551808482771367
0.058960000000000005,0.5896,14.604980289579862
0.059070000000000004,0.5907,14.658273309061046
0.05918,0.5918000000000001,14.711687560044233
0.05929,0.5929,14.7652230608712
0.0594,0.594,14.818879829668177
0.05951,0.5951000000000001,14.872657883854599
0.05962,0.5962,14.926557240500111
0.059730000000000005,0.5973,14.980577916655461
0.059840000000000004,0.5984,15.034719928515567
0.05995,0.5995,15.088983292312253
0.06006,0.6006,15.143368023558091
0.06017,0.6017,15.197874137609446
0.06028,0.6028,15.252501649385797
0.06039,0.6039,15.307250573535029
0.060500000000000005,0.6050000000000001,15.36212092430267
0.060610000000000004,0.6061000000000001,15.41711271561753
0.06072,0.6072000000000001,15.472225961037473
0.06083,0.6083,15.52746067396435
0.06094,0.6094,15.582816867146294
0.06105,0.6105,15.638294553412882
0.06116,0.6115999999999999,15.693893745076219
0.061270000000000005,0.6127,15.749614454138134
0.061380000000000004,0.6138,15.80545669237583
0.06149,0.6149000000000001,15.861420471344998
0.0616,0.616,15.917505802220274
0.06171,0.6171,15.973712695959332
0.06182,0.6182,16.030041163104627
0.06193,0.6193,16.08649121428859
0.062040000000000005,0.6204000000000001,16.143062859574407
0.062150000000000004,0.6215,16.19975610878065
0.06226,0.6226,16.25657097178799
0.06237,0.6237,16.313507457903732
0.06248,0.6248,16.370565576380244
0.06259,0.6259000000000001,16.427745336363827
0.0627,0.627,16.485046746481533
0.06281,0.6281,16.542469815385168
0.06292,0.6292000000000001,16.600014551487753
0.06303,0.6303000000000001,16.657680962970456
0.06314,0.6314,16.71546905783002
0.06325,0.6325,16.773378843918287
0.06336,0.6336,16.83141032886005
0.06347,0.6347,16.889563520091265
0.06358,0.6357999999999999,16.947838425042853
0.06369,0.6368999999999999,17.00623505077672
0.0638,0.638,17.064753404301733
0.06391000000000001,0.6391000000000001,17.123393492498217
0.06402000000000001,0.6402000000000001,17.182155322030198
0.06413,0.6413000000000001,17.241038899602717
0.06424,0.6424,17.300044231528044
0.06435,0.6435000000000001,17.359171324246507
0.06446,0.6446000000000001,17.418420183906207
0.06457,0.6457,17.47779081665853
0.06468,0.6467999999999999,17.53728322834438
0.06479,0.6479,17.596897425154552
0.0649,0.649,17.656633412620106
0.06501,0.6501,17.716491196549182
0.06512,0.6512,17.776470782541264
0.06523,0.6523,17.83657217617211
0.06534000000000001,0.6534000000000001,17.896795382956284
0.06545000000000001,0.6545000000000001,17.957140408265843
0.06556000000000001,0.6556000000000001,18.01760725737678
0.06567,0.6567000000000001,18.078195935666876
0.06578,0.6578,18.138906448378705
0.06589,0.6589,18.199738800750165
0.066,0.66,18.260692997829498
0.06611,0.6611,18.321769044766103
0.06622,0.6622,18.382966946732036
0.06633,0.6633,18.444286708736172
0.06644,0.6644,18.505728335750913
0.06655,0.6655,18.567291832902917
0.06666,0.6666,18.628977205291164
0.06677,0.6677,18.690784457764366
0.06688000000000001,0.6688000000000002,18.75271359542169
0.06699000000000001,0.6699,18.814764623422075
0.0671,0.671,18.87693754657145
0.06721,0.6721,18.93923237015607
0.06732,0.6732,19.001649099031724
0.06743,0.6743,19.064187738496102
0.06754,0.6754,19.126848293576053
0.06765,0.6765,19.189630769512412
0.06776,0.6776,19.252535171434833
0.06787,0.6787,19.315561504658856
0.06798,0.6798,19.378709774473815
0.06809,0.6809000000000001,19.441979986189413
0.0682,0.6819999999999999,19.50537214532341
0.06831,0.6830999999999999,19.568886257375755
0.06842000000000001,0.6842000000000001,19.632522327746152
0.06853000000000001,0.6853,19.696280362220254
0.06864,0.6864,19.760160366398893
0.06875,0.6875000000000001,19.82416234606792
0.06886,0.6886,19.888286307208386
0.06897,0.6897,19.952532255687178
0.06908,0.6908000000000001,20.016900197520364
0.06919,0.6919000000000001,20.08139013895416
0.0693,0.693,20.14600208620307
0.06941,0.6940999999999999,20.21073604564172
0.06952,0.6952,20.275592023716897
0.06963,0.6963,20.34057002711643
0.06974,0.6974,20.405670062448824
0.06985000000000001,0.6985,20.47089213650885
0.06996000000000001,0.6996,20.536236256425425
0.07007000000000001,0.7007000000000001,20.601702429192912
0.07018,0.7018000000000001,20.667290662087495
0.07029,0.7029000000000001,20.733000962441015
0.0704,0.7040000000000001,20.798833337667304
0.07051,0.7051000000000001,20.86478779576069
0.07062,0.7061999999999999,20.93086434410249
0.07073,0.7072999999999999,20.99706299100379
0.07084,0.7083999999999999,21.06338374445444
0.07095,0.7095,21.129826612759395
0.07106,0.7106,21.19639160434564
0.07117,0.7117,21.263078727940023
0.07128,0.7128,21.32988799224308
0.07139000000000001,0.7139,21.39681940626376
0.07150000000000001,0.7150000000000001,21.463872979165288
0.07161000000000001,0.7161000000000001,21.531048720276782
0.07172,0.7172000000000001,21.598346639096892
0.07183,0.7183,21.66576674547766
0.07194,0.7194,21.733309049201054
0.07205,0.7205000000000001,21.800973560417646
0.07216,0.7215999999999999,21.86876028942992
0.07227,0.7226999999999999,21.93666924674036
0.07238,0.7238,22.004700443149808
0.07249,0.7249,22.072853889452922
0.0726,0.726,22.141129596982157
0.07271,0.7271,22.209527576915093
0.07282,0.7282,22.278047840885808
0.07293000000000001,0.7293000000000001,22.346690400792887
0.07304000000000001,0.7304,22.415455268523022
0.07315,0.7315,22.484342456451134
0.07326,0.7326,22.55335197696525
0.07337,0.7337,22.62248384284969
0.07348,0.7348000000000001,22.691738067070826
0.07359,0.7359000000000001,22.76111466277861
0.0737,0.737,22.830613643449
0.07381,0.7381,22.900235022691852
0.07392,0.7392,22.969978814525604
0.07403,0.7403,23.03984503311041
0.07414,0.7414,23.10983369288104
0.07425,0.7424999999999999,23.179944808456163
0.07436000000000001,0.7436000000000001,23.250178394885857
0.07447000000000001,0.7447,23.320534467308455
0.07458000000000001,0.7458,23.391013041278416
0.07469,0.7469,23.46161413240822
0.0748,0.748,23.532337756783907
0.07491,0.7491000000000001,23.603183930620887
0.07502,0.7502000000000001,23.674152670425183
0.07513,0.7513000000000001,23.745243993221663
0.07524,0.7524,23.816457915840523
0.07535,0.7535,23.88779445583589
0.07546,0.7545999999999999,23.959253630755455
0.07557,0.7556999999999999,24.030835458614103
0.07568,0.7568,24.102539957569185
0.07579,0.7579,24.174367146070512
0.07590000000000001,0.7590000000000001,24.2463170430691
0.07601000000000001,0.7601,24.318389667530745
0.07612000000000001,0.7612,24.390585038873358
0.07623,0.7623,24.462903176750455
0.07634,0.7634000000000001,24.535344101137564
0.07645,0.7645000000000001,24.607907832316837
0.07656,0.7656000000000001,24.680594390825178
0.07667,0.7667,24.753403797552554
0.07678,0.7677999999999999,24.826336073650722
0.07689,0.7688999999999999,24.89939124057251
0.077,0.7699999999999999,24.97256932012354
0.07711,0.7711,25.04587033446137
0.07722,0.7722,25.119294305858556
0.07733,0.7733,25.192841257056486
0.07744000000000001,0.7744000000000002,25.266511211212798
0.07755000000000001,0.7755,25.340304191475227
0.07766,0.7766000000000001,25.414220221576652
0.07777,0.7777000000000001,25.488259325439905
0.07788,0.7788,25.56242152745133
0.07799,0.7799,25.636706852109636
0.0781,0.781,25.711115324434516
0.07821,0.7821,25.78564696956747
0.07832,0.7831999999999999,25.860301813139532
0.07843,0.7842999999999999,25.9350798810355
0.07854,0.7854,26.009981199511017
0.07865,0.7865,26.08500579502095
0.07876,0.7876,26.160153694520908
0.07887000000000001,0.7887000000000002,26.235424925216975
0.07898000000000001,0.7898000000000002,26.310819514548108
0.07909000000000001,0.7909,26.386337490502125
0.0792,0.792,26.461978881180194
0.07931,0.7931,26.53774371510514
0.07942,0.7942,26.613632021138752
0.07953,0.7953,26.689643828548956
0.07964,0.7964000000000001,26.76577916679707
0.07975,0.7975000000000001,26.84203806566657
0.07986,0.7985999999999999,26.91842055554998
0.07997,0.7997,26.994926666846492
0.08008,0.8008,27.07155643043763
0.08019,0.8019,27.14830987753486
0.0803,0.8029999999999999,27.22518703979443
0.08041000000000001,0.8041000000000001,27.302187948937654
0.08052000000000001,0.8052000000000001,27.379312637290525
0.08063000000000001,0.8063,27.456561137451125
0.08074,0.8074,27.53393348223674
0.08085,0.8085,27.61142970493291
0.08096,0.8096,27.68904983915721
0.08107,0.8107000000000001,27.766793918861584
0.08118,0.8118000000000001,27.844661978318594
0.08129,0.8129000000000001,27.92265405206148
0.0814,0.8140000000000001,28.000770175154177
0.08151,0.8150999999999999,28.079010382895028
0.08162,0.8161999999999999,28.157374710849886
0.08173,0.8172999999999999,28.235863195129184
0.08184,0.8183999999999999,28.314475872011393
0.08195000000000001,0.8195000000000001,28.39321277822339
0.08206000000000001,0.8206000000000001,28.472073950657233
0.08217,0.8217,28.551059426916954
0.08228,0.8228,28.63016924449827
0.08239,0.8239,28.709403441626804
0.0825,0.8250000000000001,28.788762056603513
0.08261,0.8261000000000001,28.86824512821588
0.08272,0.8272,28.94785269562805
0.08283,0.8283,29.02758479816789
0.08294,0.8294,29.1074414756166
0.08305,0.8304999999999999,29.187422768273258
0.08316,0.8315999999999999,29.267528716406904
0.08327,0.8327,29.34775936093239
0.08338000000000001,0.8338000000000001,29.428114743064768
0.08349000000000001,0.8349000000000001,29.508594904180747
0.08360000000000001,0.8360000000000001,29.589199886246742
0.08371,0.8371,29.66992973136982
0.08382,0.8382,29.750784482130413
0.08393,0.8393,29.831764181408207
0.08404,0.8404,29.912868872419203
0.08415,0.8415,29.994098598817217
0.08426,0.8426,30.075453404300863
0.08437,0.8437,30.156933333270672
0.08448,0.8448000000000001,30.238538430195412
0.08459,0.8458999999999999,30.320268740166597
0.0847,0.847,30.402124308197315
0.08481,0.8481,30.484105180194195
0.08492000000000001,0.8492000000000001,30.56621140190431
0.08503000000000001,0.8503000000000002,30.64844301967975
0.08514000000000001,0.8514000000000002,30.730800080110154
0.08525,0.8525,30.81328263012151
0.08536,0.8536,30.895890717061775
0.08547,0.8547,30.978624388518902
0.08558,0.8558,31.06148369247609
0.08569,0.8569,31.144468677199402
0.0858,0.858,31.22757939141289
0.08591,0.8591000000000001,31.310815883938098
0.08602,0.8602000000000001,31.394178204166586
0.08613,0.8613,31.47766640168028
0.08624,0.8623999999999999,31.561280526417498
0.08635,0.8634999999999999,31.645020628782753
0.08646000000000001,0.8646000000000001,31.72888675923496
0.08657000000000001,0.8657000000000001,31.812878968830443
0.08668000000000001,0.8668000000000001,31.89699730870782
0.08679,0.8679,31.98124183057681
0.0869,0.869,32.06561258630803
0.08701,0.8701,32.15010962817991
0.08712,0.8712,32.23473300874591
0.08723,0.8723000000000001,32.319482780840175
0.08734,0.8734000000000001,32.404358997716145
0.08745,0.8745,32.48936171293245
0.08756,0.8756,32.57449098036191
0.08767,0.8766999999999999,32.65974685401583
0.08778,0.8777999999999999,32.74512938861995
0.08789000000000001,0.8789000000000001,32.83063863874604
0.08800000000000001,0.8800000000000001,32.91627465959181
0.08811000000000001,0.8811000000000001,33.002037506657636
0.08822,0.8822000000000001,33.087927235607786
0.08833,0.8833,33.173943902474186
0.08844,0.8844,33.26008756373866
0.08855,0.8855,33.34635827597595
0.08866,0.8866,33.43275609616773
0.08877,0.8877,33.51928108165794
0.08888,0.8888,33.60593328998474
0.08899,0.8899,33.69271277905479
0.0891,0.891,33.77961960713086
0.08921,0.8920999999999999,33.86665383258526
0.08932,0.8931999999999999,33.953815514332966
0.08943000000000001,0.8943000000000001,34.04110471145964
0.08954000000000001,0.8954000000000001,34.12852148333345
0.08965000000000001,0.8965000000000001,34.21606588968731
0.08976,0.8976000000000001,34.30373799040721
0.08987,0.8986999999999999,34.391537845938466
0.08998,0.8997999999999999,34.47946551674511
0.09009,0.9009,34.567521063711396
0.0902,0.902,34.65570454798924
0.09031,0.9031,34.74401603107348
0.09042,0.9042,34.8324555746563
0.09053,0.9053,34.92102324068097
0.09064,0.9064000000000001,35.00971909161898
0.09075,0.9074999999999999,35.098543189854595
0.09086,0.9086,35.187495598437856
0.09097000000000001,0.9097000000000001,35.27657638028534
0.09108000000000001,0.9108,35.365785599040244
0.09119000000000001,0.9119000000000002,35.4551233182938
0.0913,0.9130000000000001,35.54458960205979
0.09141,0.9140999999999999,35.63418451445178
0.09152,0.9152,35.72390812018128
0.09163,0.9163,35.813760483844234
0.09174,0.9174,35.90374167055418
0.09185,0.9185,35.99385174564981
0.09196,0.9196,36.084090774794724
0.09207,0.9207000000000001,36.174458823682905
0.09218,0.9218000000000001,36.26495595847911
0.09229,0.9228999999999999,36.355582245608424
0.09240000000000001,0.924,36.4463377516439
0.09251000000000001,0.9251,36.537222543421485
0.09262000000000001,0.9262000000000001,36.62823668814601
0.09273,0.9273000000000001,36.71938025317621
0.09284,0.9284000000000001,36.81065330624506
0.09295,0.9295000000000001,36.90205591507171
0.09306,0.9306,36.993588147939654
0.09317,0.9317,37.08525007325367
0.09328,0.9328,37.177041759520115
0.09339,0.9339,37.26896327568452
0.0935,0.935,37.361014690911624
0.09361,0.9361,37.453196074492915
0.09372,0.9372,37.54550749600375
0.09383,0.9382999999999999,37.63794902535662
0.09394000000000001,0.9394,37.73052073263472
0.09405000000000001,0.9405000000000001,37.82322268800757
0.09416000000000001,0.9416000000000001,37.916054962120754
0.09427,0.9427000000000001,38.00901762565809
0.09438,0.9438000000000001,38.102110749620955
0.09449,0.9449000000000001,38.19533440529318
0.0946,0.946,38.28868866400581
0.09471,0.9470999999999999,38.38217359745589
0.09482,0.9482,38.47578927762428
0.09493,0.9493,38.569535776389245
0.09504,0.9504,38.66341316628251
0.09515,0.9515,38.75742151969637
0.09526,0.9526,38.85156090941048
0.09537000000000001,0.9537,38.94583140843339
0.09548000000000001,0.9548000000000001,39.04023308979872
0.09559000000000001,0.9559000000000001,39.134766026943645
0.09570000000000001,0.9570000000000001,39.22943029344203
0.09581,0.9581000000000001,39.32422596308535
0.09592,0.9592,39.419153109837296
0.09603,0.9603000000000002,39.51421180781886
0.09614,0.9613999999999999,39.60940213145198
0.09625,0.9625,39.704724155388114
0.09636,0.9636,39.8001779541603
0.09647,0.9647,39.89576360299864
0.09658,0.9658,39.99148117689333
0.09669,0.9669,40.0873307512392
0.0968,0.9680000000000001,40.1833124014894
0.09691000000000001,0.9691000000000001,40.279426203412925
0.09702000000000001,0.9702000000000001,40.37567223289088
0.09713000000000001,0.9713,40.47205056591351
0.09724000000000001,0.9724,40.56856127885996
0.09735,0.9735,40.665204448067584
0.09746,0.9746000000000001,40.7619801501428
0.09757,0.9757000000000001,40.8588884619037
0.09768,0.9768,40.95592946024289
0.09779,0.9779,41.05310322230281
0.0979,0.979,41.150409825392565
0.09801,0.9801,41.24784934690705
0.09812,0.9812,41.3454218644634
0.09823,0.9823000000000001,41.44312745582911
0.09834,0.9834,41.54096619898487
0.09845000000000001,0.9845,41.638938171924806
0.09856000000000001,0.9856,41.73704345302887
0.09867000000000001,0.9867,41.83528212062763
0.09878,0.9878000000000001,41.93365425312955
0.09889,0.9889000000000001,42.032159929526166
0.099,0.9900000000000001,42.130799228401116
0.09911,0.9911000000000001,42.22957222891881
0.09922,0.9922,42.32847901012888
0.09933,0.9933,42.42751965133818
0.09944,0.9944,42.526694231978006
0.09955,0.9954999999999999,42.62600283159766
0.09966,0.9966,42.72544552981438
0.09977,0.9977,42.82502240659514
0.09988000000000001,0.9988,42.92473354180967
0.09999000000000001,0.9999,43.02457901562429
0.10010000000000001,1.,42.9892269744049
0.10021000000000001,1.,42.94065337707955
0.10032,1.,42.89240728255694
0.10043,1.,42.844484314775976
0.10054,1.,42.79688019044507
0.10065,1.,42.74959071681087
0.10076,1.,42.70261178874131
0.10087,1.,42.65593938656203
0.10098,1.,42.60956957340141
0.10109,1.,42.56349849289681
0.1012,1.,42.51772236702137
0.10131,1.,42.47223749386341
0.10142000000000001,1.,42.427040245660315
0.10153000000000001,1.,42.38212706654405
0.10164000000000001,1.,42.33749447077682
0.10175000000000001,1.,42.29313904086781
0.10186,1.,42.24905742552107
0.10197,1.,42.20524633831017
0.10208,1.,42.16170255542869
0.10219,1.,42.11842291447553
0.1023,1.,42.075404312671104
0.10241,1.,42.03264370522133
0.10252,1.,41.99013810402591
0.10263,1.,41.947884576296744
0.10274,1.,41.90588024271086
0.10285,1.,41.864122276581014
0.10296000000000001,1.,41.82260790213627
0.10307000000000001,1.,41.78133439355439
0.10318000000000001,1.,41.740299073559825
0.10329,1.,41.69949931212524
0.1034,1.,41.658932525683085
0.10351,1.,41.61859617561159
0.10362,1.,41.57848776733437
0.10373,1.,41.53860484928767
0.10384,1.,41.49894501178852
0.10395,1.,41.4595058859711
0.10406,1.,41.420285143277056
0.10417,1.,41.38128049385266
0.10428,1.,41.342489686147516
0.10439000000000001,1.,41.30391050585783
0.10450000000000001,1.,41.26554077494946
0.10461000000000001,1.,41.22737835117446
0.10472000000000001,1.,41.18942112678939
0.10483,1.,41.15166702819872
0.10494,1.,41.114114014970795
0.10505,1.,41.07676007907282
0.10516,1.,41.03960324434677
0.10527,1.,41.00264156559065
0.10538,1.,40.96587312795346
0.10549,1.,40.9292960463475
0.1056,1.,40.89290846476462
0.10571,1.,40.856708555593436
0.10582,1.,40.820694519007844
0.10593000000000001,1.,40.784864582633666
0.10604000000000001,1.,40.74921700050771
0.10615000000000001,1.,40.71375005282469
0.10626000000000001,1.,40.67846204547718
0.10637,1.,40.64335130922501
0.10648,1.,40.608416199465815
0.10659,1.,40.573655095470656
0.1067,1.,40.539066400147576
0.10681,1.,40.50464853931176
0.10692,1.,40.47039996147816
0.10703,1.,40.43631913728792
0.10714,1.,40.402404558913126
0.10725,1.,40.36865473993017
0.10736,1.,40.3350682146536
0.10747000000000001,1.,40.30164353779272
0.10758000000000001,1.,40.26837928416907
0.10769000000000001,1.,40.235274048235354
0.1078,1.,40.2023264435625
0.10791,1.,40.16953510276285
0.10802,1.,40.13689867683461
0.10813,1.,40.10441583500774
0.10824,1.,40.07208526449186
0.10835,1.,40.039905669670766
0.10846,1.,40.007875772374376
0.10857,1.,39.97599431108843
0.10868,1.,39.94426004094103
0.10879,1.,39.912671733224514
0.10890000000000001,1.,39.88122817526573
0.10901000000000001,1.,39.849928169965594
0.10912000000000001,1.,39.818770535463194
0.10923000000000001,1.,39.78775410528649
0.10934,1.,39.75687772748055
0.10945,1.,39.72614026482102
0.10956,1.,39.69554059423104
0.10967,1.,39.66507760679261
0.10978,1.,39.63475020731812
0.10989,1.,39.604557314291725
0.11,0.,0.