File: Module2/strain08.txt
SAMPLE PARAMETERS
Gauge length [mm]: 23.9341
Area [mm2]: 77.0887
EXPERIMENTAL PARAMETERS
Time [s]: 0.88
Number of steps: 1000
Displacement (0) or force control (1): 0
Schedule ID: 0
Point 1,0.,0.
Point 2,0.8,1.
Point 3,0.88,1.
RESULTS
Time [s],Displacement [mm],Force [N]
0.,0.,-3.505588702329009e-11
0.00088,0.0010999999999999998,0.01972358397068212
0.00176,0.0021999999999999997,0.03900390602784369
0.00264,0.0033,0.057861753175577825
0.00352,0.004399999999999999,0.0763168938445745
0.0044,0.0055,0.09438813798336133
0.00528,0.0066,0.11209339299403344
0.0061600000000000005,0.007699999999999999,0.12944971504966515
0.00704,0.008799999999999999,0.1464733560361201
0.00792,0.009899999999999999,0.16317980729536508
0.0088,0.011,0.17958384033270633
0.009680000000000001,0.012100000000000001,0.19569954435098502
0.01056,0.0132,0.2115403616116581
0.01144,0.0143,0.22711911983533617
0.012320000000000001,0.015399999999999999,0.24244806364800278
0.0132,0.016499999999999997,0.2575388828502549
0.01408,0.017599999999999998,0.27240273943101134
0.014960000000000001,0.0187,0.2870502941889433
0.01584,0.019799999999999998,0.30149172934787555
0.016720000000000002,0.020900000000000002,0.3157367721682039
0.0176,0.022,0.32979471644057956
0.01848,0.0231,0.34367444249721557
0.019360000000000002,0.024200000000000003,0.3573844366900242
0.02024,0.0253,0.37093280966557934
0.02112,0.0264,0.3843273138176006
0.022000000000000002,0.027500000000000004,0.3975753596884135
0.02288,0.0286,0.4106840314534298
0.02376,0.029699999999999997,0.4236601024929904
0.024640000000000002,0.030799999999999998,0.43651004877370053
0.02552,0.0319,0.44924006311467696
0.0264,0.032999999999999995,0.4618560675036327
0.027280000000000002,0.0341,0.47436372590501535
0.02816,0.035199999999999995,0.48676845541178004
0.02904,0.0363,0.49907543810512073
0.029920000000000002,0.0374,0.5112896309615639
0.0308,0.0385,0.5234157767394394
0.03168,0.039599999999999996,0.5354584130491332
0.03256,0.0407,0.5474218821585087
0.033440000000000004,0.041800000000000004,0.5593103394113716
0.03432,0.0429,0.5711277617806735
0.0352,0.044,0.582877956277291
0.03608,0.0451,0.5945645670679576
0.03696,0.0462,0.6061910832707488
0.03784,0.0473,0.6177608456882465
0.038720000000000004,0.048400000000000006,0.6292770536873314
0.0396,0.0495,0.640742771544068
0.04048,0.0506,0.6521609344013632
0.04136,0.051699999999999996,0.6635343543708107
0.04224,0.0528,0.6748657257765991
0.04312,0.05389999999999999,0.6861576309415538
0.044000000000000004,0.05500000000000001,0.6974125445728894
0.04488,0.0561,0.7086328393592665
0.04576,0.0572,0.7198207899080027
0.04664,0.058300000000000005,0.7309785777995655
0.04752,0.059399999999999994,0.7421082952921018
0.0484,0.0605,0.7532119496276383
0.049280000000000004,0.061599999999999995,0.7642914667420148
0.05016,0.0627,0.7753486949757474
0.05104,0.0638,0.7863854087229075
0.05192,0.0649,0.797403311569857
0.0528,0.06599999999999999,0.808404039340132
0.05368,0.06709999999999999,0.819389163556702
0.054560000000000004,0.0682,0.8303601941913343
0.05544,0.0693,0.8413185823193596
0.05632,0.07039999999999999,0.8522657228014912
0.0572,0.0715,0.8632029567609841
0.05808,0.0726,0.8741315743411235
0.058960000000000005,0.0737,0.8850528164282123
0.059840000000000004,0.0748,0.8959678774147057
0.06072,0.0759,0.9068779069084467
0.0616,0.077,0.917784011867948
0.06248,0.0781,0.9286872586514638
0.06336,0.07919999999999999,0.9395886745044165
0.06424,0.08030000000000001,0.9504892494360332
0.06512,0.0814,0.9613899381543658
0.066,0.0825,0.9722916613826074
0.06688000000000001,0.08360000000000001,0.9831953071275897
0.06776,0.0847,0.9941017328648845
0.06864,0.0858,1.0050117658870328
0.06952,0.08689999999999999,1.0159262057546206
0.0704,0.088,1.0268458243783665
0.07128,0.08909999999999998,1.037771368219267
0.07216,0.0902,1.0487035589702565
0.07304000000000001,0.0913,1.0596430943629451
0.07392,0.0924,1.070590649837741
0.0748,0.09350000000000001,1.0815468791808203
0.07568,0.0946,1.0925124152247365
0.07656,0.0957,1.103487871434202
0.07744000000000001,0.09680000000000001,1.1144738419496452
0.07832,0.0979,1.1254709029893857
0.0792,0.099,1.1364796137435293
0.08008,0.10010000000000001,1.147500516225696
0.08096,0.1012,1.1585341370723337
0.08184,0.10229999999999999,1.1695809875838385
0.08272,0.10339999999999999,1.1806415644461408
0.08360000000000001,0.10450000000000001,1.191716350619836
0.08448,0.1056,1.2028058155175732
0.08536,0.10669999999999999,1.2139104158991234
0.08624,0.10779999999999998,1.225030596399064
0.08712,0.1089,1.2361667898891404
0.08800000000000001,0.11000000000000001,1.247319417860593
0.08888,0.1111,1.2584888914191714
0.08976,0.1122,1.2696756108125293
0.09064,0.11329999999999998,1.2808799669536348
0.09152,0.1144,1.2921023410425774
0.09240000000000001,0.1155,1.3033431052683317
0.09328,0.11660000000000001,1.3146026230059389
0.09416000000000001,0.1177,1.3258812493084202
0.09504,0.11879999999999999,1.3371793313439426
0.09592,0.11989999999999999,1.3484972083725055
0.0968,0.121,1.3598352124743909
0.09768,0.1221,1.371193668528956
0.09856000000000001,0.12319999999999999,1.3825728946270992
0.09944,0.1243,1.3939732023399665
0.10032,0.1254,1.4053948968603045
0.1012,0.1265,1.4168382776071682
0.10208,0.1276,1.4283036379052672
0.10296000000000001,0.1287,1.4397912655716696
0.10384,0.1298,1.4513014431650793
0.10472000000000001,0.1309,1.4628344481200657
0.1056,0.13199999999999998,1.4743905525815815
0.10648,0.1331,1.4859700243837497
0.10736,0.13419999999999999,1.4975731264890328
0.10824,0.13529999999999998,1.5092001173433085
0.10912000000000001,0.1364,1.5208512515289279
0.11,0.13749999999999998,1.5325267789815868
0.11088,0.1386,1.544226946222065
0.11176,0.1397,1.5559519955442032
0.11264,0.14079999999999998,1.5677021658688457
0.11352000000000001,0.1419,1.579477692439461
0.1144,0.143,1.591278807025264
0.11528000000000001,0.1441,1.6031057382275073
0.11616,0.1452,1.614958711487039
0.11704,0.14629999999999999,1.6268379488903657
0.11792000000000001,0.1474,1.6387436700119762
0.1188,0.1485,1.6506760912839376
0.11968000000000001,0.1496,1.6626354263614662
0.12056,0.1507,1.6746218864056042
0.12144,0.1518,1.686635679742268
0.12232,0.15289999999999998,1.6986770125379116
0.1232,0.154,1.710746088145261
0.12408000000000001,0.15510000000000002,1.72284310805198
0.12496,0.1562,1.734968271084806
0.12584,0.15730000000000002,1.7471217742271243
0.12672,0.15839999999999999,1.7593038119495572
0.1276,0.15949999999999998,1.7715145770917053
0.12848,0.16060000000000002,1.7837542601891014
0.12936,0.1617,1.796023050145876
0.13024,0.1628,1.8083211337130942
0.13112000000000001,0.1639,1.820648696146776
0.132,0.165,1.8330059206623008
0.13288,0.1661,1.8453929889427139
0.13376000000000002,0.16720000000000002,1.857810081113545
0.13464,0.1683,1.8702573755151535
0.13552,0.1694,1.8827350490915784
0.1364,0.17049999999999998,1.8952432771272671
0.13728,0.1716,1.90778223368193
0.13816,0.1727,1.9203520912445058
0.13904,0.17379999999999998,1.9329530208512213
0.13992000000000002,0.1749,1.9455851924966865
0.1408,0.176,1.958248774793466
0.14168,0.17709999999999998,1.9709439347470312
0.14256,0.17819999999999997,1.9836708384668678
0.14344,0.17930000000000001,1.9964296510684505
0.14432,0.1804,2.0092205359984847
0.1452,0.18149999999999997,2.0220436560431008
0.14608000000000002,0.1826,2.0348991726810364
0.14696,0.1837,2.0477872462644284
0.14784,0.1848,2.060708036375284
0.14872000000000002,0.1859,2.0736617013327403
0.1496,0.18700000000000003,2.0866483987175606
0.15048,0.1881,2.099668284864087
0.15136,0.1892,2.1127215155205277
0.15224000000000001,0.19030000000000002,2.1258082452550475
0.15312,0.1914,2.138928628031399
0.154,0.1925,2.152082816650162
0.15488000000000002,0.19360000000000002,2.1652709634310856
0.15576,0.19469999999999998,2.178493219660191
0.15664,0.1958,2.191749735786872
0.15752,0.19689999999999996,2.2050406617918528
0.1584,0.198,2.2183661466367237
0.15928,0.1991,2.2317263386613573
0.16016,0.20020000000000002,2.2451213856265273
0.16104000000000002,0.2013,2.2585514343584805
0.16192,0.2024,2.272016631258779
0.1628,0.2035,2.2855171219413126
0.16368,0.20459999999999998,2.2990530513218532
0.16456,0.20570000000000002,2.3126245639390643
0.16544,0.20679999999999998,2.3262318036491694
0.16632,0.20789999999999997,2.3398749136613612
0.16720000000000002,0.20900000000000002,2.3535540364796277
0.16808,0.21009999999999998,2.3672693144433414
0.16896,0.2112,2.3810208890238904
0.16984000000000002,0.21230000000000002,2.394808901424271
0.17072,0.21339999999999998,2.4086334920613592
0.1716,0.2145,2.42249480112875
0.17248,0.21559999999999996,2.436392968140746
0.17336000000000001,0.21670000000000003,2.4503281323732646
0.17424,0.2178,2.464300432359941
0.17512,0.21889999999999996,2.478310006399439
0.17600000000000002,0.22000000000000003,2.492356992390558
0.17688,0.2211,2.5064415277245446
0.17776,0.2222,2.5205637493280473
0.17864,0.22329999999999997,2.534723793960988
0.17952,0.2244,2.5489217977220364
0.1804,0.2255,2.563157896584365
0.18128,0.22659999999999997,2.577432226008398
0.18216000000000002,0.2277,2.5917449212810433
0.18304,0.2288,2.6060961170958854
0.18392,0.22989999999999997,2.6204859480573903
0.18480000000000002,0.231,2.634914548350271
0.18568,0.2321,2.649382051924062
0.18656,0.23320000000000002,2.663888592301384
0.18744,0.23429999999999998,2.6784343027855395
0.18832000000000002,0.2354,2.6930193164199943
0.1892,0.23650000000000002,2.7076437661769654
0.19008,0.23759999999999998,2.7223077842539207
0.19096000000000002,0.23870000000000002,2.737011503076964
0.19184,0.23979999999999999,2.751755054666615
0.19272,0.24089999999999998,2.76653857079305
0.1936,0.242,2.7813621830358586
0.19448000000000001,0.24309999999999998,2.796226022676561
0.19536,0.2442,2.8111302210052145
0.19624,0.2453,2.8260749087937933
0.19712000000000002,0.24639999999999998,2.8410602168213637
0.198,0.2475,2.856086275647153
0.19888,0.2486,2.8711532157098727
0.19976000000000002,0.24970000000000003,2.886261167183535
0.20064,0.2508,2.9014102600052185
0.20152,0.2519,2.9166006242281752
0.2024,0.253,2.931832389492813
0.20328000000000002,0.2541,2.947105685287065
0.20416,0.2552,2.9624206412539573
0.20504,0.2563,2.9777773866369124
0.20592000000000002,0.2574,2.993176050494771
0.2068,0.2585,3.0086167619779194
0.20768,0.2596,3.0240996500477513
0.20856,0.2607,3.03962484359764
0.20944000000000002,0.2618,3.055192471302802
0.21032,0.2629,3.0708026617900095
0.2112,0.26399999999999996,3.08645554364166
0.21208000000000002,0.2651,3.1021512451496607
0.21296,0.2662,3.1178898949840548
0.21384,0.2673,3.133671621368467
0.21472,0.26839999999999997,3.1494965522987246
0.2156,0.2695,3.165364816189394
0.21648,0.27059999999999995,3.181276541114992
0.21736,0.2717,3.197231855007787
0.21824000000000002,0.2728,3.213230885826157
0.21912,0.27390000000000003,3.2292737616352314
0.22,0.27499999999999997,3.2453606102677486
0.22088000000000002,0.2761,3.2614915595782557
0.22176,0.2772,3.2776667374089903
0.22264,0.2783,3.293886271494466
0.22352,0.2794,3.3101502894762014
0.22440000000000002,0.2805,3.326458919345351
0.22528,0.28159999999999996,3.342812288464084
0.22616,0.2827,3.3592105247937716
0.22704000000000002,0.2838,3.3756537559779405
0.22792,0.28490000000000004,3.3921421095033537
0.2288,0.286,3.408675713130217
0.22968,0.2871,3.4252546945069944
0.23056000000000001,0.2882,3.4418791811629816
0.23144,0.2893,3.4585493008081465
0.23232,0.2904,3.4752651810701347
0.23320000000000002,0.2915,3.4920269495754686
0.23408,0.29259999999999997,3.5088347338907844
0.23496,0.2937,3.5256886618450847
0.23584000000000002,0.2948,3.542588860991854
0.23672,0.2959,3.5595354590590738
0.2376,0.297,3.576528583680013
0.23848,0.2981,3.5935683626577384
0.23936000000000002,0.2992,3.610654923642249
0.24024,0.3003,3.627788394511664
0.24112,0.3014,3.644968902956739
0.24200000000000002,0.3025,3.662196576841177
0.24288,0.3036,3.6794715439886896
0.24376,0.30469999999999997,3.6967939322374814
0.24464,0.30579999999999996,3.7141638695458044
0.24552000000000002,0.3069,3.731581483883986
0.2464,0.308,3.749046903129087
0.24728,0.3091,3.7665602552875197
0.24816000000000002,0.31020000000000003,3.784121668475384
0.24904,0.31129999999999997,3.801731270609406
0.24992,0.3124,3.8193891900290833
0.2508,0.3135,3.837095554764081
0.25168,0.31460000000000005,3.854850493045272
0.25256,0.3157,3.872654133085078
0.25344,0.31679999999999997,3.8905066030992743
0.25432,0.31789999999999996,3.908408031473522
0.2552,0.31899999999999995,3.9263585466931836
0.25608000000000003,0.3201,3.9443582769536025
0.25696,0.32120000000000004,3.962407350770729
0.25784,0.3223,3.9805058968131988
0.25872,0.3234,3.9986540432160242
0.2596,0.32449999999999996,4.016851919074174
0.26048,0.3256,4.035099652621524
0.26136000000000004,0.32670000000000005,4.053397372643504
0.26224000000000003,0.3278,4.071745207992836
0.26312,0.3289,4.090143287246699
0.264,0.33,4.108591739323425
0.26488,0.3311,4.127090692928264
0.26576,0.3322,4.145640277190832
0.26664,0.3333,4.164240620776421
0.26752000000000004,0.33440000000000003,4.182891852863512
0.2684,0.3355,4.201594102460688
0.26928,0.3366,4.220347498481274
0.27016,0.3377,4.239152170262488
0.27104,0.3388,4.258008246738567
0.27192,0.3399,4.276915857223611
0.2728,0.34099999999999997,4.295875130876642
0.27368000000000003,0.3421,4.314886196992041
0.27456,0.3432,4.333949184979973
0.27544,0.3443,4.3530642240104775
0.27632,0.3454,4.3722314435175855
0.2772,0.3465,4.391450972976675
0.27808,0.34759999999999996,4.4107229417537575
0.27896,0.34869999999999995,4.4300474793690405
0.27984000000000003,0.3498,4.449424715347602
0.28072,0.35090000000000005,4.468854779233473
0.2816,0.352,4.488337800479002
0.28248,0.3531,4.507873908879256
0.28336,0.35419999999999996,4.527463233902237
0.28424,0.3553,4.547105905271357
0.28512,0.35639999999999994,4.56680205255965
0.28600000000000003,0.35750000000000004,4.5865518056453105
0.28688,0.35860000000000003,4.60635529412944
0.28776,0.3597,4.626212647652799
0.28864,0.3608,4.646123996216388
0.28952,0.3619,4.66608946927209
0.2904,0.36299999999999993,4.686109196844113
0.29128,0.3641,4.706183308726188
0.29216000000000003,0.3652,4.726311934538292
0.29304,0.3663,4.746495204300928
0.29392,0.3674,4.766733247609749
0.2948,0.3685,4.787026194585603
0.29568,0.3696,4.8073741746875704
0.29656,0.3707,4.827777317956496
0.29744000000000004,0.3718,4.84823575420774
0.29832000000000003,0.3729,4.868749613291242
0.2992,0.37400000000000005,4.889319024940631
0.30008,0.3751,4.909944118946993
0.30096,0.3762,4.930625025296165
0.30184,0.37729999999999997,4.951361873553694
0.30272,0.3784,4.972154793619455
0.30360000000000004,0.3795,4.993003915174989
0.30448000000000003,0.38060000000000005,5.013909367985735
0.30536,0.38170000000000004,5.034871281735645
0.30624,0.3828,5.055889786284314
0.30712,0.38389999999999996,5.0769650111805555
0.308,0.385,5.098097085973528
0.30888,0.38609999999999994,5.119286140460341
0.30976000000000004,0.38720000000000004,5.14053230407623
0.31064,0.38830000000000003,5.161835706396046
0.31152,0.38939999999999997,5.183196476963447
0.3124,0.39049999999999996,5.204614745223625
0.31328,0.3916,5.226090640745539
0.31416,0.3927,5.2476242926572745
0.31504,0.39379999999999993,5.269215830490591
0.31592000000000003,0.39490000000000003,5.2908653833136
0.3168,0.396,5.312573080686227
0.31768,0.39709999999999995,5.334339051446495
0.31856,0.3982,5.356163424959452
0.31944,0.3993,5.378046330109196
0.32032,0.40040000000000003,5.399987896085076
0.3212,0.4014999999999999,5.421988251621854
0.32208000000000003,0.4026,5.4440475257169565
0.32296,0.40370000000000006,5.466165847134409
0.32384,0.4048,5.488343344589174
0.32472,0.4059,5.510580146625449
0.3256,0.407,5.532876382007235
0.32648,0.4080999999999999,5.555232179038993
0.32736,0.40919999999999995,5.577647666326916
0.32824000000000003,0.41030000000000005,5.600122971977639
0.32912,0.41140000000000004,5.6226582243412935
0.33,0.4125,5.645253551564445
0.33088,0.41359999999999997,5.667909081466682
0.33176,0.4147,5.690624942396442
0.33264,0.41579999999999995,5.713401261846557
0.33352000000000004,0.41690000000000005,5.736238167647235
0.33440000000000003,0.41800000000000004,5.759135787546055
0.33528,0.4191,5.782094248896451
0.33616,0.42019999999999996,5.805113679249066
0.33704,0.4213,5.828194205861351
0.33792,0.4224,5.851335955954481
0.3388,0.42349999999999993,5.874539056576107
0.33968000000000004,0.42460000000000003,5.897803634612327
0.34056000000000003,0.4257,5.921129816942645
0.34144,0.42679999999999996,5.94451773022209
0.34232,0.4279,5.967967501088078
0.3432,0.429,5.991479255907997
0.34408,0.43010000000000004,6.015053121016865
0.34496,0.4311999999999999,6.038689222467866
0.34584000000000004,0.4323,6.062387686486479
0.34672000000000003,0.43340000000000006,6.086148638703585
0.3476,0.4345,6.109972205036551
0.34848,0.4356,6.133858510989176
0.34936,0.43670000000000003,6.157807681914007
0.35024,0.4377999999999999,6.181819843192646
0.35112,0.43889999999999996,6.2058951199208625
0.35200000000000004,0.44000000000000006,6.230033636934586
0.35288,0.4411,6.254235519226568
0.35376,0.4422,6.278500891261251
0.35464,0.44329999999999997,6.3028298775981755
0.35552,0.4444,6.327222602492893
0.3564,0.44549999999999995,6.351679190025467
0.35728,0.44659999999999994,6.37619976411678
0.35816000000000003,0.44770000000000004,6.400784448678579
0.35904,0.4488,6.42543336706885
0.35992,0.44989999999999997,6.450146642838962
0.3608,0.451,6.474924399173108
0.36168,0.4521,6.499766759193956
0.36256,0.45319999999999994,6.524673845514645
0.36344,0.4543,6.549645780903096
0.36432000000000003,0.4554,6.5746826878131
0.3652,0.45649999999999996,6.599784688388
0.36608,0.4576,6.624951904782341
0.36696,0.4587,6.650184458788625
0.36784,0.45979999999999993,6.675482472096153
0.36872,0.4609,6.700846066031709
0.36960000000000004,0.462,6.726275361834475
0.37048000000000003,0.46309999999999996,6.751770480577736
0.37136,0.4642,6.777331542955293
0.37224,0.4653,6.802958669525076
0.37312,0.46640000000000004,6.828651980738989
0.374,0.4674999999999999,6.854411596585843
0.37488,0.46859999999999996,6.880237637052655
0.37576000000000004,0.46970000000000006,6.906130221812653
0.37664000000000003,0.4708,6.9320894702454146
0.37752,0.4719,6.958115501575518
0.3784,0.47300000000000003,6.984208434872519
0.37928,0.4741,7.010368388650979
0.38016,0.47519999999999996,7.036595481679733
0.38104,0.47629999999999995,7.062889831913466
0.38192000000000004,0.47740000000000005,7.089251557691334
0.38280000000000003,0.4785,7.115680776487927
0.38368,0.47959999999999997,7.142177606081174
0.38456,0.4807,7.168742163461515
0.38544,0.48179999999999995,7.195374565874203
0.38632,0.48289999999999994,7.222074930015689
0.3872,0.484,7.24884337225454
0.38808000000000004,0.4851000000000001,7.275680009100302
0.38896000000000003,0.48619999999999997,7.302584956200846
0.38984,0.4873,7.3295583296663365
0.39072,0.4884,7.356600244775638
0.3916,0.48949999999999994,7.383710816666227
0.39248,0.4906,7.410890160254524
0.39336,0.49169999999999997,7.4381383903090095
0.39424000000000003,0.49279999999999996,7.465455621163474
0.39512,0.4939,7.4928419669991495
0.396,0.495,7.52029754152401
0.39688,0.49610000000000004,7.547822458335036
0.39776,0.4972,7.575416830790997
0.39864,0.49829999999999997,7.603080771779009
0.39952000000000004,0.49940000000000007,7.630814394116783
0.40040000000000003,0.5005,7.658617810139429
0.40128,0.5016,7.6864911321306915
0.40216,0.5027,7.714434471781682
0.40304,0.5038,7.742447940780911
0.40392,0.5048999999999999,7.770531650362311
0.4048,0.506,7.798685711376188
0.40568000000000004,0.5071000000000001,7.826910234724876
0.40656000000000003,0.5082,7.855205330777569
0.40744,0.5093,7.883571109500804
0.40832,0.5104,7.912007680726605
0.4092,0.5115,7.940515154055094
0.41008,0.5126,7.969093638597602
0.41096,0.5136999999999999,7.997743243210665
0.41184000000000004,0.5148,8.026464076576557
0.41272000000000003,0.5159,8.055256246813778
0.4136,0.517,8.084119862011258
0.41448,0.5181,8.113055029847265
0.41536,0.5192,8.142061857613234
0.41624,0.5203,8.17114045235447
0.41712,0.5214,8.20029092085356
0.41800000000000004,0.5225,8.229513369491887
0.41888000000000003,0.5236,8.258807904408771
0.41976,0.5247,8.288174631206257
0.42064,0.5258,8.317613655522413
0.42152,0.5268999999999999,8.347125082487064
0.4224,0.5279999999999999,8.376709016854097
0.42328,0.5291,8.406365563174571
0.42416000000000004,0.5302,8.436094825545464
0.42504000000000003,0.5313,8.465896907998143
0.42592,0.5324,8.495771913910254
0.4268,0.5335,8.525719946477896
0.42768,0.5346,8.555741108659461
0.42856,0.5357,8.585835503025606
0.42944,0.5367999999999999,8.616003231712439
0.43032000000000004,0.5379,8.646244396726605
0.4312,0.539,8.676559099532595
0.43208,0.5401,8.706947441382189
0.43296,0.5411999999999999,8.737409523272067
0.43384,0.5423,8.767945445616618
0.43472,0.5434,8.798555308779967
0.43560000000000004,0.5445,8.829239212533698
0.43648000000000003,0.5456,8.859997256698607
0.43736,0.5467,8.890829540208411
0.43824,0.5478000000000001,8.921736162212767
0.43912,0.5488999999999999,8.952717221032353
0.44,0.5499999999999999,8.98377281508365
0.44088,0.5511,9.014903042195561
0.44176000000000004,0.5522,9.046107999891436
0.44264000000000003,0.5533,9.077387785332647
0.44352,0.5544,9.108742495484297
0.4444,0.5555,9.140172226795878
0.44528,0.5566,9.171677075628775
0.44616,0.5577,9.203257137534688
0.44704,0.5588,9.234912508247076
0.44792000000000004,0.5599,9.26664328289041
0.44880000000000003,0.561,9.298449556195639
0.44968,0.5621,9.330331422791224
0.45056,0.5631999999999999,9.362288976647974
0.45144,0.5643,9.394322311718973
0.45232,0.5654,9.426431521327748
0.4532,0.5665,9.458616698591914
0.45408000000000004,0.5676,9.490877936339345
0.45496000000000003,0.5687,9.523215326898992
0.45584,0.5698000000000001,9.55562896252017
0.45672,0.5709,9.588118934771458
0.4576,0.572,9.62068533506363
0.45848,0.5730999999999999,9.653328254464306
0.45936,0.5742,9.686047783553049
0.46024000000000004,0.5753,9.718844012921839
0.46112000000000003,0.5764,9.751717032389214
0.462,0.5775,9.784666931644397
0.46288,0.5786,9.817693800059764
0.46376,0.5797,9.850797726589757
0.46464,0.5808,9.883978799787487
0.46552,0.5819,9.917237107983683
0.46640000000000004,0.583,9.950572739091168
0.46728000000000003,0.5841000000000001,9.983985780681726
0.46816,0.5851999999999999,10.017476320125466
0.46904,0.5862999999999999,10.05104444421915
0.46992,0.5874,10.084690239510866
0.4708,0.5885,10.118413792227674
0.47168000000000004,0.5896,10.15221518831932
0.47256000000000004,0.5907,10.186094513230051
0.47344,0.5918,10.220051852158116
0.47432,0.5929,10.254087289910345
0.4752,0.594,10.288200911065125
0.47608,0.5951,10.322392799639049
0.47696,0.5962,10.35666303973791
0.47784000000000004,0.5973,10.391011714517811
0.47872000000000003,0.5984,10.425438907287278
0.4796,0.5995,10.45994470075946
0.48048,0.6006,10.49452917730543
0.48136,0.6017,10.529192419298157
0.48224,0.6028,10.56393450831005
0.48312,0.6038999999999999,10.598755525752875
0.48400000000000004,0.605,10.633655552796801
0.48488000000000003,0.6061000000000001,10.668634670280007
0.48576,0.6072,10.703692958398756
0.48664,0.6083,10.738830497380457
0.48752,0.6093999999999999,10.774047366945348
0.4884,0.6105,10.809343646511628
0.48928,0.6115999999999999,10.844719415144489
0.49016000000000004,0.6127,10.880174751619634
0.49104000000000003,0.6138,10.915709734278302
0.49192,0.6149,10.951324441183369
0.4928,0.616,10.987018950250757
0.49368,0.6171,11.022793338723108
0.49456,0.6182,11.058647683670609
0.49544,0.6193,11.094582061862532
0.49632000000000004,0.6204000000000001,11.130596549844558
0.49720000000000003,0.6215,11.166691223630115
0.49808,0.6225999999999999,11.202866158964989
0.49896,0.6237,11.239121431265655
0.49984,0.6248,11.275457115732012
0.50072,0.6259,11.311873287092892
0.5016,0.627,11.348370019779935
0.50248,0.6281,11.38494738793619
0.50336,0.6292000000000001,11.421605465492146
0.50424,0.6303,11.458344325882566
0.50512,0.6314,11.49516404225981
0.506,0.6325,11.53206468743493
0.50688,0.6335999999999999,11.569046334095418
0.50776,0.6346999999999999,11.606109054354793
0.50864,0.6357999999999999,11.643252920106546
0.50952,0.6369,11.680478002998594
0.5104,0.6379999999999999,11.717784374304145
0.5112800000000001,0.6391000000000001,11.755172104993374
0.5121600000000001,0.6402,11.792641265659764
0.51304,0.6413,11.830191926681403
0.51392,0.6424000000000001,11.867824158034079
0.5148,0.6435000000000001,11.905538029587351
0.51568,0.6446,11.943333610621115
0.51656,0.6456999999999999,11.981210970254912
0.51744,0.6468,12.019170177350821
0.51832,0.6479,12.057211300387127
0.5192,0.6489999999999999,12.095334407482083
0.52008,0.6500999999999999,12.133539566636749
0.52096,0.6512,12.171826845364569
0.52184,0.6522999999999999,12.210196311017292
0.5227200000000001,0.6534000000000001,12.248648030530491
0.5236000000000001,0.6545000000000001,12.287182070705114
0.5244800000000001,0.6556,12.325798497869679
0.52536,0.6567000000000001,12.364497378059115
0.52624,0.6578,12.403278777302427
0.52712,0.6588999999999999,12.442142760863938
0.528,0.66,12.481089394202808
0.52888,0.6611,12.520118742179667
0.52976,0.6622,12.559230869394469
0.53064,0.6632999999999999,12.598425840339555
0.53152,0.6644,12.637703718964724
0.5324,0.6655,12.677064569182654
0.53328,0.6666,12.716508454489926
0.53416,0.6676999999999998,12.756035438125759
0.5350400000000001,0.6688000000000001,12.795645583051114
0.5359200000000001,0.6699,12.835338951887277
0.5368,0.671,12.875115607188496
0.53768,0.6721,12.914975610918727
0.53856,0.6732,12.95491902512953
0.53944,0.6743,12.994945911280452
0.54032,0.6754,13.035056330754447
0.5412,0.6765,13.075250344517828
0.54208,0.6776,13.115528013398952
0.54296,0.6787,13.155889397911496
0.54384,0.6798,13.196334558396192
0.54472,0.6809,13.236863554659033
0.5456,0.6819999999999999,13.277476446588794
0.54648,0.6830999999999999,13.31817329363714
0.5473600000000001,0.6842,13.35895415499383
0.5482400000000001,0.6853,13.399819089550789
0.54912,0.6864,13.440768156120376
0.55,0.6875,13.481801412998307
0.55088,0.6886,13.522918918531209
0.55176,0.6897,13.564120730609272
0.55264,0.6908,13.605406907004674
0.55352,0.6919,13.6467775051022
0.5544,0.693,13.68823258202575
0.55528,0.6940999999999999,13.729772194824154
0.55616,0.6951999999999999,13.771396400305042
0.55704,0.6962999999999999,13.813105254832923
0.55792,0.6973999999999999,13.85489881465846
0.5588000000000001,0.6985000000000001,13.896777135807133
0.5596800000000001,0.6996,13.938740274090353
0.5605600000000001,0.7007,13.980788285011853
0.56144,0.7018000000000001,14.022921223853846
0.56232,0.7029000000000001,14.065139145719272
0.5632,0.704,14.10744210546875
0.56408,0.7051,14.149830157690294
0.56496,0.7062,14.192303356788377
0.56584,0.7072999999999999,14.23486175696751
0.56672,0.7083999999999999,14.277505412208214
0.5676,0.7095,14.32023437611706
0.56848,0.7106,14.363048702385141
0.56936,0.7116999999999999,14.405948444160384
0.57024,0.7127999999999999,14.448933654596274
0.5711200000000001,0.7139,14.492004386606293
0.5720000000000001,0.7150000000000001,14.535160692829622
0.5728800000000001,0.7161000000000001,14.57840262561037
0.57376,0.7172000000000001,14.621730237356674
0.57464,0.7182999999999999,14.6651435800131
0.57552,0.7194,14.708642705394476
0.5764,0.7205,14.752227665237184
0.57728,0.7216,14.795898510914602
0.57816,0.7226999999999999,14.839655293631402
0.57904,0.7238,14.883498064577363
0.57992,0.7249,14.927426874448466
0.5808,0.7259999999999999,14.971441773917315
0.58168,0.7271,15.015542813493997
0.58256,0.7282,15.059730043401354
0.5834400000000001,0.7293000000000001,15.104003513857371
0.5843200000000001,0.7304,15.148363274613883
0.5852,0.7315,15.19280937544058
0.58608,0.7326,15.237341865928066
0.58696,0.7337,15.281960795231262
0.58784,0.7348,15.326666212890336
0.58872,0.7359,15.37145816762885
0.5896,0.737,15.41633670837448
0.59048,0.7381,15.46130188372923
0.59136,0.7392,15.506353742161645
0.59224,0.7403,15.55149233214359
0.59312,0.7414,15.59671770172299
0.594,0.7424999999999999,15.642029898832511
0.5948800000000001,0.7436,15.68742897137057
0.5957600000000001,0.7447,15.732914966994004
0.5966400000000001,0.7458,15.778487933216637
0.59752,0.7469,15.824147917288858
0.5984,0.7480000000000001,15.869894966464503
0.59928,0.7491,15.915729127785246
0.60016,0.7502,15.961650448197837
0.60104,0.7513000000000001,16.00765897431002
0.60192,0.7524,16.05375475277982
0.6028,0.7534999999999998,16.099937830053072
0.60368,0.7545999999999999,16.146208252439383
0.60456,0.7556999999999999,16.192566066064348
0.60544,0.7568,16.239011316882273
0.60632,0.7578999999999999,16.28554405080499
0.6072000000000001,0.759,16.33216431365134
0.6080800000000001,0.7601,16.37887215088804
0.6089600000000001,0.7612000000000001,16.42566760815001
0.60984,0.7623,16.472550730707795
0.61072,0.7634000000000001,16.51952156369518
0.6116,0.7645000000000001,16.566580152218872
0.61248,0.7656,16.613726541241885
0.61336,0.7667,16.660960775741746
0.61424,0.7677999999999999,16.708282900230838
0.61512,0.7688999999999999,16.755692959421623
0.616,0.77,16.803190997671724
0.61688,0.7710999999999999,16.850777059549966
0.61776,0.7721999999999999,16.898451189036365
0.61864,0.7733,16.946213430430053
0.6195200000000001,0.7744000000000001,16.99406382770603
0.6204000000000001,0.7755,17.042002424751093
0.62128,0.7766000000000001,17.090029265464935
0.62216,0.7777,17.138144393453643
0.62304,0.7787999999999999,17.186347852349996
0.62392,0.7799,17.234639685625165
0.6248,0.7809999999999999,17.28301993678036
0.62568,0.7821,17.331488648977594
0.62656,0.7832,17.38004586552132
0.62744,0.7842999999999999,17.428691629425586
0.62832,0.7854,17.477425983770534
0.6292,0.7865,17.5262489715895
0.63008,0.7875999999999999,17.57516063557247
0.6309600000000001,0.7887000000000002,17.62416101856693
0.6318400000000001,0.7898000000000001,17.673250163175293
0.6327200000000001,0.7908999999999999,17.722428112013745
0.6336,0.792,17.77169490764013
0.63448,0.7931,17.821050592410646
0.63536,0.7941999999999999,17.870495208738365
0.63624,0.7953,17.9200287989074
0.63712,0.7964,17.969651405073584
0.638,0.7974999999999999,18.019363069341832
0.63888,0.7986,18.069163833893345
0.63976,0.7997,18.119053740635493
0.64064,0.8008000000000001,18.169032831560934
0.64152,0.8019,18.2191011484914
0.6424,0.8029999999999998,18.26925873328137
0.6432800000000001,0.8041000000000001,18.319505627600414
0.6441600000000001,0.8052,18.36984187322132
0.6450400000000001,0.8063,18.420267511762678
0.64592,0.8074000000000001,18.47078258466138
0.6468,0.8085,18.521387133581943
0.64768,0.8096,18.57208120003182
0.64856,0.8107000000000001,18.62286482538874
0.64944,0.8118,18.673738050890705
0.65032,0.8129,18.724700918068983
0.6512,0.814,18.775753468061843
0.65208,0.8150999999999999,18.82689574217816
0.65296,0.8161999999999998,18.878127781550894
0.65384,0.8172999999999999,18.92944962755238
0.65472,0.8183999999999999,18.98086132107107
0.6556000000000001,0.8195,19.03236290322658
0.6564800000000001,0.8206000000000001,19.083954415269382
0.65736,0.8217,19.135635897978702
0.65824,0.8228000000000001,19.18740739247336
0.65912,0.8239000000000001,19.239268939698142
0.66,0.825,19.29122058056192
0.66088,0.8261000000000001,19.343262356038064
0.66176,0.8271999999999999,19.39539430697545
0.66264,0.8282999999999999,19.447616474306457
0.66352,0.8294,19.499928898783306
0.6644,0.8304999999999999,19.552331621315695
0.66528,0.8315999999999999,19.604824682649973
0.66616,0.8327,19.657408123604096
0.6670400000000001,0.8338000000000001,19.71008198509911
0.6679200000000001,0.8349,19.762846307719144
0.6688000000000001,0.8360000000000001,19.815701132342312
0.66968,0.8371000000000001,19.868646499706752
0.67056,0.8382,19.921682450597135
0.67144,0.8393,19.974809025728376
0.67232,0.8403999999999999,20.02802626575366
0.6732,0.8415,20.081334211555053
0.67408,0.8426,20.13473290380801
0.67496,0.8436999999999999,20.188222383350958
0.67584,0.8448,20.2418026908254
0.67672,0.8459,20.295473866992307
0.6776,0.8469999999999999,20.349235952722164
0.67848,0.8481,20.403088988671456
0.6793600000000001,0.8492000000000001,20.45703301568272
0.6802400000000001,0.8503,20.511068074522015
0.6811200000000001,0.8514,20.565194206025307
0.682,0.8525,20.619411450943353
0.68288,0.8535999999999999,20.673719850161863
0.68376,0.8547,20.728119444641916
0.68464,0.8558,20.782610275138097
0.68552,0.8568999999999999,20.837192382525796
0.6864,0.858,20.89186580780956
0.68728,0.8591,20.94663059187089
0.68816,0.8602000000000001,21.001486775738567
0.68904,0.8613,21.056434400333465
0.68992,0.8623999999999998,21.1114735067948
0.6908,0.8634999999999999,21.16660413605644
0.6916800000000001,0.8646,21.22182632930934
0.6925600000000001,0.8657,21.27714012756239
0.6934400000000001,0.8668000000000001,21.332545572159482
0.69432,0.8679,21.38804270415516
0.6952,0.869,21.443631564747974
0.69608,0.8701000000000001,21.49931219532908
0.69696,0.8712,21.555084637221363
0.69784,0.8723,21.61094893160463
0.69872,0.8734000000000001,21.666905120027565
0.6996,0.8744999999999999,21.722953243919193
0.70048,0.8755999999999998,21.779093344715893
0.70136,0.8766999999999999,21.835325464041517
0.70224,0.8777999999999999,21.891649643493206
0.7031200000000001,0.8789,21.948065924564627
0.7040000000000001,0.8800000000000001,22.00457434904806
0.7048800000000001,0.8811,22.061174958693165
0.70576,0.8822,22.117867795269973
0.70664,0.8833000000000001,22.174652900752406
0.70752,0.8844,22.231530316991392
0.7084,0.8855000000000001,22.288500085878226
0.70928,0.8865999999999999,22.345562249547736
0.71016,0.8876999999999999,22.40271685015978
0.71104,0.8888,22.459963929728254
0.71192,0.8898999999999999,22.517303530499156
0.7128,0.8909999999999999,22.574735694867336
0.71368,0.8921,22.632260465121597
0.71456,0.8931999999999999,22.689877883771647
0.7154400000000001,0.8943,22.747587993278778
0.7163200000000001,0.8954000000000001,22.805390836159567
0.7172000000000001,0.8965000000000001,22.86328645515194
0.71808,0.8976,22.921274892916575
0.71896,0.8987,22.97935619221591
0.71984,0.8997999999999999,23.03753039612409
0.72072,0.9008999999999999,23.095797547392518
0.7216,0.902,23.154157689093257
0.72248,0.9030999999999999,23.212610864434062
0.72336,0.9042,23.27115711643281
0.72424,0.9053,23.329796488509526
0.72512,0.9063999999999999,23.38852902400363
0.726,0.9075,23.447354766315307
0.72688,0.9086,23.506273758989376
0.7277600000000001,0.9097000000000001,23.565286045741733
0.7286400000000001,0.9108,23.624391670082336
0.7295200000000001,0.9119,23.683590675974944
0.7304,0.9129999999999999,23.742883107273805
0.73128,0.9141,23.80226900802643
0.73216,0.9152,23.861748422192345
0.73304,0.9162999999999999,23.92132139399578
0.73392,0.9174,23.980987967711396
0.7348,0.9185,24.04074818770876
0.73568,0.9195999999999999,24.100602098396514
0.73656,0.9207,24.160549744495114
0.73744,0.9218,24.22059117051316
0.73832,0.9228999999999999,24.280726421291867
0.7392000000000001,0.924,24.340955541678323
0.7400800000000001,0.9251,24.4012785766348
0.7409600000000001,0.9261999999999999,24.461695571278806
0.74184,0.9273,24.5222065708241
0.74272,0.9284,24.582811620429265
0.7436,0.9295000000000001,24.643510765630637
0.74448,0.9306,24.704304051814542
0.74536,0.9317,24.765191524838365
0.74624,0.9328000000000001,24.82617323022528
0.74712,0.9339,24.887249213815554
0.748,0.9349999999999998,24.94841952166897
0.74888,0.9360999999999999,25.009684199680027
0.74976,0.9371999999999999,25.07104329430371
0.75064,0.9382999999999998,25.132496851709394
0.7515200000000001,0.9394000000000001,25.1940449182794
0.7524000000000001,0.9405,25.255687540598213
0.7532800000000001,0.9416,25.317424765333655
0.75416,0.9427000000000001,25.37925663926195
0.75504,0.9438,25.441183209224633
0.75592,0.9449,25.503204522271275
0.7568,0.9460000000000001,25.56532062564372
0.75768,0.9470999999999999,25.62753156647957
0.75856,0.9482,25.68983739230313
0.75944,0.9492999999999999,25.752238150493707
0.76032,0.9503999999999999,25.814733888776686
0.7612,0.9515,25.877324654950975
0.76208,0.9525999999999999,25.940010496800085
0.7629600000000001,0.9537,26.00279146253923
0.7638400000000001,0.9548000000000001,26.065667600308394
0.7647200000000001,0.9559000000000001,26.128638958199033
0.7656000000000001,0.957,26.191705584893704
0.76648,0.9581000000000001,26.25486752870978
0.76736,0.9591999999999999,26.318124838548023
0.76824,0.9602999999999999,26.381477563126982
0.76912,0.9614,26.444925751426148
0.77,0.9624999999999999,26.508469452579426
0.77088,0.9635999999999999,26.57210871575566
0.77176,0.9647,26.63584359035577
0.77264,0.9657999999999999,26.699674125946927
0.77352,0.9669,26.76360037207511
0.7744,0.968,26.827622378664763
0.7752800000000001,0.9691000000000001,26.891740195545292
0.7761600000000001,0.9702000000000002,26.955953872828434
0.7770400000000001,0.9713,27.02026346073871
0.7779200000000001,0.9723999999999999,27.084669009549888
0.7788,0.9735,27.149170569844294
0.77968,0.9746,27.213768192343494
0.78056,0.9756999999999999,27.27846192770879
0.78144,0.9768,27.343251826914884
0.78232,0.9779,27.40813794107708
0.7832,0.9789999999999999,27.473120321394692
0.78408,0.9801,27.538199019245496
0.78496,0.9812,27.60337408618784
0.78584,0.9823000000000001,27.66864557383078
0.78672,0.9833999999999999,27.73401353408511
0.7876000000000001,0.9845,27.799478018802333
0.7884800000000001,0.9855999999999999,27.865039080343738
0.7893600000000001,0.9867,27.930696770785595
0.79024,0.9878,27.99645114264306
0.79112,0.9889000000000001,28.062302248435365
0.792,0.99,28.128250140897347
0.79288,0.9911,28.194294873091152
0.79376,0.9922000000000001,28.260436497869765
0.79464,0.9933,28.326675068519936
0.79552,0.9944,28.39301063842215
0.7964,0.9954999999999999,28.459443261016084
0.79728,0.9965999999999999,28.525972990003122
0.79816,0.9976999999999998,28.592599879266366
0.7990400000000001,0.9988000000000001,28.659323982689767
0.7999200000000001,0.9999,28.72614535457002
0.8008000000000001,1.,28.69981985222698
0.8016800000000001,1.,28.66473279698933
0.80256,1.,28.630235465824278
0.80344,1.,28.596304960367153
0.80432,1.,28.562919546147228
0.8052,1.,28.530058578256835
0.80608,1.,28.497702433550483
0.80696,1.,28.465832448175842
0.80784,1.,28.434430860448924
0.80872,1.,28.403480757740443
0.8096,1.,28.372966027702322
0.81048,1.,28.342871313074035
0.8113600000000001,1.,28.313181969802834
0.8122400000000001,1.,28.283884027900207
0.8131200000000001,1.,28.25496415517179
0.8140000000000001,1.,28.22640962327828
0.81488,1.,28.19820827592262
0.81576,1.,28.170348499874574
0.81664,1.,28.142819196305403
0.81752,1.,28.115609755261104
0.8184,1.,28.088710031072992
0.81928,1.,28.062110319067333
0.82016,1.,28.0358013342961
0.82104,1.,28.009774190512687
0.82192,1.,27.984020381488737
0.8228,1.,27.958531762048377
0.8236800000000001,1.,27.933300531352657
0.8245600000000001,1.,27.908319216325705
0.8254400000000001,1.,27.88358065627657
0.82632,1.,27.859077988168117
0.8272,1.,27.834804632659466
0.82808,1.,27.810754281067936
0.82896,1.,27.78692088285102
0.82984,1.,27.76329863385519
0.83072,1.,27.739881964353625
0.8316,1.,27.716665529336876
0.83248,1.,27.693644197382472
0.83336,1.,27.670813041750087
0.83424,1.,27.648167330427015
0.8351200000000001,1.,27.625702517890264
0.8360000000000001,1.,27.603414236534682
0.8368800000000001,1.,27.58129828847258
0.8377600000000001,1.,27.559350638529107
0.83864,1.,27.53756740650112
0.83952,1.,27.515944860544504
0.8404,1.,27.494479410376268
0.84128,1.,27.4731676014058
0.84216,1.,27.45200610828222
0.84304,1.,27.430991729862903
0.84392,1.,27.410121383067562
0.8448,1.,27.389392098053527
0.84568,1.,27.368801013648834
0.84656,1.,27.348345371952252
0.8474400000000001,1.,27.328022514331334
0.8483200000000001,1.,27.30782987703716
0.8492000000000001,1.,27.28776498705842
0.8500800000000001,1.,27.267825458095825
0.85096,1.,27.248008987320762
0.85184,1.,27.228313351477226
0.85272,1.,27.20873640324499
0.8536,1.,27.18927606853553
0.85448,1.,27.169930343017036
0.85536,1.,27.15069728955959
0.85624,1.,27.131575034913915
0.85712,1.,27.11256176745736
0.858,1.,27.093655734406408
0.85888,1.,27.074855239372493
0.8597600000000001,1.,27.05615864013979
0.8606400000000001,1.,27.037564346273754
0.8615200000000001,1.,27.019070817116585
0.8624,1.,27.000676559848838
0.86328,1.,26.982380126990638
0.86416,1.,26.964180115483586
0.86504,1.,26.946075163874927
0.86592,1.,26.928063951458025
0.8668,1.,26.910145196025667
0.86768,1.,26.89231765280774
0.86856,1.,26.87458011269108
0.86944,1.,26.856931400882278
0.87032,1.,26.83937037557385
0.8712000000000001,1.,26.821895926476532
0.8720800000000001,1.,26.804506973992837
0.8729600000000001,1.,26.787202467682967
0.8738400000000001,1.,26.769981384949617
0.87472,1.,26.752842730585563
0.8756,1.,26.735785535097293
0.87648,1.,26.71880885430132
0.87736,1.,26.701911767761082
0.87824,1.,26.685093378254308
0.87912,1.,26.66835281085401
0.88,0.,-4.540351159582637e-12