File: Module2/strain128.txt
SAMPLE PARAMETERS
Gauge length [mm]: 23.5478
Area [mm2]: 78.1703
EXPERIMENTAL PARAMETERS
Time [s]: 14.08
Number of steps: 1000
Displacement (0) or force control (1): 0
Schedule ID: 0
Point 1,0.,0.
Point 2,12.8,1.
Point 3,14.08,1.
RESULTS
Time [s],Displacement [mm],Force [N]
0.,0.,-1.7773876224358274e-11
0.01408,0.0011,0.016704778353966616
0.02816,0.0022,0.030809141540907806
0.04224,0.0033000000000000004,0.043349791866354785
0.05632,0.0044,0.05492383535111592
0.0704,0.005500000000000001,0.0658762509988864
0.08448,0.006600000000000001,0.07640736886743024
0.09856000000000001,0.007700000000000002,0.08663449249717863
0.11264,0.0088,0.09662723267838946
0.12672,0.0099,0.10642776843427082
0.1408,0.011000000000000003,0.11606246631477588
0.15488000000000002,0.012100000000000003,0.1255485457110502
0.16896,0.013200000000000002,0.13489790316476563
0.18304,0.014300000000000002,0.1441193085762046
0.19712000000000002,0.015400000000000004,0.15321966703317805
0.2112,0.0165,0.1622047451615124
0.22528,0.0176,0.17107959093713251
0.23936000000000002,0.018700000000000005,0.17984877609436856
0.25344,0.0198,0.18851653857942266
0.26752000000000004,0.020900000000000005,0.1970868658912592
0.2816,0.022000000000000006,0.2055635456144263
0.29568,0.023100000000000002,0.21395019662837753
0.30976000000000004,0.024200000000000006,0.22225028852680798
0.32384,0.025300000000000003,0.230467155517094
0.33792,0.026400000000000003,0.23860400579373117
0.35200000000000004,0.027500000000000004,0.2466639290514404
0.36608,0.028600000000000004,0.25464990212124755
0.38016,0.0297,0.26256479435417135
0.39424000000000003,0.030800000000000008,0.2704113722922904
0.40832,0.031900000000000005,0.2781923032377988
0.4224,0.033,0.2859101599124809
0.43648000000000003,0.034100000000000005,0.29356742338812847
0.45056,0.0352,0.30116648703117144
0.46464,0.036300000000000006,0.30870965957908697
0.47872000000000003,0.03740000000000001,0.31619916823263033
0.4928,0.038500000000000006,0.3236371619493478
0.50688,0.0396,0.3310257141958651
0.52096,0.0407,0.3383668255467747
0.5350400000000001,0.04180000000000001,0.345662426872103
0.54912,0.04290000000000001,0.35291438133463815
0.5632,0.04400000000000001,0.36012448728867563
0.57728,0.0451,0.36729448057125785
0.59136,0.046200000000000005,0.3744260366004253
0.60544,0.04730000000000001,0.3815207729589359
0.6195200000000001,0.04840000000000001,0.3885802511868879
0.6336,0.0495,0.39560597905570644
0.64768,0.050600000000000006,0.4025994124844704
0.66176,0.0517,0.4095619572798842
0.67584,0.05280000000000001,0.4164949714028605
0.68992,0.0539,0.42339976614426644
0.7040000000000001,0.05500000000000001,0.4302776083724763
0.71808,0.05610000000000001,0.43712972181734533
0.73216,0.05720000000000001,0.4439572888858687
0.74624,0.05830000000000001,0.4507614518787351
0.76032,0.0594,0.4575433149120494
0.7744,0.060500000000000005,0.46430394484953363
0.7884800000000001,0.061600000000000016,0.4710443730208701
0.80256,0.0627,0.47776559631533677
0.81664,0.06380000000000001,0.48446857863922255
0.83072,0.0649,0.49115425184013617
0.8448,0.066,0.4978235172884741
0.85888,0.0671,0.5044772465985246
0.8729600000000001,0.06820000000000001,0.5111162829573511
0.88704,0.06930000000000001,0.5177414422285582
0.90112,0.0704,0.5243535135888872
0.9152,0.07150000000000001,0.5309532610595368
0.92928,0.07260000000000001,0.5375414239148909
0.9433600000000001,0.07370000000000002,0.5441187179450071
0.9574400000000001,0.07480000000000002,0.5506858361656414
0.97152,0.07590000000000001,0.5572434496956641
0.9856,0.07700000000000001,0.5637922084105426
0.99968,0.0781,0.5703327421413908
1.01376,0.0792,0.5768656609368128
1.02784,0.08030000000000001,0.5833915559481986
1.04192,0.0814,0.5899110004029164
1.056,0.08250000000000002,0.5964245499345466
1.0700800000000001,0.08360000000000002,0.6029327431104118
1.08416,0.0847,0.6094361026333269
1.09824,0.08580000000000002,0.6159351352664456
1.11232,0.0869,0.6224303330009272
1.1264,0.08800000000000002,0.6289221730054873
1.14048,0.0891,0.6354111187632231
1.15456,0.0902,0.6418976202863192
1.1686400000000001,0.09130000000000002,0.6483821143827105
1.18272,0.09240000000000001,0.6548650255236872
1.1968,0.09350000000000001,0.6613467662502946
1.21088,0.09460000000000002,0.6678277374751003
1.22496,0.09570000000000001,0.6743083288562041
1.2390400000000001,0.09680000000000002,0.6807889193772408
1.25312,0.09790000000000001,0.6872698776361081
1.2672,0.099,0.693751562314462
1.28128,0.10010000000000001,0.7002343223578641
1.29536,0.10120000000000001,0.7067184977258256
1.30944,0.10230000000000002,0.7132044191874884
1.32352,0.1034,0.7196924090354554
1.3376000000000001,0.10450000000000002,0.726182781287015
1.35168,0.10560000000000001,0.7326758419162088
1.36576,0.1067,0.739171889326579
1.37984,0.1078,0.7456712144407557
1.39392,0.10890000000000002,0.752174101095137
1.4080000000000001,0.11000000000000001,0.7586808262698645
1.42208,0.1111,0.7651916601878778
1.43616,0.11220000000000002,0.7717068668966893
1.45024,0.11330000000000001,0.7782267042390418
1.46432,0.11440000000000002,0.7847514239420884
1.4784000000000002,0.11550000000000002,0.7912812724027478
1.49248,0.11660000000000002,0.7978164900929055
1.5065600000000001,0.11770000000000001,0.8043573124569282
1.52064,0.1188,0.8109039698783667
1.53472,0.11990000000000002,0.8174566875714657
1.5488,0.12100000000000001,0.8240156862358063
1.56288,0.12210000000000001,0.8305811818631037
1.5769600000000001,0.12320000000000003,0.8371533860935141
1.59104,0.12430000000000002,0.8437325064079573
1.60512,0.1254,0.8503187459157691
1.6192,0.1265,0.8569123041681407
1.63328,0.12760000000000002,0.8635133766135062
1.6473600000000002,0.1287,0.8701221551875242
1.66144,0.1298,0.8767388282516768
1.6755200000000001,0.13090000000000002,0.8833635807442415
1.6896,0.132,0.8899965942812768
1.70368,0.13310000000000002,0.8966380474659782
1.71776,0.1342,0.9032881157595589
1.73184,0.13530000000000003,0.9099469716000244
1.7459200000000001,0.13640000000000002,0.916614784738866
1.76,0.1375,0.9232917221763639
1.77408,0.13860000000000003,0.929977948184403
1.78816,0.1397,0.9366736245580871
1.80224,0.1408,0.9433789106677096
1.8163200000000002,0.14190000000000003,0.9500939634703357
1.8304,0.14300000000000002,0.956818937701861
1.8444800000000001,0.1441,0.9635539858191584
1.85856,0.14520000000000002,0.9702992582880604
1.87264,0.1463,0.9770549034114957
1.8867200000000002,0.14740000000000003,0.9838210676367786
1.9008,0.14850000000000002,0.9905978954961034
1.9148800000000001,0.14960000000000004,0.9973855295872057
1.92896,0.1507,1.0041841108742013
1.94304,0.15180000000000002,1.010993778549039
1.95712,0.1529,1.0178146702055206
1.9712,0.15400000000000003,1.0246469218919012
1.9852800000000002,0.15510000000000002,1.0314906680016056
1.99936,0.1562,1.0383460417137063
2.01344,0.15730000000000002,1.0452131744295157
2.02752,0.1584,1.0520921964705214
2.0416,0.1595,1.0589832368370635
2.05568,0.16060000000000002,1.0658864230571885
2.06976,0.16170000000000004,1.072801881647934
2.08384,0.1628,1.0797297378974064
2.0979200000000002,0.16390000000000005,1.0866701159003898
2.112,0.16500000000000004,1.0936231386735122
2.12608,0.1661,1.1005889282554633
2.1401600000000003,0.16720000000000004,1.1075676055353871
2.15424,0.16830000000000003,1.1145592905451283
2.16832,0.1694,1.1215641023531573
2.1824,0.1705,1.128582159000707
2.19648,0.17160000000000003,1.1356135779360519
2.21056,0.17270000000000002,1.1426584754098104
2.22464,0.1738,1.1497169670870961
2.2387200000000003,0.17490000000000003,1.1567891677547093
2.2528,0.17600000000000005,1.1638751916048151
2.26688,0.1771,1.1709751518638278
2.28096,0.1782,1.1780891612527622
2.29504,0.17930000000000004,1.185217331658781
2.30912,0.1804,1.1923597745169847
2.3232,0.1815,1.1995166005715783
2.3372800000000002,0.18260000000000004,1.2066879197446179
2.35136,0.18370000000000003,1.2138738417032473
2.36544,0.18480000000000002,1.2210744754086955
2.3795200000000003,0.18590000000000004,1.2282899292970815
2.3936,0.18700000000000003,1.2355203113151063
2.40768,0.18810000000000002,1.2427657289178962
2.42176,0.18920000000000003,1.2500262890044973
2.4358400000000002,0.19030000000000002,1.2573020980939993
2.44992,0.19140000000000001,1.2645932622882297
2.464,0.1925,1.27189988731
2.4780800000000003,0.19360000000000005,1.279222078203346
2.49216,0.19470000000000004,1.2865599400716332
2.50624,0.19580000000000003,1.2939135773490031
2.52032,0.19690000000000002,1.3012830939906799
2.5344,0.198,1.3086685940079816
2.54848,0.19910000000000003,1.3160701808409365
2.56256,0.20020000000000002,1.323487957524277
2.5766400000000003,0.20130000000000003,1.3309220270273068
2.59072,0.20240000000000002,1.3383724917952782
2.6048,0.20350000000000004,1.3458394542334524
2.61888,0.20460000000000003,1.3533230163793966
2.63296,0.20570000000000002,1.360823279964461
2.64704,0.2068,1.3683403465358857
2.66112,0.2079,1.3758743174040275
2.6752000000000002,0.20900000000000005,1.3834252936965798
2.68928,0.21010000000000004,1.3909933763086206
2.70336,0.21120000000000003,1.3985786658482096
2.7174400000000003,0.21230000000000002,1.4061812629470027
2.73152,0.2134,1.4138012678214769
2.7456,0.21450000000000002,1.4214387806941415
2.75968,0.2156,1.4290939015513402
2.7737600000000002,0.21670000000000003,1.4367667302739076
2.78784,0.21780000000000005,1.4444573664734721
2.80192,0.21890000000000004,1.4521659098034982
2.8160000000000003,0.22000000000000003,1.4598924596130884
2.83008,0.22110000000000002,1.4676371152814873
2.84416,0.2222,1.475399976014773
2.85824,0.2233,1.4831811409460183
2.87232,0.22440000000000004,1.4909807090293377
2.8864,0.22550000000000003,1.4987987791568622
2.90048,0.22660000000000002,1.5066354501908137
2.9145600000000003,0.2277,1.514490820876182
2.92864,0.22880000000000003,1.522364989858486
2.94272,0.22990000000000002,1.5302580558054983
2.9568000000000003,0.23100000000000004,1.5381701171729893
2.97088,0.23210000000000006,1.5461012725298704
2.98496,0.23320000000000005,1.5540516202276546
2.99904,0.23430000000000004,1.5620212587235143
3.0131200000000002,0.23540000000000003,1.5700102863296388
3.0272,0.23650000000000002,1.5780188014014038
3.04128,0.2376,1.5860469021279633
3.0553600000000003,0.23870000000000005,1.594094686914065
3.06944,0.23980000000000004,1.6021622538522602
3.08352,0.24090000000000003,1.6102497012561299
3.0976,0.24200000000000002,1.6183571272148893
3.1116800000000002,0.24310000000000004,1.6264846300067783
3.12576,0.24420000000000003,1.634632307840981
3.13984,0.24530000000000002,1.6428002588312776
3.1539200000000003,0.24640000000000006,1.6509885812815157
3.168,0.24750000000000005,1.6591973732369594
3.18208,0.24860000000000004,1.6674267329818167
3.1961600000000003,0.24970000000000003,1.6756767587523063
3.21024,0.2508,1.6839475487085183
3.22432,0.2519,1.6922392011685945
3.2384,0.253,1.700551814391435
3.2524800000000003,0.25410000000000005,1.7088854866174392
3.26656,0.25520000000000004,1.7172403162487204
3.28064,0.25630000000000003,1.7256164016011697
3.2947200000000003,0.2574,1.7340138410424712
3.3088,0.2585,1.7424327330559275
3.32288,0.2596,1.750873176034208
3.33696,0.26070000000000004,1.7593352685325396
3.3510400000000002,0.26180000000000003,1.767819109137737
3.36512,0.2629,1.7763247963508686
3.3792,0.264,1.7848524288604217
3.3932800000000003,0.26510000000000006,1.7934021054598794
3.40736,0.26620000000000005,1.8019739246766726
3.42144,0.26730000000000004,1.810567985397374
3.43552,0.2684,1.8191843865896047
3.4496,0.2695000000000001,1.8278232270537926
3.46368,0.27060000000000006,1.8364846057547561
3.47776,0.2717,1.84516862177308
3.4918400000000003,0.27280000000000004,1.8538753740599732
3.50592,0.27390000000000003,1.8626049620216223
3.52,0.275,1.871357484739862
3.5340800000000003,0.27610000000000007,1.8801330414980246
3.54816,0.27720000000000006,1.8889317316690124
3.56224,0.27830000000000005,1.8977536546442297
3.57632,0.2794,1.906598910100108
3.5904000000000003,0.2805,1.9154675974052486
3.60448,0.2816,1.924359816310491
3.61856,0.2827,1.9332756665191968
3.6326400000000003,0.28380000000000005,1.942215247860528
3.64672,0.28490000000000004,1.951178660218946
3.6608,0.28600000000000003,1.960166003445221
3.67488,0.2871,1.9691773777768988
3.6889600000000002,0.2882,1.978212883145719
3.70304,0.2893,1.987272619806645
3.71712,0.29040000000000005,1.996356688129366
3.7312000000000003,0.29150000000000004,2.0054651883605574
3.74528,0.2926,2.0145982210704516
3.75936,0.29370000000000007,2.0237558865872134
3.7734400000000003,0.29480000000000006,2.0329382857314915
3.78752,0.29590000000000005,2.042145519092362
3.8016,0.29700000000000004,2.0513776875308944
3.81568,0.29810000000000003,2.060634891891319
3.8297600000000003,0.2992000000000001,2.0699172331001385
3.84384,0.30030000000000007,2.079224812281107
3.85792,0.3014,2.0885577305518823
3.8720000000000003,0.30250000000000005,2.0979160890963158
3.88608,0.30360000000000004,2.1072999892263793
3.90016,0.3047,2.1167095325231933
3.91424,0.3058,2.1261448202675606
3.9283200000000003,0.30690000000000006,2.135605954087705
3.9424,0.30800000000000005,2.145093035777311
3.95648,0.3091,2.1546061669555714
3.9705600000000003,0.31020000000000003,2.164145449631386
3.98464,0.3113,2.17371098564849
3.99872,0.3124,2.183302877082286
4.0128,0.31350000000000006,2.192921226083738
4.02688,0.31460000000000005,2.2025661348349415
4.04096,0.31570000000000004,2.2122377056225804
4.05504,0.3168,2.221936040948008
4.06912,0.3179,2.231661243342916
4.0832,0.319,2.241413415205709
4.0972800000000005,0.32010000000000005,2.251192659421528
4.11136,0.32120000000000004,2.2609990786510656
4.12544,0.3223000000000001,2.270832775744543
4.13952,0.3234000000000001,2.2806938537152166
4.1536,0.3245,2.290582415584598
4.16768,0.3256,2.30049856454121
4.181760000000001,0.3267000000000001,2.3104424037097413
4.1958400000000005,0.3278000000000001,2.320414036414231
4.20992,0.3289000000000001,2.330413566176412
4.224,0.33000000000000007,2.340441096471034
4.23808,0.3311,2.3504967308349225
4.25216,0.3322,2.3605805728853726
4.26624,0.3333,2.3706927265348696
4.280320000000001,0.3344000000000001,2.3808332954961657
4.2944,0.3355000000000001,2.3910023838390346
4.30848,0.33660000000000007,2.401200095508744
4.32256,0.33770000000000006,2.4114265346518
4.33664,0.3388,2.421681805488644
4.35072,0.3399,2.4319660123292923
4.3648,0.341,2.442279259551072
4.3788800000000005,0.34210000000000007,2.4526216515728625
4.39296,0.34320000000000006,2.462993293009293
4.40704,0.34430000000000005,2.473394288396327
4.42112,0.34540000000000004,2.4838247426101736
4.4352,0.34650000000000003,2.494284760348577
4.44928,0.3476,2.5047744465726383
4.46336,0.3487,2.5152939062079707
4.4774400000000005,0.34980000000000006,2.5258432442905887
4.49152,0.35090000000000005,2.5364225660567534
4.5056,0.3520000000000001,2.5470319766031477
4.51968,0.3531,2.557671581366976
4.53376,0.3542,2.5683414856549236
4.54784,0.3553,2.5790417949693034
4.56192,0.3564,2.589772614805452
4.5760000000000005,0.3575000000000001,2.6005340507667634
4.59008,0.3586000000000001,2.611326208627368
4.60416,0.3597000000000001,2.6221491941623642
4.61824,0.3608,2.633003113212219
4.63232,0.3619,2.6438880716841644
4.6464,0.363,2.654804175573864
4.66048,0.3641,2.6657515310147044
4.6745600000000005,0.3652000000000001,2.676730244125258
4.68864,0.36630000000000007,2.6877404212086056
4.70272,0.36740000000000006,2.698782168460051
4.7168,0.3685,2.7098555922594394
4.73088,0.36960000000000004,2.7209607991451494
4.74496,0.37070000000000003,2.7320978955253885
4.759040000000001,0.3718000000000001,2.7432669881570555
4.7731200000000005,0.37290000000000006,2.754468183452431
4.7872,0.37400000000000005,2.765701588330564
4.80128,0.37510000000000004,2.7769673094781635
4.81536,0.37620000000000003,2.788265453875916
4.82944,0.3773000000000001,2.7995961282767077
4.84352,0.37840000000000007,2.810959439809825
4.857600000000001,0.37950000000000006,2.822355495464142
4.8716800000000005,0.38060000000000005,2.8337844023526304
4.88576,0.38170000000000004,2.845246267713726
4.89984,0.38280000000000003,2.856741198744943
4.91392,0.3839,2.8682693027353605
4.928,0.385,2.8798306871745463
4.94208,0.3861,2.8914254593042603
4.956160000000001,0.3872000000000001,2.9030537267298566
4.97024,0.3883000000000001,2.9147155969555807
4.98432,0.3894000000000001,2.9264111775971604
4.9984,0.39050000000000007,2.9381405762991144
5.01248,0.39160000000000006,2.9499039008259174
5.02656,0.39270000000000005,2.9617012588401668
5.04064,0.39380000000000004,2.9735327581908835
5.0547200000000005,0.39490000000000003,2.985398506834955
5.0688,0.396,2.9972986126567998
5.08288,0.3971,3.0092331835987784
5.09696,0.39820000000000005,3.02120232771736
5.11104,0.39930000000000004,3.03320615309779
5.12512,0.40040000000000003,3.0452447678110572
5.1392,0.4015,3.0573182801889596
5.1532800000000005,0.40260000000000007,3.069426798246725
5.16736,0.40370000000000006,3.0815704304006197
5.18144,0.40480000000000005,3.093749284904604
5.19552,0.4059000000000001,3.105963470172049
5.2096,0.4070000000000001,3.1182130945364785
5.22368,0.4081000000000001,3.1304982664850427
5.23776,0.40920000000000006,3.142819094490936
5.2518400000000005,0.41030000000000005,3.15517568711346
5.26592,0.41140000000000004,3.1675681528739594
5.28,0.41250000000000003,3.179996600387477
5.29408,0.4136,3.1924611383446257
5.30816,0.4147,3.2049618754211107
5.32224,0.4158,3.217498920286396
5.336320000000001,0.4169000000000001,3.2300723818113672
5.3504000000000005,0.4180000000000001,3.242682368650802
5.36448,0.4191000000000001,3.25532898972712
5.37856,0.4202000000000001,3.2680123539364136
5.39264,0.42130000000000006,3.2807325700387038
5.40672,0.42240000000000005,3.2934897469992697
5.4208,0.42350000000000004,3.3062839938823845
5.434880000000001,0.42460000000000003,3.3191154195342514
5.4489600000000005,0.4257,3.3319841330626683
5.46304,0.4268,3.3448902434957795
5.47712,0.42790000000000006,3.357833859889076
5.4912,0.42900000000000005,3.370815091354999
5.50528,0.43010000000000004,3.383834046978722
5.51936,0.4312,3.396890835968026
5.533440000000001,0.4323000000000001,3.409985567436774
5.5475200000000005,0.43340000000000006,3.423118350648223
5.5616,0.4345000000000001,3.436289294738374
5.57568,0.4356000000000001,3.4494985089971504
5.58976,0.4367000000000001,3.462746102651159
5.60384,0.4378000000000001,3.476032185038782
5.61792,0.43890000000000007,3.4893568654211067
5.632000000000001,0.44000000000000006,3.502720253096925
5.64608,0.44110000000000005,3.516122457389016
5.66016,0.44220000000000004,3.5295635876865292
5.67424,0.4433,3.543043753298528
5.68832,0.4444,3.556563063713348
5.7024,0.4455,3.5701216281619006
5.71648,0.4466,3.5837195561652635
5.7305600000000005,0.4477000000000001,3.5973569571932593
5.74464,0.4488000000000001,3.6110339405639094
5.75872,0.4499000000000001,3.624750615744378
5.7728,0.45100000000000007,3.638507092254795
5.78688,0.45210000000000006,3.6523034794321467
5.80096,0.45320000000000005,3.666139886874067
5.81504,0.45430000000000004,3.680016423933114
5.8291200000000005,0.4554,3.693933200196882
5.8432,0.4565000000000001,3.7078903250370336
5.85728,0.45760000000000006,3.721887908044812
5.87136,0.45870000000000005,3.735926058697694
5.88544,0.45980000000000004,3.750004886478324
5.89952,0.46090000000000003,3.764124500974506
5.913600000000001,0.4620000000000001,3.7782850114663296
5.9276800000000005,0.46310000000000007,3.7924865276836024
5.94176,0.4642000000000001,3.8067291590940937
5.95584,0.4653000000000001,3.8210130150564066
5.96992,0.4664000000000001,3.8353382052334903
5.984,0.4675000000000001,3.849704839086307
5.99808,0.46860000000000007,3.864113026133545
6.012160000000001,0.46970000000000006,3.878562875753768
6.0262400000000005,0.47080000000000005,3.893054497553789
6.04032,0.47190000000000004,3.907588000974441
6.0544,0.47300000000000003,3.9221634955649267
6.06848,0.4741,3.936781090661363
6.08256,0.4752,3.9514408958627265
6.09664,0.4763,3.9661430206317276
6.110720000000001,0.4774000000000001,3.9808875743513408
6.1248000000000005,0.4785000000000001,3.995674666431979
6.13888,0.4796000000000001,4.010504406463173
6.15296,0.48070000000000007,4.02537690369377
6.16704,0.48180000000000006,4.040292267573903
6.18112,0.48290000000000005,4.055250607610837
6.1952,0.48400000000000004,4.070252033101846
6.209280000000001,0.4851000000000001,4.085296653416913
6.2233600000000004,0.4862000000000001,4.100384577931376
6.23744,0.48730000000000007,4.115515915861696
6.25152,0.48840000000000006,4.130690776785058
6.2656,0.48950000000000005,4.145909269846156
6.27968,0.49060000000000004,4.161171504361598
6.29376,0.4917,4.17647758963286
6.307840000000001,0.4928000000000001,4.191827634901837
6.32192,0.4939000000000001,4.207221749419497
6.336,0.4950000000000001,4.222660042408687
6.35008,0.4961000000000001,4.2381426230733785
6.36416,0.4972000000000001,4.253669600529003
6.37824,0.4983000000000001,4.2692410840813695
6.392320000000001,0.49940000000000007,4.284857182690863
6.4064000000000005,0.5005000000000001,4.300518005602434
6.42048,0.5016,4.316223661832235
6.43456,0.5027,4.331974260527468
6.44864,0.5038,4.347769910674338
6.46272,0.5049,4.36361072126086
6.4768,0.506,4.379496801266006
6.490880000000001,0.5071000000000001,4.395428259795608
6.5049600000000005,0.5082000000000001,4.411405205583956
6.51904,0.5093000000000001,4.42742774780005
6.53312,0.5104000000000001,4.443495995045713
6.5472,0.5115000000000001,4.459610056313135
6.56128,0.5126000000000001,4.475770040505635
6.57536,0.5137,4.491976056350388
6.589440000000001,0.5148,4.508228212569029
6.6035200000000005,0.5159,4.524526617991475
6.6176,0.517,4.540871381223713
6.63168,0.5181,4.557262611022284
6.64576,0.5192,4.573700415944583
6.65984,0.5203,4.590184904716281
6.67392,0.5214000000000001,4.606716185763853
6.688000000000001,0.5225000000000001,4.623294367710533
6.7020800000000005,0.5236000000000001,4.6399195591135785
6.71616,0.5247,4.656591868302733
6.73024,0.5258,4.673311403900319
6.74432,0.5269,4.69007827411846
6.7584,0.528,4.706892587416333
6.77248,0.5291,4.723754452148888
6.786560000000001,0.5302000000000001,4.7406639765856875
6.8006400000000005,0.5313000000000001,4.757621268903034
6.81472,0.5324000000000001,4.774626437380228
6.8288,0.5335000000000001,4.791679590210453
6.84288,0.5346000000000001,4.808780835462915
6.85696,0.5357000000000001,4.825930281286919
6.87104,0.5368,4.843128035745843
6.885120000000001,0.5379000000000002,4.860374206803776
6.8992,0.5390000000000001,4.877668902473397
6.91328,0.5401000000000001,4.895012230614323
6.92736,0.5412000000000001,4.912404299267948
6.94144,0.5423000000000001,4.929845216080445
6.95552,0.5434,4.94733508902401
6.969600000000001,0.5445000000000001,4.964874025817725
6.9836800000000006,0.5456000000000001,4.982462134135665
6.99776,0.5467000000000001,5.000099521648694
7.01184,0.5478000000000001,5.017786295999352
7.02592,0.5489,5.035522564849101
7.04,0.55,5.0533084356040305
7.05408,0.5511,5.071144015887241
7.068160000000001,0.5522000000000001,5.089029413067701
7.0822400000000005,0.5533000000000001,5.106964734519299
7.09632,0.5544000000000001,5.124950087608785
7.1104,0.5555000000000001,5.142985579709064
7.12448,0.5566000000000001,5.161071318005257
7.13856,0.5577000000000001,5.179207409810562
7.15264,0.5588,5.197393962194763
7.166720000000001,0.5599000000000001,5.21563108224081
7.1808000000000005,0.561,5.233918877106059
7.19488,0.5621,5.252257453745509
7.20896,0.5632,5.270646919122429
7.22304,0.5643,5.2890873801781515
7.23712,0.5654,5.307578943729319
7.2512,0.5665,5.326121716654188
7.265280000000001,0.5676000000000001,5.344715805684666
7.2793600000000005,0.5687000000000001,5.363361317535035
7.29344,0.5698000000000001,5.382058358864196
7.30752,0.5709000000000001,5.400807036314741
7.3216,0.5720000000000001,5.4196074563403585
7.33568,0.5731,5.43845972550314
7.34976,0.5742,5.457363950273466
7.363840000000001,0.5753,5.476320237017188
7.3779200000000005,0.5764,5.4953286921309
7.392,0.5775,5.514389421780005
7.40608,0.5786,5.5335025323546025
7.42016,0.5797000000000001,5.552668129885413
7.43424,0.5808000000000001,5.571886320576775
7.44832,0.5819000000000001,5.591157210534745
7.462400000000001,0.5830000000000001,5.6104809055984965
7.4764800000000005,0.5841000000000001,5.629857511936054
7.49056,0.5852,5.649287135345437
7.50464,0.5863,5.66876988170031
7.51872,0.5874000000000001,5.688305856738874
7.5328,0.5885,5.707895166284212
7.546880000000001,0.5896000000000001,5.727537915934504
7.560960000000001,0.5907000000000001,5.7472342113590695
7.57504,0.5918000000000001,5.766984158013143
7.58912,0.5929000000000001,5.786787861557718
7.6032,0.5940000000000001,5.806645427333076
7.61728,0.5951000000000001,5.826556960780807
7.63136,0.5962000000000001,5.846522567262682
7.645440000000001,0.5973000000000002,5.866542351925792
7.6595200000000006,0.5984000000000002,5.8866164200415625
7.6736,0.5995000000000001,5.906744876785437
7.68768,0.6006000000000001,5.926927827245188
7.70176,0.6017000000000001,5.947165376471819
7.71584,0.6028,5.967457629366921
7.72992,0.6039,5.987804690946672
7.744000000000001,0.6050000000000001,6.008206666029349
7.7580800000000005,0.6061000000000001,6.028663659376293
7.77216,0.6072000000000001,6.049175775715445
7.78624,0.6083000000000001,6.06974311977648
7.80032,0.6094,6.090365796158
7.8144,0.6105,6.111043909362434
7.82848,0.6116,6.131777563915218
7.842560000000001,0.6127000000000001,6.152566864275122
7.8566400000000005,0.6138000000000001,6.173411914809477
7.87072,0.6149000000000001,6.194312819793335
7.8848,0.6160000000000001,6.215269683547672
7.89888,0.6171000000000001,6.236282610055156
7.91296,0.6182,6.25735170365843
7.92704,0.6193,6.278477068267066
7.941120000000001,0.6204000000000001,6.299658807957559
7.9552000000000005,0.6215,6.3208970266908695
7.96928,0.6226,6.3421918282448395
7.98336,0.6237,6.363543316540989
7.99744,0.6248,6.38495159517035
8.01152,0.6259000000000001,6.4064167679641315
8.0256,0.6270000000000001,6.427938938431302
8.03968,0.6281000000000001,6.449518210211573
8.05376,0.6292000000000001,6.471154686745797
8.06784,0.6303000000000001,6.492848471468543
8.08192,0.6314000000000001,6.514599667796237
8.096,0.6325000000000001,6.53640837895095
8.11008,0.6336,6.558274708181943
8.12416,0.6347,6.580198758717949
8.13824,0.6358,6.6021806336175475
8.15232,0.6369,6.624220435918593
8.1664,0.638,6.646318268665082
8.180480000000001,0.6391000000000001,6.668474234664426
8.194560000000001,0.6402000000000001,6.690688436865264
8.20864,0.6413000000000001,6.712960978021527
8.22272,0.6424000000000001,6.735291960808265
8.2368,0.6435000000000001,6.757681487923604
8.25088,0.6446000000000002,6.780129662011051
8.26496,0.6457000000000002,6.802636585468953
8.27904,0.6468000000000002,6.825202360831305
8.29312,0.6479,6.847827090519399
8.3072,0.649,6.87051087673522
8.32128,0.6501,6.8932538219203945
8.33536,0.6512,6.91605602812731
8.34944,0.6523,6.938917597527349
8.363520000000001,0.6534000000000002,6.961838632215536
8.377600000000001,0.6545000000000002,6.984819234232064
8.391680000000001,0.6556000000000002,7.007859505405505
8.40576,0.6567000000000002,7.030959547689106
8.41984,0.6578000000000002,7.054119462801586
8.43392,0.6589000000000002,7.077339352572566
8.448,0.6600000000000001,7.100619318586632
8.46208,0.6611000000000001,7.123959462535435
8.47616,0.6622,7.147359885835801
8.49024,0.6633,7.170820690044853
8.50432,0.6644,7.194341976530491
8.5184,0.6655,7.217923846724487
8.53248,0.6666,7.241566401766621
8.54656,0.6677,7.265269742932311
8.560640000000001,0.6688000000000002,7.289033971352336
8.574720000000001,0.6699000000000002,7.312859188116451
8.5888,0.6710000000000002,7.336745494136992
8.60288,0.6721000000000001,7.3606929904682445
8.61696,0.6732000000000001,7.384701777944678
8.63104,0.6743000000000001,7.408771957356037
8.64512,0.6754000000000001,7.432903629433112
8.6592,0.6765000000000001,7.457096894862231
8.67328,0.6776,7.481351854239683
8.68736,0.6787,7.505668608138494
8.70144,0.6798,7.530047256883591
8.71552,0.6809000000000001,7.554487901138478
8.7296,0.682,7.578990641001502
8.74368,0.6831,7.603555576842859
8.757760000000001,0.6842000000000001,7.628182808878706
8.771840000000001,0.6853000000000001,7.652872437173211
8.78592,0.6864000000000001,7.677624561901962
8.8,0.6875000000000001,7.702439283049859
8.81408,0.6886000000000001,7.72731670044755
8.82816,0.6897000000000001,7.752256914027991
8.84224,0.6908000000000001,7.77726002357474
8.85632,0.6919000000000001,7.80232612881516
8.8704,0.6930000000000001,7.827455329491258
8.88448,0.6941,7.852647725026829
8.89856,0.6952,7.877903415186426
8.91264,0.6963,7.90322249925207
8.92672,0.6974,7.928605076723624
8.940800000000001,0.6985000000000001,7.954051246903051
8.954880000000001,0.6996000000000001,7.979561109006427
8.968960000000001,0.7007000000000001,8.005134762282147
8.98304,0.7018000000000001,8.03077230586594
8.99712,0.7029000000000002,8.056473838784557
9.0112,0.7040000000000002,8.082239460070523
9.02528,0.7051000000000002,8.108069268569038
9.03936,0.7062,8.133963363186398
9.05344,0.7073,8.15992184278376
9.06752,0.7084,8.185944806002933
9.0816,0.7095,8.212032351551533
9.09568,0.7106,8.238184577979245
9.10976,0.7117,8.264401583821675
9.12384,0.7128,8.290683467565737
9.137920000000001,0.7139000000000002,8.317030327683446
9.152000000000001,0.7150000000000002,8.343442262302702
9.166080000000001,0.7161000000000002,8.369919369782037
9.18016,0.7172000000000002,8.396461748235128
9.19424,0.7183000000000002,8.42306949598868
9.20832,0.7194000000000002,8.449742710940962
9.2224,0.7205000000000001,8.476481491053631
9.23648,0.7216,8.503285934375187
9.25056,0.7227,8.530156138606433
9.26464,0.7238,8.557092201624009
9.27872,0.7249,8.584094221234023
9.2928,0.726,8.611162294991445
9.30688,0.7271,8.638296520529641
9.32096,0.7282,8.665496995266578
9.335040000000001,0.7293000000000002,8.692763816758758
9.349120000000001,0.7304000000000002,8.720097082363477
9.3632,0.7315000000000002,8.7474968894078
9.37728,0.7326000000000001,8.774963335189616
9.39136,0.7337000000000001,8.802496516889795
9.40544,0.7348000000000001,8.830096531481498
9.41952,0.7359000000000001,8.857763476266722
9.4336,0.737,8.885497448116345
9.44768,0.7381000000000001,8.913298543845364
9.46176,0.7392000000000001,8.94116686053223
9.47584,0.7403000000000001,8.969102494781081
9.48992,0.7414000000000001,8.9971055433999
9.504,0.7425,9.02517610306446
9.518080000000001,0.7436000000000001,9.053314270294742
9.532160000000001,0.7447,9.081520141758572
9.546240000000001,0.7458000000000001,9.109793813749903
9.56032,0.7469000000000001,9.138135382749336
9.5744,0.7480000000000001,9.166544945114413
9.58848,0.7491000000000001,9.195022597016308
9.60256,0.7502000000000001,9.223568434755233
9.61664,0.7513000000000001,9.252182554430872
9.63072,0.7524000000000001,9.28086505202536
9.6448,0.7535000000000001,9.309616023712648
9.65888,0.7546000000000002,9.338435565243076
9.67296,0.7557,9.367323772614002
9.68704,0.7568000000000001,9.396280741551472
9.70112,0.7579,9.425306567791608
9.715200000000001,0.7590000000000001,9.454401347035976
9.729280000000001,0.7601000000000001,9.483565174948296
9.743360000000001,0.7612000000000001,9.512798147049356
9.75744,0.7623000000000002,9.542100358709574
9.77152,0.7634000000000001,9.57147190545384
9.7856,0.7645000000000002,9.600912882584083
9.79968,0.7656000000000001,9.630423385418709
9.81376,0.7667000000000002,9.660003509146224
9.82784,0.7678,9.689653348902738
9.84192,0.7689000000000001,9.719372999762205
9.856,0.77,9.749162556811566
9.87008,0.7711000000000001,9.779022115000448
9.88416,0.7722,9.808951769092367
9.89824,0.7733000000000001,9.838951614109675
9.912320000000001,0.7744000000000002,9.86902174470958
9.926400000000001,0.7755000000000001,9.899162255525543
9.94048,0.7766000000000002,9.92937324136675
9.95456,0.7777000000000001,9.959654796658851
9.96864,0.7788000000000002,9.990007015983023
9.98272,0.7799,10.02042999367308
9.9968,0.7810000000000001,10.050923824229349
10.01088,0.7821,10.081488601958002
10.02496,0.7832000000000001,10.11212442100069
10.03904,0.7843,10.142831375655701
10.05312,0.7854000000000001,10.173609559991828
10.0672,0.7865,10.204459068055604
10.08128,0.7876000000000001,10.235379993822963
10.095360000000001,0.7887000000000002,10.266372431328943
10.109440000000001,0.7898000000000001,10.297436474290196
10.123520000000001,0.7909000000000002,10.328572216680472
10.1376,0.792,10.359779752066165
10.15168,0.7931000000000001,10.391059174209094
10.16576,0.7942,10.422410576736477
10.17984,0.7953000000000001,10.453834053141856
10.19392,0.7964000000000001,10.485329696899347
10.208,0.7975000000000001,10.516897601466384
10.22208,0.7986000000000001,10.548537860290525
10.23616,0.7997000000000001,10.580250566509275
10.25024,0.8008000000000001,10.612035813411003
10.26432,0.8019000000000001,10.643893694191748
10.2784,0.803,10.675824301942347
10.292480000000001,0.8041000000000001,10.707827729706096
10.306560000000001,0.8052000000000001,10.739904070421296
10.320640000000001,0.8063000000000001,10.772053417099698
10.33472,0.8074000000000001,10.804275862489026
10.3488,0.8085000000000001,10.836571499462885
10.36288,0.8096000000000001,10.868940420697024
10.37696,0.8107000000000001,10.901382718876974
10.39104,0.8118000000000002,10.933898486665921
10.40512,0.8129000000000001,10.966487816486673
10.4192,0.8140000000000002,10.999150800924156
10.43328,0.8151,11.031887532405648
10.44736,0.8162000000000001,11.064698103239747
10.46144,0.8173,11.097582605670745
10.47552,0.8184000000000001,11.1305411319874
10.489600000000001,0.8195000000000002,11.163573774359895
10.503680000000001,0.8206000000000001,11.196680624924303
10.51776,0.8217000000000002,11.229861775664055
10.53184,0.8228000000000001,11.26311731861379
10.54592,0.8239000000000002,11.296447345677691
10.56,0.8250000000000001,11.329851948753026
10.57408,0.8261000000000002,11.363331219627938
10.58816,0.8272,11.396885249969996
10.60224,0.8283000000000001,11.430514131504356
10.61632,0.8294,11.464217955923822
10.6304,0.8305000000000001,11.497996814597302
10.64448,0.8316,11.531850799250819
10.65856,0.8327000000000001,11.565780001183168
10.672640000000001,0.8338000000000002,11.59978451175366
10.686720000000001,0.8349000000000001,11.633864422367465
10.700800000000001,0.8360000000000002,11.668019824205695
10.71488,0.8371000000000001,11.702250808398555
10.72896,0.8382000000000002,11.736557466262733
10.74304,0.8393,11.770939888721276
10.75712,0.8404000000000001,11.805398166778506
10.7712,0.8415,11.839932391475504
10.78528,0.8426000000000001,11.874542653602894
10.79936,0.8437,11.909229044035522
10.81344,0.8448000000000001,11.943991653609809
10.82752,0.8459,11.97883057292089
10.8416,0.8470000000000001,12.013745892637811
10.85568,0.8481000000000001,12.048737703414622
10.869760000000001,0.8492000000000001,12.083806095710313
10.883840000000001,0.8503000000000002,12.11895116004878
10.897920000000001,0.8514,12.154172986803623
10.912,0.8525000000000001,12.189471666302406
10.92608,0.8536,12.224847288874239
10.94016,0.8547000000000001,12.260299944763858
10.95424,0.8558000000000001,12.295829724068911
10.96832,0.8569000000000001,12.331436717016993
10.9824,0.8580000000000001,12.367121013491952
10.99648,0.8591000000000001,12.40288270362614
11.01056,0.8602000000000001,12.438721877286222
11.02464,0.8613000000000001,12.474638624425603
11.03872,0.8624,12.510633034752454
11.0528,0.8635000000000002,12.546705198095045
11.066880000000001,0.8646000000000001,12.582855204082904
11.080960000000001,0.8657000000000001,12.61908314256165
11.095040000000001,0.8668000000000001,12.655389102829703
11.10912,0.8679000000000001,12.69177317457142
11.1232,0.8690000000000002,12.7282354471603
11.13728,0.8701000000000001,12.764776010022878
11.15136,0.8712000000000002,12.801394952557631
11.16544,0.8723000000000001,12.838092364062412
11.17952,0.8734000000000002,12.874868333660576
11.1936,0.8745,12.911722950632633
11.20768,0.8756000000000002,12.948656304034849
11.22176,0.8767,12.98566848296535
11.23584,0.8778000000000001,13.022759576345187
11.249920000000001,0.8789000000000002,13.059929673187796
11.264000000000001,0.8800000000000001,13.09717886233151
11.278080000000001,0.8811000000000002,13.134507232633954
11.29216,0.8822000000000001,13.171914872778418
11.30624,0.8833000000000002,13.209401871617127
11.32032,0.8844000000000001,13.246968317692394
11.3344,0.8855000000000002,13.284614299613422
11.34848,0.8866,13.322339905866095
11.36256,0.8877000000000002,13.360145225016742
11.37664,0.8888,13.398030345456652
11.39072,0.8899000000000001,13.435995355566986
11.4048,0.891,13.474040343565221
11.41888,0.8921000000000001,13.512165397833165
11.43296,0.8932,13.550370606472185
11.447040000000001,0.8943000000000001,13.588656057707373
11.461120000000001,0.8954000000000002,13.627021839474098
11.475200000000001,0.8965000000000001,13.6654680399025
11.48928,0.8976000000000002,13.703994746916049
11.50336,0.8987,13.742602048373117
11.51744,0.8998000000000002,13.781290032297566
11.53152,0.9009,13.820058786270005
11.5456,0.9020000000000001,13.858908398186074
11.55968,0.9031,13.897838955635795
11.57376,0.9042000000000001,13.936850546336238
11.58784,0.9053000000000001,13.975943257708336
11.60192,0.9064000000000001,14.01511717741995
11.616,0.9075000000000001,14.05437239282234
11.63008,0.9086000000000001,14.093708991440897
11.644160000000001,0.9097000000000002,14.13312706049567
11.658240000000001,0.9108,14.172626687336948
11.672320000000001,0.9119000000000002,14.2122079591214
11.6864,0.9130000000000001,14.251870963146118
11.70048,0.9141000000000001,14.291615786502224
11.71456,0.9152000000000001,14.331442516134373
11.72864,0.9163000000000001,14.371351239196258
11.74272,0.9174000000000001,14.41134204258109
11.7568,0.9185000000000001,14.451415013224262
11.77088,0.9196000000000001,14.491570237915301
11.78496,0.9207000000000002,14.531807803441135
11.79904,0.9218000000000001,14.572127796621832
11.81312,0.9229000000000002,14.612530304128656
11.827200000000001,0.9240000000000002,14.653015412477039
11.841280000000001,0.9251000000000001,14.693583208274374
11.855360000000001,0.9262000000000001,14.73423377808519
11.86944,0.9273000000000001,14.77496720839635
11.88352,0.9284000000000002,14.815783585458044
11.8976,0.9295000000000001,14.856682995803084
11.91168,0.9306000000000002,14.897665525571652
11.92576,0.9317000000000001,14.938731261134336
11.93984,0.9328000000000002,14.97988028850679
11.95392,0.9339000000000001,15.021112694039859
11.968,0.9350000000000002,15.062428563637294
11.98208,0.9361,15.103827983342514
11.99616,0.9372000000000001,15.145311039228314
12.01024,0.9383,15.186877817102056
12.024320000000001,0.9394000000000001,15.228528402872078
12.038400000000001,0.9405000000000002,15.27026288233374
12.052480000000001,0.9416000000000001,15.312081341198972
12.06656,0.9427000000000002,15.353983865227109
12.08064,0.9438000000000001,15.395970540022473
12.09472,0.9449000000000002,15.438041451264628
12.1088,0.9460000000000001,15.480196684313531
12.12288,0.9471000000000002,15.52243632478122
12.13696,0.9482,15.564760458039883
12.15104,0.9493000000000001,15.607169169487525
12.16512,0.9504,15.649662544475255
12.1792,0.9515000000000001,15.692240668103892
12.19328,0.9526,15.734903625851306
12.207360000000001,0.9537000000000001,15.777651502680111
12.221440000000001,0.9548000000000002,15.820484383776456
12.235520000000001,0.9559000000000001,15.863402354178678
12.249600000000001,0.9570000000000002,15.906405498913712
12.26368,0.9581000000000001,15.949493902843422
12.27776,0.9592000000000002,15.992667650912727
12.29184,0.9603,16.035926828013697
12.30592,0.9614000000000001,16.07927151884216
12.32,0.9625000000000001,16.12270180823912
12.33408,0.9636000000000001,16.166217780798654
12.34816,0.9647000000000001,16.20981952116904
12.36224,0.9658000000000001,16.25350711390461
12.37632,0.9669000000000001,16.29728064359838
12.3904,0.9680000000000001,16.341140194687142
12.404480000000001,0.9691000000000002,16.385085851569773
12.418560000000001,0.9702000000000002,16.42911769860691
12.432640000000001,0.9713000000000002,16.473235820175077
12.446720000000001,0.9724000000000002,16.517440300507314
12.4608,0.9735000000000001,16.56173122368757
12.47488,0.9746000000000001,16.606108674058802
12.48896,0.9757000000000001,16.650572735691558
12.50304,0.9768000000000001,16.695123492513428
12.51712,0.9779000000000002,16.73976102866898
12.5312,0.9790000000000001,16.784485427993225
12.54528,0.9801000000000002,16.829296774446004
12.55936,0.9812000000000001,16.874195151966468
12.57344,0.9823000000000002,16.919180644084253
12.58752,0.9834,16.96425333474891
12.601600000000001,0.9845000000000002,17.009413307658672
12.615680000000001,0.9856000000000003,17.054660646338665
12.629760000000001,0.9867000000000001,17.09999543440965
12.64384,0.9878000000000002,17.145417755497814
12.65792,0.9889000000000001,17.190927692980296
12.672,0.9900000000000002,17.236525330238152
12.68608,0.9911000000000001,17.282210750794313
12.70016,0.9922000000000002,17.327984037891813
12.71424,0.9933000000000001,17.373845274813114
12.72832,0.9944000000000002,17.419794544854838
12.7424,0.9955,17.46583193106131
12.75648,0.9966000000000002,17.511957516689602
12.77056,0.9977,17.558171384696124
12.784640000000001,0.9988000000000001,17.60447361820613
12.798720000000001,0.9999000000000002,17.650864300107663
12.812800000000001,1.,17.640758264837512
12.826880000000001,1.,17.627405617031762
12.84096,1.,17.615756972917115
12.85504,1.,17.605174188399133
12.86912,1.,17.59528837274981
12.8832,1.,17.58588511739972
12.89728,1.,17.57683869700107
12.91136,1.,17.568074341596528
12.92544,1.,17.55954660259501
12.93952,1.,17.551226944088654
12.9536,1.,17.543096625125962
12.96768,1.,17.53514261307642
12.981760000000001,1.,17.52735523769434
12.995840000000001,1.,17.519726841455295
13.009920000000001,1.,17.51225100191338
13.024000000000001,1.,17.504922082562057
13.03808,1.,17.49773497127212
13.05216,1.,17.49068492800884
13.06624,1.,17.48376749363448
13.08032,1.,17.476978434980765
13.0944,1.,17.470313710897276
13.10848,1.,17.463769449440893
13.12256,1.,17.457341933339904
13.13664,1.,17.451027588304804
13.15072,1.,17.4448229747214
13.1648,1.,17.438724780415335
13.178880000000001,1.,17.432729814858217
13.192960000000001,1.,17.42683500342134
13.207040000000001,1.,17.421037382453232
13.22112,1.,17.41533409483459
13.2352,1.,17.409722385649555
13.24928,1.,17.404199597915305
13.26336,1.,17.398763168889985
13.27744,1.,17.3934106262291
13.29152,1.,17.388139584558207
13.3056,1.,17.382947742078496
13.31968,1.,17.377832877432436
13.33376,1.,17.372792846298008
13.34784,1.,17.367825578949024
13.361920000000001,1.,17.362929077131067
13.376000000000001,1.,17.358101411084746
13.390080000000001,1.,17.353340717700053
13.404160000000001,1.,17.348645197167613
13.41824,1.,17.34401311126637
13.43232,1.,17.339442780642923
13.4464,1.,17.334932582970588
13.46048,1.,17.330480950364105
13.47456,1.,17.326086367918286
13.48864,1.,17.321747371209938
13.50272,1.,17.31746254494592
13.5168,1.,17.313230520670466
13.53088,1.,17.309049975488975
13.54496,1.,17.304919630023885
13.559040000000001,1.,17.300838247235767
13.573120000000001,1.,17.29680463030463
13.587200000000001,1.,17.292817621861076
13.601280000000001,1.,17.288876101904293
13.61536,1.,17.28497898700414
13.62944,1.,17.281125228487074
13.64352,1.,17.2773138116848
13.6576,1.,17.273543754134526
13.67168,1.,17.26981410508578
13.68576,1.,17.266123943651028
13.69984,1.,17.262472378402162
13.71392,1.,17.25885854582051
13.728,1.,17.25528160968201
13.74208,1.,17.25174075969053
13.756160000000001,1.,17.248235210949346
13.770240000000001,1.,17.244764202755086
13.784320000000001,1.,17.241326998028462
13.7984,1.,17.237922882127375
13.81248,1.,17.234551162520575
13.82656,1.,17.231211167350562
13.84064,1.,17.227902245583966
13.85472,1.,17.22462376538131
13.8688,1.,17.221375114146895
13.88288,1.,17.218155697363198
13.89696,1.,17.21496493830894
13.91104,1.,17.21180227712014
13.92512,1.,17.20866717064129
13.939200000000001,1.,17.20555909125405
13.953280000000001,1.,17.202477527028933
13.967360000000001,1.,17.199421980465456
13.981440000000001,1.,17.196391968724996
13.99552,1.,17.193387022416164
14.0096,1.,17.190406685876283
14.02368,1.,17.187450515905486
14.03776,1.,17.184518082106404
14.05184,1.,17.181608965772785
14.06592,1.,17.178722760215447
14.08,0.,-2.5779874112527313e-12