File: Module2/strain100sec.txt
SAMPLE PARAMETERS
Gauge length [mm]: 24.1354
Area [mm2]: 74.44
EXPERIMENTAL PARAMETERS
Time [s]: 110
Number of steps: 1000
Displacement (0) or force control (1): 0
Schedule ID: 0
Point 1,0.,0.
Point 2,100.,1.
Point 3,110.,1.
RESULTS
Time [s],Displacement [mm],Force [N]
0,0.,0.
0.11,0.0010999999999999998,0.008632239544644751
0.22,0.0021999999999999997,0.015611235378814953
0.33,0.0033,0.02191477566141783
0.44,0.004399999999999999,0.02778907356470452
0.55,0.0055,0.03333370415701578
0.66,0.0066,0.03861102785137658
0.77,0.0077,0.043668197502958625
0.88,0.008799999999999999,0.048542797364771136
0.99,0.009899999999999999,0.053265178520644885
1.1,0.011,0.057859939583571836
1.21,0.0121,0.06234704830935381
1.32,0.0132,0.06674273363355787
1.43,0.014299999999999998,0.07106020390237772
1.54,0.0154,0.07531022687257173
1.65,0.016499999999999997,0.07950159758955232
1.76,0.017599999999999998,0.08364151650902008
1.87,0.0187,0.08773589486347423
1.98,0.019799999999999998,0.09178960132268184
2.09,0.020899999999999995,0.09580666104980454
2.2,0.022,0.09979041710494366
2.31,0.0231,0.10374365973188018
2.42,0.0242,0.10766873195960773
2.53,0.025299999999999996,0.11156761394753055
2.64,0.0264,0.11544199195956842
2.75,0.027499999999999997,0.11929331339369256
2.86,0.028599999999999997,0.12312283173250865
2.97,0.029699999999999997,0.1269316426356875
3.08,0.0308,0.13072071296119514
3.19,0.0319,0.1344909050263109
3.3,0.032999999999999995,0.1382429947591242
3.41,0.0341,0.1419776881710177
3.52,0.035199999999999995,0.14569563314694042
3.63,0.0363,0.14939742983673113
3.74,0.0374,0.15308363903714672
3.85,0.0385,0.1567547884479043
3.96,0.039599999999999996,0.16041137823431015
4.07,0.0407,0.16405388572404628
4.18,0.04179999999999999,0.16768276835781237
4.29,0.0429,0.17129846704200358
4.4,0.044,0.17490140838821092
4.51,0.045099999999999994,0.17849200634399323
4.62,0.0462,0.1820706644577489
4.73,0.047299999999999995,0.1856377762532169
4.84,0.0484,0.18919372704545367
4.95,0.0495,0.19273889431680893
5.06,0.05059999999999999,0.19627364879386708
5.17,0.05169999999999999,0.1997983546126159
5.28,0.0528,0.20331337034808086
5.39,0.05389999999999999,0.20681904890375705
5.5,0.05499999999999999,0.21031573819374952
5.61,0.0561,0.21380378134218983
5.72,0.057199999999999994,0.21728351687244243
5.83,0.0583,0.22075527898775968
5.94,0.059399999999999994,0.22421939761520168
6.05,0.0605,0.22767619895209823
6.16,0.0616,0.23112600502391073
6.27,0.06269999999999999,0.23456913431568627
6.38,0.0638,0.23800590159109777
6.49,0.0649,0.241436618120519
6.6,0.06599999999999999,0.24486159174504146
6.71,0.06709999999999999,0.24828112679983727
6.82,0.0682,0.25169552448853233
6.93,0.0693,0.2551050829429085
7.04,0.07039999999999999,0.2585100965597637
7.15,0.0715,0.2619108574401523
7.26,0.0726,0.2653076540120923
7.37,0.0737,0.268700771966015
7.48,0.0748,0.2720904941157134
7.59,0.0759,0.2754771004437243
7.7,0.077,0.2788608678203583
7.81,0.07809999999999999,0.28224207051727784
7.92,0.07919999999999999,0.28562098012606985
8.03,0.08029999999999998,0.28899786552020057
8.14,0.0814,0.29237299281864354
8.25,0.08249999999999999,0.29574662550443687
8.36,0.08359999999999998,0.29911902478235103
8.47,0.0847,0.30249044892176924
8.58,0.0858,0.3058611539710816
8.69,0.08689999999999999,0.30923139346181144
8.8,0.088,0.312601418382818
8.91,0.08909999999999998,0.3159714775546296
9.02,0.09019999999999999,0.3193418173306712
9.13,0.0913,0.32271268168040557
9.24,0.0924,0.3260843123229482
9.35,0.0935,0.32945694879850546
9.46,0.09459999999999999,0.332830828508086
9.57,0.0957,0.3362061864065687
9.68,0.0968,0.33958325547284834
9.79,0.09789999999999997,0.34296226659973067
9.9,0.099,0.34634344849555565
10.01,0.1001,0.34972702780616793
10.12,0.10119999999999998,0.3531132292923141
10.23,0.1023,0.35650227544827034
10.34,0.10339999999999998,0.3598943869959335
10.45,0.10449999999999998,0.36328978273375184
10.56,0.1056,0.36668867937520816
10.67,0.10669999999999999,0.3700912919194181
10.78,0.10779999999999998,0.37349783333111936
10.89,0.10890000000000001,0.3769085149260651
11,0.10999999999999999,0.3803235460906294
11.11,0.11109999999999999,0.38374313446206676
11.22,0.1122,0.38716748589279887
11.33,0.11329999999999998,0.3905968045987167
11.44,0.11439999999999999,0.39403129291882344
11.55,0.11549999999999999,0.3974711516984063
11.66,0.1166,0.40091657997502644
11.77,0.1177,0.40436777533565965
11.88,0.11879999999999999,0.4078249334993975
11.99,0.11989999999999999,0.4112882487850541
12.1,0.121,0.41475791400017825
12.21,0.1221,0.4182341201758047
12.32,0.1232,0.42171705709975216
12.43,0.12429999999999998,0.42520691288279944
12.54,0.12539999999999998,0.42870387421355016
12.65,0.1265,0.43220812636086936
12.76,0.1276,0.4357198531149124
12.87,0.12869999999999998,0.4392392369114797
12.98,0.1298,0.4427664587720192
13.09,0.1309,0.4463016984850299
13.2,0.13199999999999998,0.44984513403893217
13.31,0.1331,0.45339694273223635
13.42,0.13419999999999999,0.4569573001548703
13.53,0.13529999999999998,0.46052638068079177
13.64,0.1364,0.46410435750442064
13.75,0.13749999999999998,0.4676914024449705
13.86,0.1386,0.4712876862002197
13.97,0.1397,0.4748933782296461
14.08,0.14079999999999998,0.47850864668443477
14.19,0.1419,0.4821336588286496
14.3,0.143,0.48576858049469634
14.41,0.1441,0.48941357646426414
14.52,0.1452,0.4930688104548501
14.63,0.14629999999999999,0.49673444507490083
14.74,0.1474,0.50041064173126
14.85,0.14849999999999997,0.5040975608658781
14.96,0.1496,0.5077953619381407
15.07,0.1507,0.5115042030596397
15.18,0.1518,0.5152242417130654
15.29,0.15289999999999998,0.5189556342182712
15.4,0.154,0.5226985357872503
15.51,0.1551,0.5264531009281909
15.62,0.15619999999999998,0.5302194828772031
15.73,0.1573,0.533997834047183
15.84,0.15839999999999999,0.5377883060583878
15.95,0.15949999999999998,0.5415910493694961
16.06,0.16059999999999997,0.5454062138691766
16.17,0.1617,0.5492339482875114
16.28,0.1628,0.5530744004937214
16.39,0.1639,0.5569277176315529
16.5,0.16499999999999998,0.5607940458725313
16.61,0.1661,0.5646735307272123
16.72,0.16719999999999996,0.5685663167293418
16.83,0.16829999999999998,0.5724725477019837
16.94,0.1694,0.5763923665346696
17.05,0.17049999999999998,0.5803259155243893
17.16,0.1716,0.584273335972075
17.27,0.17269999999999996,0.5882347687733036
17.38,0.17379999999999998,0.592210353746854
17.49,0.17489999999999997,0.5962002299803026
17.6,0.176,0.6002045362309664
17.71,0.1771,0.604223410028429
17.82,0.17819999999999997,0.6082569886252244
17.93,0.1793,0.6123054082416522
18.04,0.18039999999999998,0.6163688047703916
18.15,0.18149999999999997,0.6204473131530821
18.26,0.1826,0.6245410677793534
18.37,0.1837,0.6286502024166181
18.48,0.1848,0.6327748501774263
18.59,0.18589999999999998,0.6369151435987259
18.7,0.187,0.6410712145023928
18.81,0.18809999999999996,0.6452431941226002
18.92,0.18919999999999998,0.6494312132564504
19.03,0.1903,0.6536354019027633
19.14,0.1914,0.6578558895746598
19.25,0.1925,0.6620928053005424
19.36,0.1936,0.6663462774187133
19.47,0.19469999999999998,0.6706164336996527
19.58,0.19579999999999995,0.6749034015614801
19.69,0.1969,0.6792073077153445
19.8,0.198,0.6835282784385063
19.91,0.1991,0.6878664394783197
20.02,0.2002,0.6922219159809322
20.13,0.20129999999999995,0.6965948326894936
20.24,0.20239999999999997,0.7009853138805401
20.35,0.20350000000000001,0.7053934833190029
20.46,0.2046,0.7098194641820816
20.57,0.2057,0.7142633793784796
20.68,0.20679999999999996,0.7187253512555559
20.79,0.20789999999999997,0.7232055015459704
20.9,0.20899999999999996,0.7277039518486675
21.01,0.2101,0.7322208231999571
21.12,0.2112,0.736756236044945
21.23,0.21230000000000002,0.741310310665556
21.34,0.21339999999999998,0.7458831667092823
21.45,0.21449999999999997,0.7504749235210906
21.56,0.21559999999999996,0.7550856999523826
21.67,0.2167,0.7597156145639377
21.78,0.21780000000000002,0.7643647854743411
21.89,0.21889999999999998,0.7690333304622139
22,0.21999999999999997,0.7737213668051793
22.11,0.22109999999999996,0.7784290115048476
22.22,0.22219999999999998,0.7831563811631788
22.33,0.22329999999999997,0.7879035920794026
22.44,0.2244,0.792670759978158
22.55,0.22549999999999998,0.7974580005919698
22.66,0.22659999999999997,0.8022654290150995
22.77,0.22769999999999999,0.8070931600448772
22.88,0.22879999999999998,0.81194130825363
22.99,0.2299,0.8168099878503928
23.1,0.23099999999999998,0.8216993125957656
23.21,0.23209999999999997,0.8266093960249167
23.32,0.2332,0.8315403514331906
23.43,0.23429999999999998,0.8364922916482721
23.54,0.2354,0.8414653292284783
23.65,0.2365,0.8464595766169526
23.76,0.23759999999999998,0.8514751457504937
23.87,0.2387,0.8565121481783162
23.98,0.23979999999999999,0.8615706954463376
24.09,0.2409,0.8666508987747883
24.2,0.242,0.8717528688410225
24.31,0.24309999999999996,0.8768767162779119
24.42,0.2442,0.8820225513584008
24.53,0.2453,0.8871904841412112
24.64,0.2464,0.8923806244419846
24.75,0.2475,0.8975930817475163
24.86,0.24859999999999996,0.9028279652803378
24.97,0.24969999999999995,0.9080853840038197
25.08,0.25079999999999997,0.9133654467668929
25.19,0.2519,0.9186682619781716
25.3,0.253,0.9239939380020754
25.41,0.2541,0.9293425828156289
25.52,0.2552,0.9347143041648475
25.63,0.2563,0.9401092097167661
25.74,0.25739999999999996,0.9455274067845274
25.85,0.2585,0.950969002359608
25.96,0.2596,0.9564341033955723
26.07,0.2607,0.9619228166981746
26.18,0.2618,0.967435248511589
26.29,0.26289999999999997,0.9729715051266931
26.4,0.26399999999999996,0.9785316926456321
26.51,0.2651,0.9841159168386312
26.62,0.2662,0.9897242833631814
26.73,0.2673,0.9953568976797768
26.84,0.26839999999999997,1.0010138649489388
26.95,0.26949999999999996,1.0066952901849462
27.06,0.27059999999999995,1.012401278246146
27.17,0.2717,1.0181319337789039
27.28,0.2728,1.0238873612562576
27.39,0.2739,1.0296676649342027
27.5,0.27499999999999997,1.0354729489898833
27.61,0.27609999999999996,1.0413033171937147
27.72,0.2772,1.0471588733111286
27.83,0.2783,1.0530397209456543
27.94,0.2794,1.0589459634576617
28.05,0.28049999999999997,1.064877704078346
28.16,0.28159999999999996,1.0708350457772668
28.27,0.2827,1.0768180915675183
28.38,0.2838,1.0828269440853235
28.49,0.28489999999999993,1.0888617058714178
28.6,0.286,1.0949224793610852
28.71,0.28709999999999997,1.1010093667190126
28.82,0.2882,1.107122470137324
28.93,0.2893,1.1132618913831878
29.04,0.2904,1.1194277324238342
29.15,0.2914999999999999,1.125620094645145
29.26,0.29259999999999997,1.1318390797190263
29.37,0.2937,1.1380847888639112
29.48,0.2948,1.14435732334132
29.59,0.2959,1.150656784059587
29.7,0.29699999999999993,1.1569832720017015
29.81,0.2981,1.1633368879006125
29.92,0.2992,1.1697177324203207
30.03,0.3003,1.1761259060146632
30.14,0.3014,1.1825615089532475
30.25,0.30249999999999994,1.1890246414892698
30.36,0.3036,1.195515403753554
30.47,0.30469999999999997,1.202033895615242
30.58,0.30579999999999996,1.2085802170019593
30.69,0.3069,1.2151544674299024
30.8,0.308,1.2217567466437158
30.91,0.3091,1.228387153923867
31.02,0.3102,1.235045788698877
31.13,0.31129999999999997,1.2417327501269264
31.24,0.31239999999999996,1.2484481372825404
31.35,0.3135,1.2551920490895907
31.46,0.3146,1.2619645843768017
31.57,0.3157,1.2687658418831158
31.68,0.31679999999999997,1.275595920259172
31.79,0.31789999999999996,1.2824549178093965
31.9,0.31899999999999995,1.2893429331518358
32.01,0.3201,1.2962600643250597
32.12,0.32119999999999993,1.3032064096121883
32.23,0.3222999999999999,1.3101820670044997
32.34,0.3234,1.317187134402099
32.45,0.3245,1.3242217096393543
32.56,0.3256,1.3312858903775913
32.67,0.3267,1.338379774368145
32.78,0.3278,1.3455034589404784
32.89,0.32889999999999997,1.3526570415214003
33,0.32999999999999996,1.359840619504797
33.11,0.3311,1.3670542899481926
33.22,0.3322,1.3742981500416411
33.33,0.33329999999999993,1.381572296707098
33.44,0.3343999999999999,1.388876826826169
33.55,0.33549999999999996,1.3962118371514431
33.66,0.33659999999999995,1.4035774244771506
33.77,0.3377,1.4109736852716823
33.88,0.3388,1.418400716174631
33.99,0.3399,1.4258586133651487
34.1,0.34099999999999997,1.4333474733657348
34.21,0.3421,1.44086739226798
34.32,0.3432,1.4484184662253583
34.43,0.34429999999999994,1.4560007912499409
34.54,0.34539999999999993,1.4636144632344736
34.65,0.3465,1.4712595780601954
34.76,0.34759999999999996,1.4789362314532826
34.87,0.34869999999999995,1.4866445190426905
34.98,0.34979999999999994,1.49438453641334
35.09,0.3509,1.502156379134688
35.2,0.352,1.5099601424199887
35.31,0.3531,1.5177959217190586
35.42,0.3542,1.5256638122070227
35.53,0.3553,1.5335639089918218
35.64,0.35639999999999994,1.5414963071180896
35.75,0.3575,1.5494611016824482
35.86,0.3586,1.5574583872444572
35.97,0.35969999999999996,1.5654882588352703
36.08,0.36079999999999995,1.5735508111577
36.19,0.36189999999999994,1.5816461387318952
36.3,0.36299999999999993,1.5897743362071861
36.41,0.3640999999999999,1.5979354979918343
36.52,0.3652,1.6061297184947985
36.63,0.3663,1.6143570918872476
36.74,0.3674,1.6226177125176993
36.85,0.3685,1.6309116744709182
36.96,0.3696,1.6392390717696663
37.07,0.3707,1.6475999985633534
37.18,0.37179999999999996,1.6559945485496452
37.29,0.37289999999999995,1.6644228155708318
37.4,0.374,1.6728848935195708
37.51,0.37509999999999993,1.68138087587119
37.62,0.3761999999999999,1.68991085633505
37.73,0.3772999999999999,1.698474928434143
37.84,0.37839999999999996,1.707073185440008
37.95,0.3795,1.7157057209865856
38.06,0.3806,1.7243726281111655
38.17,0.38170000000000004,1.7330740001740064
38.28,0.3828,1.741809930227167
38.39,0.38389999999999996,1.750580511310259
38.5,0.385,1.759385836479235
38.61,0.38609999999999994,1.7682259985992768
38.72,0.3872,1.777101090594794
38.83,0.3882999999999999,1.7860112050604187
38.94,0.38939999999999997,1.7949564348314646
39.05,0.39049999999999996,1.8039368724916987
39.16,0.3915999999999999,1.8129526105014737
39.27,0.39270000000000005,1.8220037415104369
39.38,0.3938,1.8310903578449012
39.49,0.3949,1.8402125516724874
39.6,0.396,1.849370415545997
39.71,0.39709999999999995,1.8585640414099427
39.82,0.3982,1.8677935214537897
39.93,0.39929999999999993,1.8770589477676058
40.04,0.4004,1.886360412351739
40.15,0.40149999999999997,1.8956980070339358
40.26,0.4025999999999999,1.9050718236268798
40.37,0.40369999999999995,1.9144819539885554
40.48,0.40479999999999994,1.9239284898531626
40.59,0.40590000000000004,1.9334115228000914
40.7,0.40700000000000003,1.9429311443168127
40.81,0.40809999999999996,1.9524874459605037
40.92,0.4092,1.9620805191654191
41.03,0.41029999999999994,1.97171045527048
41.14,0.4114,1.981377345548928
41.25,0.4125,1.9910812813274086
41.36,0.4135999999999999,2.000822353538488
41.47,0.41469999999999996,2.0106006534151692
41.58,0.41579999999999995,2.020416271967445
41.69,0.4169,2.030269300156434
41.8,0.4179999999999999,2.040159828847525
41.91,0.4191,2.050087948777382
42.02,0.4202,2.060053750977747
42.13,0.42129999999999995,2.0700573257379737
42.24,0.4224,2.0800987638724213
42.35,0.4235,2.0901781559636343
42.46,0.42460000000000003,2.1002955924506117
42.57,0.42569999999999997,2.1104511637498473
42.68,0.42679999999999996,2.120644960248248
42.79,0.4279,2.130877072209902
42.9,0.42899999999999994,2.14114758979815
43.01,0.4301,2.15145660321884
43.12,0.4311999999999999,2.161804202567435
43.23,0.4322999999999999,2.172190477996005
43.34,0.4334,2.182615519203005
43.45,0.4345,2.193079416298688
43.56,0.43560000000000004,2.2035822590116227
43.67,0.4367,2.2141241370316247
43.78,0.43779999999999997,2.224705140297037
43.89,0.4389,2.2353253582906807
44,0.43999999999999995,2.245984880586332
44.11,0.4411,2.2566837967257354
44.22,0.4421999999999999,2.267422196121477
44.33,0.44329999999999997,2.2782001680978836
44.44,0.44439999999999996,2.28901780212716
44.55,0.4454999999999999,2.299875187402901
44.66,0.44659999999999994,2.310772413025244
44.77,0.4477,2.3217095682173863
44.88,0.4488,2.332686741958617
44.99,0.4499,2.3437040232757176
45.1,0.45099999999999996,2.3547615012416374
45.21,0.4521,2.3658592645091296
45.32,0.45319999999999994,2.376997401986314
45.43,0.4543,2.388176002390178
45.54,0.45539999999999997,2.3993951545657133
45.65,0.4564999999999999,2.4106549467993057
45.76,0.45759999999999995,2.421955467894269
45.87,0.45869999999999994,2.433296806198485
45.98,0.4598,2.4446790503458007
46.09,0.46090000000000003,2.4561022885270134
46.2,0.46199999999999997,2.467566609036472
46.31,0.4631,2.4790721002293137
46.42,0.46419999999999995,2.490618850205269
46.53,0.4653,2.5022069471504964
46.64,0.4664,2.5138364789361347
46.75,0.4674999999999999,2.5255075337326978
46.86,0.46859999999999996,2.537220199352788
46.97,0.46969999999999995,2.5489745637137156
47.08,0.4708,2.560770714658707
47.19,0.47189999999999993,2.5726087397997786
47.3,0.473,2.5844887269079817
47.41,0.47409999999999997,2.5964107635973988
47.52,0.47519999999999996,2.6083749373990277
47.63,0.4763,2.620381335744079
47.74,0.4774,2.63243004622088
47.85,0.47850000000000004,2.6445211559231026
47.96,0.47959999999999997,2.6566547523416957
48.07,0.48069999999999996,2.6688309227766265
48.18,0.4818,2.681049754205064
48.29,0.48289999999999994,2.6933113339133397
48.4,0.484,2.7056157488755876
48.51,0.4850999999999999,2.717963086033843
48.62,0.4861999999999999,2.7303534324289815
48.73,0.48729999999999996,2.742786874839382
48.84,0.4884,2.7552635000527137
48.95,0.48950000000000005,2.767783394911983
49.06,0.4906,2.7803466460105675
49.17,0.49169999999999997,2.792953340017313
49.28,0.4928,2.8056035634464673
49.39,0.49389999999999995,2.8182974028520387
49.5,0.495,2.831034944560777
49.61,0.49609999999999993,2.843816275018771
49.72,0.4971999999999999,2.8566414805004485
49.83,0.49829999999999997,2.8695106472649794
49.94,0.4993999999999999,2.882423861506499
50.05,0.5005,2.895381209351652
50.16,0.5015999999999999,2.9083827768589883
50.27,0.5026999999999999,2.921428649935843
50.38,0.5038,2.9345189146180193
50.49,0.5049,2.947653656843446
50.6,0.506,2.960832962233825
50.71,0.5071,2.974056916708628
50.82,0.5082,2.987325605852074
50.93,0.5093,3.0006391153613117
51.04,0.5104,3.0139975307113143
51.15,0.5115,3.0274009374338853
51.26,0.5126,3.0408494210231067
51.37,0.5136999999999999,3.0543430667951967
51.48,0.5147999999999999,3.06788196020506
51.59,0.5159,3.0814661863750334
51.7,0.517,3.0950958304927365
51.81,0.5181,3.1087709777695665
51.92,0.5192,3.1224917132299264
52.03,0.5203,3.1362581218418697
52.14,0.5214,3.1500702886043954
52.25,0.5225,3.163928298360085
52.36,0.5236,3.177832235967498
52.47,0.5246999999999999,3.191782186264267
52.58,0.5257999999999999,3.2057782337717278
52.69,0.5269,3.219820463328481
52.8,0.5279999999999999,3.2339089593320507
52.91,0.5290999999999999,3.2480438063994304
53.02,0.5302,3.2622250889417694
53.13,0.5313,3.276452891382296
53.24,0.5324,3.290727297997273
53.35,0.5335,3.305048393121906
53.46,0.5346,3.31941626080805
53.57,0.5357,3.3338309854118413
53.68,0.5367999999999999,3.348292650909646
53.79,0.5379,3.362801341331629
53.9,0.5389999999999999,3.3773571406651954
54.01,0.5400999999999999,3.391960132729098
54.12,0.5411999999999999,3.4066104014300223
54.23,0.5422999999999999,3.421308030415559
54.34,0.5434,3.4360531035349506
54.45,0.5445,3.450845704421694
54.56,0.5456,3.4656859166072334
54.67,0.5467,3.480573823641927
54.78,0.5478,3.4955095090572894
54.89,0.5489,3.5104930560472947
55,0.5499999999999999,3.525524548187973
55.11,0.5510999999999999,3.540604068636096
55.22,0.5521999999999999,3.5557317005799196
55.33,0.5532999999999999,3.5709075272970914
55.44,0.5544,3.5861316318266874
55.55,0.5554999999999999,3.601404097098589
55.66,0.5566,3.6167250061764684
55.77,0.5577,3.6320944419766827
55.88,0.5588,3.647512487234786
55.99,0.5599000000000001,3.6629792248684576
56.1,0.5609999999999999,3.678494737525295
56.21,0.5621,3.6940591079590903
56.32,0.5631999999999999,3.7096724185763468
56.43,0.5642999999999999,3.725334751969016
56.54,0.5654,3.741046190808517
56.65,0.5664999999999999,3.7568068172768228
56.76,0.5676,3.7726167138886564
56.87,0.5687,3.7884759627274778
56.98,0.5697999999999999,3.8043846462149795
57.09,0.5709000000000001,3.8203428465101257
57.2,0.572,3.836350645421075
57.31,0.5731,3.852408125426522
57.42,0.5741999999999999,3.868515368184446
57.53,0.5752999999999999,3.8846724556878587
57.64,0.5764,3.9008794698743436
57.75,0.5774999999999999,3.917136492408093
57.86,0.5786,3.93344360515022
57.97,0.5797,3.949800889636946
58.08,0.5808,3.9662084275568055
58.19,0.5819,3.982666300483368
58.3,0.5829999999999999,3.999174589809251
58.41,0.5841,4.015733376967513
58.52,0.5851999999999999,4.032342743336433
58.63,0.5862999999999999,4.049002770210038
58.74,0.5874,4.0657135389026955
58.85,0.5884999999999999,4.082475130438489
58.96,0.5896,4.099287626027638
59.07,0.5907,4.116151106700051
59.18,0.5918,4.133065653465595
59.29,0.5929,4.150031347095877
59.4,0.5939999999999999,4.167048268610608
59.51,0.5951,4.184116498798731
59.62,0.5962,4.201236118336836
59.73,0.5972999999999999,4.2184072079179895
59.84,0.5984,4.235629848179607
59.95,0.5994999999999999,4.252904119693507
60.06,0.6006,4.270230102965971
60.17,0.6017,4.2876078783263
60.28,0.6028,4.3050375260948925
60.39,0.6039,4.3225191267532574
60.5,0.6049999999999999,4.3400527604688985
60.61,0.6061,4.357638507351074
60.72,0.6072,4.375276447629599
60.83,0.6083,4.392966661274556
60.94,0.6093999999999999,4.410709228341202
61.05,0.6104999999999999,4.4285042287194285
61.16,0.6115999999999999,4.446351742328501
61.27,0.6127,4.464251848876337
61.38,0.6138,4.482204628232469
61.49,0.6149,4.500210159962943
61.6,0.616,4.518268523767272
61.71,0.6171,4.53637979925278
61.82,0.6182,4.55454406572942
61.93,0.6193,4.572761402874913
62.04,0.6204,4.591031889843758
62.15,0.6214999999999999,4.609355606086678
62.26,0.6225999999999999,4.627732630842953
62.37,0.6236999999999999,4.646163043252256
62.48,0.6247999999999999,4.6646469224526195
62.59,0.6259,4.683184347458697
62.7,0.627,4.701775397441605
62.81,0.6281,4.720420151177689
62.92,0.6292,4.739118687622325
63.03,0.6303,4.757871085567207
63.14,0.6314,4.776677423712477
63.25,0.6325,4.79553778091474
63.36,0.6335999999999999,4.8144522355355015
63.47,0.6347,4.833420866450627
63.58,0.6357999999999999,4.852443751889157
63.69,0.6368999999999999,4.871520970604253
63.8,0.6379999999999999,4.890652600703779
63.91,0.6390999999999999,4.909838720637186
64.02,0.6402,4.929079408625167
64.13,0.6412999999999999,4.948374742872706
64.24,0.6423999999999999,4.967724801599815
64.35,0.6435,4.987129662749202
64.46,0.6445999999999998,5.006589404476186
64.57,0.6456999999999999,5.026104104636953
64.68,0.6468,5.045673841010335
64.79,0.6479,5.065298691683239
64.9,0.649,5.0849787342017505
65.01,0.6501,5.104714046379054
65.12,0.6512,5.124504705930157
65.23,0.6523,5.144350790189229
65.34,0.6534,5.164252376938463
65.45,0.6545,5.1842095435691355
65.56,0.6556,5.204222367308526
65.67,0.6567000000000001,5.224290925701052
65.78,0.6577999999999999,5.244415295968292
65.89,0.6588999999999999,5.264595555270873
66,0.6599999999999999,5.2848317807602125
66.11,0.6610999999999999,5.305124049632204
66.22,0.6622,5.325472438756178
66.33,0.6632999999999999,5.345877025153646
66.44,0.6644,5.366337885853172
66.55,0.6655,5.386855097497729
66.66,0.6665999999999999,5.407428736935296
66.77,0.6677,5.4280588810621095
66.88,0.6687999999999998,5.448745606267574
66.99,0.6698999999999999,5.469488989339412
67.1,0.6709999999999999,5.490289106695507
67.21,0.6720999999999998,5.511146034995962
67.32,0.6731999999999999,5.532059850431799
67.43,0.6743,5.553030629460639
67.54,0.6754,5.574058448375883
67.65,0.6765,5.595143383395155
67.76,0.6776,5.616285510699559
67.87,0.6787000000000001,5.63748490636097
67.98,0.6798,5.658741646421051
68.09,0.6809000000000001,5.680055806984279
68.2,0.6819999999999999,5.701427463794219
68.31,0.6830999999999999,5.722856692855075
68.42,0.6842,5.74434356993595
68.53,0.6852999999999999,5.765888170775547
68.64,0.6864,5.787490570980523
68.75,0.6875,5.809150846246716
68.86,0.6885999999999999,5.830869072143249
68.97,0.6897,5.852645324176893
69.08,0.6907999999999999,5.874479677696453
69.19,0.6919,5.896372208187589
69.3,0.693,5.918322990862904
69.41,0.6940999999999999,5.940332101045294
69.52,0.6951999999999999,5.96239961390583
69.63,0.6962999999999999,5.984525604615097
69.74,0.6973999999999999,6.0067101481821625
69.85,0.6984999999999999,6.028953319602417
69.96,0.6995999999999999,6.051255193900101
70.07,0.7006999999999999,6.0736158459885266
70.18,0.7018,6.096035350544823
70.29,0.7029000000000001,6.118513782557982
70.4,0.704,6.141051216562363
70.51,0.7051,6.163647727304093
70.62,0.7062,6.186303389240739
70.73,0.7072999999999999,6.209018277081237
70.84,0.7084,6.231792465155914
70.95,0.7095,6.254626027896999
71.06,0.7106,6.277519039753303
71.17,0.7117,6.300471574824119
71.28,0.7127999999999999,6.323483707516246
71.39,0.7139,6.346555511949269
71.5,0.715,6.369687062070671
71.61,0.7161,6.392878432122171
71.72,0.7172,6.416129696017658
71.83,0.7182999999999999,6.439440927770893
71.94,0.7193999999999999,6.4628122009864715
72.05,0.7204999999999999,6.486243589799975
72.16,0.7215999999999999,6.50973516778772
72.27,0.7226999999999999,6.533287008593206
72.38,0.7237999999999999,6.55689918593501
72.49,0.7248999999999999,6.580571773374479
72.6,0.7259999999999999,6.604304844320441
72.71,0.7270999999999999,6.628098472310983
72.82,0.7281999999999998,6.651952730815129
72.93,0.7293,6.675867693000224
73.04,0.7304,6.699843432024442
73.15,0.7315,6.723880021437231
73.26,0.7326,6.747977534198516
73.37,0.7337,6.772136043297101
73.48,0.7348,6.796355621964456
73.59,0.7359,6.820636343118445
73.7,0.737,6.844978279554553
73.81,0.7381,6.869381504217812
73.92,0.7392,6.893846089921929
74.03,0.7403,6.918372109390299
74.14,0.7414,6.9429596352146925
74.25,0.7424999999999999,6.967608740052604
74.36,0.7435999999999999,6.992319496480347
74.47,0.7446999999999999,7.0170919770235605
74.58,0.7457999999999999,7.041926254115601
74.69,0.7468999999999999,7.066822400082995
74.8,0.748,7.091780487272727
74.91,0.7490999999999999,7.1168005879178935
75.02,0.7501999999999999,7.14188277417154
75.13,0.7513,7.1670271183557865
75.24,0.7523999999999998,7.192233692421698
75.35,0.7535,7.21750256843248
75.46,0.7545999999999998,7.242833818377941
75.57,0.7556999999999998,7.268227514051838
75.68,0.7567999999999999,7.293683727473668
75.79,0.7579000000000001,7.319202530383782
75.9,0.759,7.344783994377074
76.01,0.7601,7.370428191313255
76.12,0.7612,7.396135192635848
76.23,0.7623,7.4219050701732865
76.34,0.7634000000000001,7.447737895142488
76.45,0.7645000000000001,7.473633739141019
76.56,0.7656,7.499592673491632
76.67,0.7666999999999999,7.525614769564944
76.78,0.7677999999999999,7.551700098631516
76.89,0.7689,7.577848731823536
77,0.77,7.604060740395697
77.11,0.7710999999999999,7.630336195337487
77.22,0.7721999999999999,7.656675167838449
77.33,0.7732999999999999,7.683077728689908
77.44,0.7744,7.709543949033839
77.55,0.7755,7.736073899479591
77.66,0.7765999999999998,7.762667651046005
77.77,0.7776999999999998,7.789325274399048
77.88,0.7787999999999999,7.816046840217298
77.99,0.7798999999999999,7.8428324191995005
78.1,0.7809999999999999,7.869682081825625
78.21,0.7820999999999999,7.896595898692841
78.32,0.7831999999999998,7.923573940293928
78.43,0.7843,7.950616276915152
78.54,0.7854000000000001,7.977722979018622
78.65,0.7865000000000001,8.00489411678989
78.76,0.7876,8.032129760598025
78.87,0.7887,8.059429980545225
78.98,0.7898,8.086794846772827
79.09,0.7909,8.114224429274827
79.2,0.792,8.141718798112917
79.31,0.7930999999999999,8.169278023305521
79.42,0.7941999999999999,8.196902174642863
79.53,0.7953,8.22459132201095
79.64,0.7964,8.25234553523524
79.75,0.7975,8.28016488398175
79.86,0.7985999999999999,8.308049437851801
79.97,0.7996999999999999,8.335999266591433
80.08,0.8008,8.364014439687876
80.19,0.8019,8.392095026677652
80.3,0.8029999999999999,8.420241097008127
80.41,0.8040999999999999,8.448452719992407
80.52,0.8051999999999998,8.47672996506023
80.63,0.8063,8.505072901418274
80.74,0.8073999999999999,8.533481598321496
80.85,0.8084999999999999,8.561956124970223
80.96,0.8095999999999999,8.590496550336947
81.07,0.8106999999999998,8.619102943708315
81.18,0.8118000000000001,8.647775373882421
81.29,0.8129000000000001,8.676513909948735
81.4,0.8140000000000001,8.705318620547024
81.51,0.8150999999999999,8.734189574800372
81.62,0.8161999999999999,8.763126841323265
81.73,0.8173,8.792130488888327
81.84,0.8184,8.821200586133193
81.95,0.8195,8.850337201758284
82.06,0.8205999999999999,8.879540404165764
82.17,0.8216999999999999,8.908810261949798
82.28,0.8228,8.93814684359314
82.39,0.8239,8.96755021750296
82.5,0.825,8.997020451895965
82.61,0.8261,9.026557615052454
82.72,0.8271999999999998,9.056161775356477
82.83,0.8283,9.085833000892922
82.94,0.8293999999999999,9.11557135968732
83.05,0.8304999999999999,9.14537691998735
83.16,0.8315999999999999,9.175249749717343
83.27,0.8327,9.205189916794247
83.38,0.8338,9.235197489145477
83.49,0.8348999999999999,9.26527253469254
83.6,0.8359999999999999,9.295415121146045
83.71,0.8370999999999998,9.325625316246471
83.82,0.8382,9.355903187667781
83.93,0.8393,9.386248803107993
84.04,0.8404,9.416662230150584
84.15,0.8415,9.447143536250763
84.26,0.8425999999999999,9.477692788917935
84.37,0.8436999999999999,9.508310055603117
84.48,0.8448,9.538995403653312
84.59,0.8459,9.569748900302356
84.7,0.847,9.600570612867084
84.81,0.8481,9.631460608607135
84.92,0.8492000000000001,9.662418954592228
85.03,0.8503000000000001,9.693445717910773
85.14,0.8513999999999999,9.724540965687757
85.25,0.8524999999999999,9.755704764861623
85.36,0.8535999999999999,9.786937182457418
85.47,0.8547,9.818238285185384
85.58,0.8558,9.84960814011521
85.69,0.8568999999999999,9.88104681378359
85.8,0.8579999999999999,9.912554373072735
85.91,0.8590999999999999,9.944130884608665
86.02,0.8602,9.97577641505777
86.13,0.8613,10.007491030955983
86.24,0.8623999999999998,10.039274798860712
86.35,0.8634999999999998,10.0711277852034
86.46,0.8645999999999998,10.103050056397533
86.57,0.8656999999999999,10.135041678765107
86.68,0.8668,10.167102718713815
86.79,0.8679,10.199233242478261
86.9,0.869,10.231433316231351
87.01,0.8701,10.263703006205029
87.12,0.8712000000000001,10.296042378397624
87.23,0.8723000000000001,10.328451498948667
87.34,0.8734,10.360930433775044
87.45,0.8744999999999999,10.393479248876702
87.56,0.8755999999999999,10.426098010218736
87.67,0.8767,10.458786783539832
87.78,0.8778,10.491545634683813
87.89,0.8788999999999999,10.524374629409927
88,0.8799999999999999,10.557273833365198
88.11,0.8810999999999999,10.59024331226641
88.22,0.8822,10.623283131667637
88.33,0.8833,10.656393357030618
88.44,0.8843999999999999,10.689574054026762
88.55,0.8854999999999998,10.722825288025886
88.66,0.8865999999999999,10.756147124281098
88.77,0.8876999999999999,10.789539628316412
88.88,0.8887999999999999,10.823002865298909
88.99,0.8898999999999999,10.85653690056215
89.1,0.8909999999999998,10.890141799223573
89.21,0.8921,10.92381762654005
89.32,0.8931999999999999,10.957564447499728
89.43,0.8943000000000001,10.991382327049305
89.54,0.8954,11.025271330311522
89.65,0.8965,11.05923152221724
89.76,0.8976,11.09326296762775
89.87,0.8987,11.127365731540829
89.98,0.8998,11.16153987848513
90.09,0.9008999999999999,11.195785473304044
90.2,0.9019999999999999,11.230102580742978
90.31,0.9031,11.264491265381052
90.42,0.9042,11.29895159193066
90.53,0.9053,11.333483624806194
90.64,0.9063999999999999,11.368087428542026
90.75,0.9074999999999999,11.402763067540349
90.86,0.9086,11.437510606302675
90.97,0.9097,11.472330109169596
91.08,0.9107999999999999,11.507221640310156
91.19,0.9118999999999999,11.542185264032288
91.3,0.9129999999999998,11.57722104468891
91.41,0.9141,11.612329046297582
91.52,0.9151999999999999,11.647509332966298
91.63,0.9162999999999999,11.682761968742879
91.74,0.9173999999999999,11.718087017662171
91.85,0.9184999999999998,11.753484543758614
91.96,0.9196,11.788954610892343
92.07,0.9206999999999999,11.824497282931366
92.18,0.9218000000000001,11.86011262363
92.29,0.9228999999999999,11.895800696761443
92.4,0.9239999999999999,11.931561566143193
92.51,0.9251,11.96739529537227
92.62,0.9262,12.00330194821279
92.73,0.9273,12.039281588120664
92.84,0.9283999999999999,12.075334278597513
92.95,0.9294999999999999,12.111460083181774
93.06,0.9306,12.14765906540092
93.17,0.9317,12.183931288503961
93.28,0.9328,12.220276815938464
93.39,0.9339,12.256695710922505
93.5,0.9349999999999998,12.29318803669716
93.61,0.9361,12.329753856620068
93.72,0.9371999999999999,12.366393233666027
93.83,0.9382999999999999,12.403106230983573
93.94,0.9393999999999999,12.439892911703623
94.05,0.9405,12.476753338927127
94.16,0.9416,12.5136875753987
94.27,0.9426999999999999,12.550695684241656
94.38,0.9437999999999999,12.58777772815515
94.49,0.9448999999999999,12.62493377016495
94.6,0.946,12.662163872969723
94.71,0.9470999999999999,12.699468099223354
94.82,0.9481999999999999,12.736846511779742
94.93,0.9493,12.774299173144108
95.04,0.9503999999999999,12.811826145999621
95.15,0.9514999999999999,12.849427492940272
95.26,0.9526,12.887103276452166
95.37,0.9537,12.924853558997228
95.48,0.9548,12.962678402971967
95.59,0.9559,13.00057787078408
95.7,0.9570000000000001,13.038552024748306
95.81,0.9581000000000001,13.076600927106412
95.92,0.9591999999999999,13.11472464014687
96.03,0.9602999999999999,13.152923226132257
96.14,0.9613999999999999,13.191196747179324
96.25,0.9625,13.229545265326719
96.36,0.9636,13.267968842669573
96.47,0.9646999999999999,13.306467541334587
96.58,0.9657999999999999,13.34504142306666
96.69,0.9668999999999999,13.383690550031275
96.8,0.968,13.42241498403849
96.91,0.9691,13.461214786878031
97.02,0.9701999999999998,13.500090020311141
97.13,0.9712999999999998,13.539040746181854
97.24,0.9723999999999998,13.578067026270165
97.35,0.9734999999999999,13.617168922007924
97.46,0.9745999999999999,13.656346495189554
97.57,0.9756999999999999,13.695599807435073
97.68,0.9768,13.734928920250205
97.79,0.9779,13.774333895007265
97.9,0.9790000000000001,13.813814793248522
98.01,0.9801000000000001,13.853371676355263
98.12,0.9812,13.893004605701114
98.23,0.9823,13.932713642610304
98.34,0.9833999999999999,13.972498848344761
98.45,0.9845,14.012360284138035
98.56,0.9856,14.05229801112138
98.67,0.9866999999999999,14.09231209060387
98.78,0.9877999999999999,14.132402583510599
98.89,0.9888999999999999,14.172569551027369
99,0.99,14.212813054003002
99.11,0.9911,14.253133153707694
99.22,0.9921999999999999,14.29352991091694
99.33,0.9932999999999998,14.334003386292249
99.44,0.9943999999999998,14.374553641064994
99.55,0.9954999999999999,14.415180735850301
99.66,0.9965999999999999,14.455884731427002
99.77,0.9976999999999999,14.496665688561137
99.88,0.9987999999999998,14.537523667882478
99.99,0.9999,14.578458730111736
100.1,1.,14.575495669218943
100.21,1.,14.569651071283861
100.32,1.,14.564580658498608
100.43,1.,14.559971275028277
100.54,1.,14.555709664682608
100.65,1.,14.55172979065632
100.76,1.,14.547982864303272
100.87,1.,14.544430206664153
100.98,1.,14.541040605235017
101.09,1.,14.537788752194652
101.2,1.,14.534654086599268
101.31,1.,14.531619880015992
101.42,1.,14.52867250116489
101.53,1.,14.525800822965877
101.64,1.,14.52299574367714
101.75,1.,14.520249800144356
101.86,1.,14.51755685553534
101.97,1.,14.514911847054524
102.08,1.,14.51231058197163
102.19,1.,14.509749573095572
102.3,1.,14.5072259055049
102.41,1.,14.504737129157434
102.52,1.,14.502281171789875
102.63,1.,14.499856268752186
102.74,1.,14.497460906022646
102.85,1.,14.495093774410616
102.96,1.,14.492753732124392
103.07,1.,14.490439774824274
103.18,1.,14.488151011117965
103.29,1.,14.485886642892572
103.4,1.,14.483645949208913
103.51,1.,14.48142827328887
103.62,1.,14.47923301206052
103.73,1.,14.477059607485655
103.84,1.,14.474907539475103
103.95,1.,14.47277632042726
104.06,1.,14.470665490399231
104.17,1.,14.468574613379566
104.28,1.,14.466503274085284
104.39,1.,14.464451075507464
104.5,1.,14.46241763669755
104.61,1.,14.460402591190428
104.72,1.,14.458405585296326
104.83,1.,14.456426276976803
104.94,1.,14.454464335124985
105.05,1.,14.452519438251175
105.16,1.,14.450591273989419
105.27,1.,14.44867953851393
105.38,1.,14.446783935982827
105.49,1.,14.444904178054134
105.6,1.,14.443039983348918
105.71,1.,14.441191077382555
105.82,1.,14.43935719212327
105.93,1.,14.437538065580197
106.04,1.,14.435733441774117
106.15,1.,14.433943070382218
106.26,1.,14.432166706600519
106.37,1.,14.430404110820078
106.48,1.,14.428655048666666
106.59,1.,14.426919290674803
106.7,1.,14.4251966121998
106.81,1.,14.423486793226747
106.92,1.,14.421789618318995
107.03,1.,14.420104876426185
107.14,1.,14.418432360774387
107.25,1.,14.416771868791052
107.36,1.,14.415123201903192
107.47,1.,14.41348616558385
107.58,1.,14.411860569110699
107.69,1.,14.410246225489628
107.8,1.,14.40864295146843
107.91,1.,14.407050567345966
108.02,1.,14.405468896894307
108.13,1.,14.403897767315819
108.24,1.,14.402337009175332
108.35,1.,14.400786456174075
108.46,1.,14.399245945362425
108.57,1.,14.397715316766924
108.68,1.,14.396194413502947
108.79,1.,14.394683081651662
108.9,1.,14.39318117018068
109.01,1.,14.391688530889322
109.12,1.,14.390205018385098
109.23,1.,14.388730489965011
109.34,1.,14.387264805588098
109.45,1.,14.385807827776425
109.56,1.,14.384359421729892
109.67,1.,14.38291945491464
109.78,1.,14.381487797405486
109.89,1.,14.380064321640978
110,0.,0.