File: Module2/strain64.txt
SAMPLE PARAMETERS
Gauge length [mm]: 22.4523
Area [mm2]: 77.6157
EXPERIMENTAL PARAMETERS
Time [s]: 7.04
Number of steps: 1000
Displacement (0) or force control (1): 0
Schedule ID: 0
Point 1,0.,0.
Point 2,6.4,1.
Point 3,7.04,1.
RESULTS
Time [s],Displacement [mm],Force [N]
0.,0.,0.
0.00704,0.0010999999999999998,0.0195321285079521
0.01408,0.0021999999999999997,0.03673330527072823
0.02112,0.0033,0.052246820022749885
0.02816,0.004399999999999999,0.06653043053966332
0.0352,0.0055000000000000005,0.07991007776282208
0.04224,0.0066,0.0926180331610352
0.049280000000000004,0.007700000000000001,0.10481999908844135
0.05632,0.008799999999999999,0.11663436402303089
0.06336,0.009899999999999999,0.12814588486247414
0.0704,0.011000000000000001,0.13941540869829286
0.07744000000000001,0.0121,0.15048678108861052
0.08448,0.0132,0.16139175489269733
0.09152,0.0143,0.1721534779707509
0.09856000000000001,0.015400000000000002,0.18278897225522917
0.1056,0.016499999999999997,0.19331089477024224
0.11264,0.017599999999999998,0.2037287897391669
0.11968000000000001,0.0187,0.21404997836603534
0.12672,0.019799999999999998,0.22428019087679432
0.13376000000000002,0.020900000000000002,0.2344240170073959
0.1408,0.022000000000000002,0.2444852249682303
0.14784,0.023099999999999996,0.25446698972160475
0.15488000000000002,0.0242,0.26437205450702994
0.16192,0.0253,0.27420284616581997
0.16896,0.0264,0.2839615577334275
0.17600000000000002,0.0275,0.2936502067136844
0.18304,0.0286,0.30327067714610834
0.19008,0.029699999999999997,0.31282474972798213
0.19712000000000002,0.030800000000000004,0.32231412324608183
0.20416,0.0319,0.3317404301534941
0.2112,0.032999999999999995,0.3411052477899011
0.21824000000000002,0.034100000000000005,0.35041010672409384
0.22528,0.035199999999999995,0.35965649638760233
0.23232,0.0363,0.36884587000721547
0.23936000000000002,0.0374,0.3779796475974773
0.2464,0.0385,0.38705921850584674
0.25344,0.039599999999999996,0.3960859436501398
0.26048,0.04069999999999999,0.40506115683520866
0.26752000000000004,0.041800000000000004,0.41398616599569293
0.27456,0.0429,0.4228622544401338
0.2816,0.044000000000000004,0.43169068155148643
0.28864,0.0451,0.44047268361549047
0.29568,0.04619999999999999,0.4492094743163144
0.30272,0.047299999999999995,0.4579022457939733
0.30976000000000004,0.0484,0.46655216871380784
0.3168,0.0495,0.4751603930382745
0.32384,0.0506,0.4837280483017773
0.33088,0.0517,0.49225624448832
0.33792,0.0528,0.5007460717945504
0.34496,0.053899999999999997,0.5091986018385941
0.35200000000000004,0.055,0.5176148874284986
0.35904,0.0561,0.5259959629985599
0.36608,0.0572,0.534342845489133
0.37312,0.0583,0.5426565341983276
0.38016,0.059399999999999994,0.5509380111145862
0.3872,0.0605,0.5591882419321292
0.39424000000000003,0.06160000000000001,0.5674081752652133
0.40128,0.06269999999999999,0.5755987438691087
0.40832,0.0638,0.5837608648594603
0.41536,0.0649,0.5918954395067011
0.4224,0.06599999999999999,0.6000033540268219
0.42944,0.06709999999999999,0.6080854794866991
0.43648000000000003,0.06820000000000001,0.6161426725800306
0.44352,0.0693,0.6241757753770613
0.45056,0.07039999999999999,0.6321856159191066
0.4576,0.0715,0.6401730084822088
0.46464,0.0726,0.6481387535875879
0.47168000000000004,0.0737,0.6560836384326113
0.47872000000000003,0.0748,0.6640084373586844
0.48576,0.0759,0.6719139114865748
0.4928,0.077,0.679800809601916
0.49984,0.0781,0.6876698680438393
0.50688,0.07919999999999999,0.6955218108598806
0.51392,0.0803,0.7033573503931059
0.52096,0.08139999999999999,0.7111771871400796
0.528,0.0825,0.7189820100356066
0.5350400000000001,0.08360000000000001,0.7267724968971602
0.54208,0.0847,0.7345493143467132
0.54912,0.0858,0.7423131181840895
0.55616,0.08689999999999999,0.7500645534150296
0.5632,0.08800000000000001,0.7578042547205907
0.57024,0.0891,0.7655328464133727
0.57728,0.0902,0.7732509426514974
0.5843200000000001,0.09129999999999999,0.7809591478227588
0.59136,0.09239999999999998,0.7886580564486465
0.5984,0.0935,0.7963482534474707
0.60544,0.09459999999999999,0.8040303144486913
0.61248,0.0957,0.8117048058944085
0.6195200000000001,0.0968,0.8193722851468241
0.62656,0.09789999999999999,0.8270333004399635
0.6336,0.099,0.8346883916640254
0.64064,0.1001,0.8423380899711366
0.64768,0.1012,0.8499829181369982
0.65472,0.10229999999999999,0.8576233906182302
0.66176,0.1034,0.8652600138059
0.6688000000000001,0.10450000000000001,0.8728932861211632
0.67584,0.1056,0.8805236982946052
0.68288,0.1067,0.8881517333160601
0.68992,0.10779999999999999,0.8957778663823233
0.69696,0.10889999999999998,0.9034025658583567
0.7040000000000001,0.11,0.9110262923698537
0.71104,0.11109999999999999,0.9186494995638529
0.71808,0.1122,0.9262726342349191
0.72512,0.11329999999999998,0.9338961361227067
0.73216,0.1144,0.9415204382864408
0.7392000000000001,0.1155,0.9491459673064039
0.74624,0.1166,0.9567731430588708
0.7532800000000001,0.1177,0.9644023791802433
0.76032,0.11879999999999999,0.9720340830392574
0.76736,0.1199,0.9796686557875466
0.7744,0.121,0.9873064926254279
0.78144,0.1221,0.9949479828188774
0.7884800000000001,0.12320000000000002,1.0025935098244663
0.79552,0.12430000000000001,1.0102434512725456
0.80256,0.12539999999999998,1.0178981794370987
0.8096,0.12649999999999997,1.0255580608417825
0.81664,0.1276,1.033223456853453
0.8236800000000001,0.1287,1.040894723275412
0.83072,0.1298,1.04857221104089
0.8377600000000001,0.1309,1.056256265667541
0.8448,0.13199999999999998,1.0639472277990867
0.85184,0.1331,1.0716454332902727
0.85888,0.13419999999999999,1.0793512128768479
0.86592,0.1353,1.0870648927362296
0.8729600000000001,0.13640000000000002,1.0947867944726122
0.88,0.1375,1.1025172349276278
0.88704,0.1386,1.1102565266447764
0.89408,0.1397,1.1180049775751524
0.90112,0.14079999999999998,1.1257628915055748
0.9081600000000001,0.1419,1.1335305678233627
0.9152,0.143,1.141308302065882
0.9222400000000001,0.1441,1.149096385387928
0.92928,0.1452,1.1568951050017822
0.93632,0.14629999999999999,1.1647047442781189
0.9433600000000001,0.1474,1.1725255825492578
0.9504,0.1485,1.180357895456907
0.9574400000000001,0.1496,1.1882019550457037
0.96448,0.1507,1.1960580294458811
0.97152,0.1518,1.2039263834301743
0.97856,0.15289999999999998,1.2118072780742435
0.9856,0.154,1.2197009711003142
0.9926400000000001,0.15510000000000002,1.2276077167581736
0.99968,0.1562,1.235527766110294
1.00672,0.1573,1.2434613666589052
1.01376,0.15839999999999999,1.2514087630863204
1.0208,0.15949999999999998,1.259370196577499
1.02784,0.1606,1.2673459053258604
1.03488,0.16169999999999998,1.2753361246549588
1.04192,0.16279999999999997,1.2833410865936892
1.0489600000000001,0.16390000000000002,1.291361020526917
1.056,0.165,1.2993961528008495
1.06304,0.1661,1.307446707049946
1.0700800000000001,0.16720000000000002,1.3155129038598383
1.07712,0.1683,1.3235949615431806
1.08416,0.1694,1.3316930953096564
1.0912,0.17049999999999998,1.3398075179674778
1.09824,0.1716,1.3479384397685417
1.10528,0.1727,1.3560860683367784
1.11232,0.17379999999999998,1.3642506088044442
1.1193600000000001,0.1749,1.3724322639183397
1.1264,0.17600000000000002,1.3806312340930464
1.13344,0.17709999999999998,1.3888477171421123
1.14048,0.1782,1.3970819089341941
1.14752,0.17930000000000001,1.4053340027114258
1.15456,0.1804,1.4136041897222875
1.1616,0.18149999999999997,1.42189265894328
1.1686400000000001,0.18259999999999998,1.4301995972145785
1.17568,0.1837,1.4385251892369357
1.18272,0.18479999999999996,1.446869617809551
1.1897600000000002,0.1859,1.4552330633158472
1.1968,0.187,1.463615704548748
1.20384,0.1881,1.4720177180368639
1.21088,0.18919999999999998,1.4804392787111669
1.2179200000000001,0.19030000000000002,1.4888805593050325
1.22496,0.1914,1.4973417307120198
1.232,0.1925,1.5058229622211798
1.2390400000000001,0.1936,1.5143244211504407
1.24608,0.1947,1.5228462730892116
1.25312,0.19579999999999997,1.5313886819850802
1.26016,0.1969,1.539951809932992
1.2672,0.198,1.5485358174796997
1.27424,0.19909999999999997,1.5571408634517807
1.28128,0.2002,1.5657671051550857
1.2883200000000001,0.2013,1.5744146982598026
1.29536,0.2024,1.5830837968624125
1.3024,0.20349999999999996,1.5917745536585564
1.30944,0.20459999999999998,1.6004871195973425
1.31648,0.2057,1.60922164437148
1.32352,0.2068,1.6179782762153863
1.33056,0.20789999999999997,1.626757161907692
1.3376000000000001,0.20900000000000002,1.635558446771452
1.34464,0.21009999999999998,1.6443822747845687
1.35168,0.2112,1.6532287886761694
1.3587200000000001,0.21230000000000002,1.6620981297500699
1.36576,0.2134,1.6709904379945406
1.3728,0.2145,1.6799058522174828
1.37984,0.21559999999999999,1.6888445099998823
1.3868800000000001,0.2167,1.6978065475082016
1.39392,0.21779999999999997,1.7067920998822506
1.40096,0.21889999999999998,1.7158013009238358
1.4080000000000001,0.22,1.724834283454908
1.41504,0.22110000000000002,1.7338911789751905
1.42208,0.22219999999999998,1.742972117974804
1.42912,0.2233,1.7520772297576857
1.43616,0.2244,1.7612066425450557
1.4432,0.2255,1.7703604836598
1.45024,0.22659999999999997,1.7795388791651974
1.4572800000000001,0.2277,1.788741954133615
1.46432,0.2288,1.7979698327301732
1.47136,0.2299,1.8072226379537164
1.4784000000000002,0.231,1.8165004920703216
1.48544,0.23209999999999997,1.8258035162521586
1.49248,0.2332,1.8351318306669828
1.49952,0.23429999999999995,1.8444855546783399
1.5065600000000001,0.2354,1.8538648065739025
1.5136,0.2365,1.8632697040810322
1.52064,0.23759999999999998,1.8727003636520383
1.5276800000000001,0.2387,1.882156901108215
1.53472,0.2398,1.8916394314257932
1.54176,0.24089999999999998,1.9011480687235716
1.5488,0.242,1.9106829262327711
1.5558400000000001,0.2431,1.9202441164847244
1.56288,0.2442,1.9298317511659044
1.56992,0.24529999999999996,1.9394459411619636
1.5769600000000001,0.24640000000000004,1.9490867967455683
1.584,0.2475,1.9587544273811013
1.59104,0.24860000000000002,1.96844894157792
1.5980800000000002,0.2497,1.978170447515268
1.60512,0.25079999999999997,1.9879190524430668
1.61216,0.2519,1.997694862817467
1.6192,0.25299999999999995,2.007497984780101
1.6262400000000001,0.2541,2.0173285233916136
1.63328,0.2552,2.027186583241454
1.64032,0.2563,2.037072268520224
1.6473600000000002,0.2574,2.04698568229415
1.6544,0.2585,2.056926927360103
1.66144,0.2596,2.0668961058847275
1.66848,0.2607,2.0768933192693364
1.6755200000000001,0.2618,2.086918668508567
1.68256,0.2629,2.0969722539774893
1.6896,0.26399999999999996,2.1070541754036394
1.6966400000000001,0.2651,2.1171645320272408
1.70368,0.2662,2.12730342247056
1.71072,0.2673,2.1374709450932556
1.71776,0.26839999999999997,2.1476671974664105
1.7248,0.26949999999999996,2.1578922766200983
1.73184,0.2706,2.16814627929998
1.73888,0.27169999999999994,2.1784293016138654
1.7459200000000001,0.27280000000000004,2.1887414392470226
1.75296,0.2739,2.1990827873398544
1.76,0.275,2.2094534406395945
1.7670400000000002,0.2761,2.2198534934301253
1.77408,0.2772,2.2302830395703213
1.78112,0.2783,2.240742172356066
1.78816,0.2794,2.251230984930174
1.7952000000000001,0.2805,2.261749569693189
1.80224,0.28159999999999996,2.27229801884188
1.80928,0.2827,2.2828764241368766
1.8163200000000002,0.2838,2.2934848769200946
1.82336,0.2849,2.3041234681468947
1.8304,0.286,2.314792288379176
1.83744,0.28709999999999997,2.325491427841392
1.8444800000000001,0.2882,2.3362209764130974
1.85152,0.2893,2.3469810236621758
1.85856,0.2904,2.35777165867056
1.8656000000000001,0.29150000000000004,2.368592970266294
1.87264,0.29259999999999997,2.379445046924189
1.87968,0.2937,2.390327976839514
1.8867200000000002,0.2948,2.401241847904249
1.89376,0.2959,2.4121867476127186
1.9008,0.297,2.4231627632046204
1.90784,0.2981,2.434169981643507
1.9148800000000001,0.2992,2.4452084896710664
1.92192,0.30029999999999996,2.4562783735037983
1.92896,0.3014,2.4673797193852307
1.9360000000000002,0.3025,2.478512613089905
1.94304,0.3036,2.4896771402051425
1.95008,0.30469999999999997,2.5008733860587307
1.95712,0.30579999999999996,2.5121014356505436
1.9641600000000001,0.3069,2.5233613739606855
1.9712,0.308,2.5346532854423978
1.97824,0.3091,2.5459772545314023
1.9852800000000002,0.31020000000000003,2.5573333653726835
1.99232,0.31129999999999997,2.568721701873129
1.99936,0.3124,2.580142347639961
2.0064,0.3135,2.5915953863228953
2.01344,0.3146,2.6030809011252596
2.02048,0.3157,2.6145989752254213
2.02752,0.31679999999999997,2.626149691423236
2.03456,0.31789999999999996,2.6377331325569076
2.0416,0.31899999999999995,2.6493493811230007
2.0486400000000002,0.32010000000000005,2.660998519533385
2.05568,0.3212,2.672680629893102
2.06272,0.32230000000000003,2.6843957943814725
2.06976,0.32339999999999997,2.6961440948072313
2.0768,0.3245,2.707925612923485
2.08384,0.32559999999999995,2.7197404303015844
2.0908800000000003,0.32670000000000005,2.731588628380044
2.0979200000000002,0.32780000000000004,2.7434702884281266
2.10496,0.3289,2.7553854916698346
2.112,0.33,2.767334319153321
2.11904,0.3311,2.7793168517016826
2.12608,0.3322,2.791333170256777
2.13312,0.3333,2.8033833552954324
2.1401600000000003,0.33440000000000003,2.815467487621469
2.1472,0.3355,2.8275856475192143
2.15424,0.3366,2.839737915347815
2.16128,0.3377,2.851924371485868
2.16832,0.3388,2.8641450960775354
2.17536,0.3399,2.8764001691708247
2.1824,0.34099999999999997,2.888689670749448
2.1894400000000003,0.3421,2.9010136807470124
2.19648,0.3432,2.9133722790553755
2.20352,0.3443,2.9257655453592144
2.21056,0.3454,2.9381935593641675
2.2176,0.3465,2.950656400754844
2.22464,0.34759999999999996,2.9631541491165536
2.23168,0.34869999999999995,2.975686883868758
2.2387200000000003,0.3498,2.9882546846127926
2.24576,0.3509,3.0008576306112174
2.2528,0.35200000000000004,3.0134958013660866
2.25984,0.35309999999999997,3.0261692761547567
2.26688,0.35419999999999996,3.038878134289924
2.27392,0.35529999999999995,3.051622454952783
2.28096,0.3564,3.0644023174653854
2.2880000000000003,0.3575,3.077217800881849
2.29504,0.35860000000000003,3.090068984551777
2.30208,0.3597,3.1029559474839745
2.30912,0.3608,3.1158787688844733
2.31616,0.36189999999999994,3.1288375278455507
2.3232,0.36299999999999993,3.141832303464789
2.33024,0.3641,3.15486317485733
2.3372800000000002,0.36519999999999997,3.167930221155375
2.34432,0.3663,3.1810335213748644
2.35136,0.3674,3.194173154646815
2.3584,0.3685,3.207349199968756
2.36544,0.36959999999999993,3.220561736609395
2.37248,0.3707,3.233810843627073
2.3795200000000003,0.3718,3.247096600062767
2.3865600000000002,0.37290000000000006,3.2604190851548744
2.3936,0.374,3.27377837800096
2.40064,0.3751,3.2871745578324028
2.40768,0.3762,3.3006077037896646
2.41472,0.3773,3.3140778952049104
2.42176,0.37839999999999996,3.3275852112569693
2.4288000000000003,0.3795,3.3411297313006796
2.4358400000000002,0.38060000000000005,3.3547115346027927
2.44288,0.3817,3.3683307005724057
2.44992,0.3828,3.3819873086150625
2.45696,0.38389999999999996,3.3956814381720988
2.464,0.385,3.4094131686976215
2.47104,0.38609999999999994,3.4231825798268836
2.4780800000000003,0.3872,3.436989751059319
2.48512,0.38830000000000003,3.4508347621195683
2.49216,0.3894,3.4647176925878247
2.4992,0.39049999999999996,3.4786386223085435
2.50624,0.39159999999999995,3.4925976311258116
2.51328,0.3927,3.506594798810891
2.52032,0.3938,3.5206302053171608
2.5273600000000003,0.3949,3.534703930727167
2.5344,0.396,3.548816055068003
2.54144,0.3971,3.562966658391611
2.54848,0.39819999999999994,3.577155821111306
2.55552,0.39929999999999993,3.591383623269683
2.56256,0.4004,3.605650145417477
2.5696,0.40149999999999997,3.6199554678448203
2.5766400000000003,0.4026,3.6342996711128457
2.58368,0.4037,3.6486828358637626
2.59072,0.4048,3.6631050427872665
2.59776,0.40590000000000004,3.677566372578835
2.6048,0.4069999999999999,3.6920669061005227
2.61184,0.40809999999999996,3.706606724355282
2.61888,0.40919999999999995,3.7211859082201197
2.6259200000000003,0.41030000000000005,3.7358045389320154
2.63296,0.4114,3.750462697714797
2.64,0.4125,3.7651604658451667
2.64704,0.4136,3.7798979247094966
2.65408,0.4147,3.7946751557764418
2.66112,0.41579999999999995,3.8094922408105942
2.6681600000000003,0.41690000000000005,3.8243492613939822
2.6752000000000002,0.41800000000000004,3.839246299271405
2.68224,0.4191,3.8541834364267933
2.68928,0.42019999999999996,3.869160754817824
2.69632,0.4213,3.884178336751416
2.70336,0.4224,3.899236264238586
2.7104,0.42349999999999993,3.9143346196791207
2.7174400000000003,0.42460000000000003,3.9294734855324145
2.7244800000000002,0.4257,3.9446529443817426
2.73152,0.4268,3.959873078974681
2.73856,0.42789999999999995,3.975133971856733
2.7456,0.429,3.9904357062986606
2.75264,0.4301,4.005778364988679
2.75968,0.43119999999999997,4.021162031208504
2.7667200000000003,0.4323,4.03658678824255
2.7737600000000002,0.4334,4.05205271951368
2.7808,0.4345,4.067559908317568
2.78784,0.43559999999999993,4.0831084384497585
2.79488,0.4367,4.098698393631435
2.80192,0.43779999999999997,4.1143298577205645
2.80896,0.43889999999999996,4.130002914729993
2.8160000000000003,0.44,4.145717648757672
2.82304,0.4411,4.161474144084541
2.83008,0.44220000000000004,4.17727248503384
2.83712,0.4433,4.193112756232075
2.84416,0.44439999999999996,4.208995042176086
2.8512,0.44549999999999995,4.224919427697673
2.85824,0.4466,4.240885997738187
2.8652800000000003,0.4477,4.256894837299338
2.87232,0.4488,4.272946031559888
2.87936,0.4499,4.289039665746258
2.8864,0.451,4.3051758254167956
2.89344,0.45209999999999995,4.321354596050369
2.90048,0.45319999999999994,4.337576063344049
2.90752,0.4543,4.353840313211374
2.9145600000000003,0.4554,4.370147431553112
2.9216,0.45649999999999996,4.3864975046247086
2.92864,0.4576,4.402890618491325
2.93568,0.4587,4.419326859640165
2.94272,0.4598,4.435806314706584
2.94976,0.4608999999999999,4.45232907024213
2.9568000000000003,0.462,4.468895212995613
2.9638400000000003,0.4631,4.485504830105373
2.97088,0.46419999999999995,4.502158008516439
2.97792,0.4653,4.518854835544307
2.98496,0.4664,4.535595398548574
2.992,0.46749999999999997,4.5523797850275
2.99904,0.4685999999999999,4.569208082682025
3.0060800000000003,0.4697,4.586080379277899
3.0131200000000002,0.4708,4.602996762836721
3.02016,0.47190000000000004,4.619957321416391
3.0272,0.473,4.636962143228
3.03424,0.47409999999999997,4.654011316746524
3.04128,0.47519999999999996,4.6711049303339
3.04832,0.4763,4.6882430728266264
3.0553600000000003,0.4774,4.705425832995789
3.0624000000000002,0.4785,4.722653299754765
3.06944,0.4796,4.739925562328798
3.07648,0.48069999999999996,4.757242709780717
3.08352,0.48179999999999995,4.774604831640196
3.09056,0.48289999999999994,4.792012017432201
3.0976,0.484,4.809464356900877
3.1046400000000003,0.4851,4.826961939813183
3.1116800000000002,0.4862,4.844504856167272
3.11872,0.4873,4.862093196142692
3.12576,0.4884,4.879727049891206
3.1328,0.48949999999999994,4.897406507991479
3.13984,0.4905999999999999,4.9151316609310305
3.14688,0.49169999999999997,4.932902599372895
3.1539200000000003,0.49280000000000007,4.950719414267928
3.16096,0.4939,4.968582196598159
3.168,0.495,4.986491037550628
3.17504,0.4961,5.004446028357622
3.18208,0.49720000000000003,5.022447260491568
3.18912,0.49829999999999997,5.040494825494149
3.1961600000000003,0.4994,5.058588815141905
3.2032000000000003,0.5005000000000001,5.076729321362659
3.21024,0.5015999999999999,5.094916436166298
3.21728,0.5026999999999999,5.113150251644233
3.22432,0.5038,5.131430860229036
3.23136,0.5049,5.149758354280471
3.2384,0.5059999999999999,5.168132826452081
3.2454400000000003,0.5071,5.186554369503702
3.2524800000000003,0.5082,5.205023076253027
3.25952,0.5093000000000001,5.223539039866514
3.26656,0.5104,5.2421023533718785
3.2736,0.5115,5.2607131102576945
3.28064,0.5126,5.279371403902848
3.28768,0.5137,5.298077327887069
3.2947200000000003,0.5148,5.316830976067759
3.3017600000000003,0.5159,5.3356324422287775
3.3088,0.517,5.354481820484767
3.31584,0.5181,5.37337920495564
3.32288,0.5192,5.392324689955682
3.32992,0.5203,5.411318370004551
3.33696,0.5214,5.430360339655502
3.3440000000000003,0.5225,5.44945069368629
3.3510400000000002,0.5236,5.468589526939387
3.35808,0.5247,5.487776934442412
3.36512,0.5258,5.507013011383449
3.37216,0.5268999999999999,5.526297852974407
3.3792,0.5279999999999999,5.54563155472348
3.38624,0.5291,5.565014212137594
3.3932800000000003,0.5302,5.584445921015458
3.4003200000000002,0.5313,5.603926777127192
3.40736,0.5324,5.623456876412227
3.4144,0.5335,5.6430363150738705
3.42144,0.5346,5.66266518937193
3.42848,0.5357,5.682343595505344
3.43552,0.5367999999999999,5.702071630175687
3.4425600000000003,0.5379,5.7218493899787
3.4496,0.5389999999999999,5.741676971714852
3.45664,0.5401,5.761554472201477
3.46368,0.5412,5.781481988590762
3.47072,0.5423,5.801459617986877
3.47776,0.5433999999999999,5.821487457706788
3.4848000000000003,0.5445,5.841565605195232
3.4918400000000003,0.5456000000000001,5.861694158058781
3.49888,0.5467,5.88187321390062
3.50592,0.5478,5.902102870547452
3.51296,0.5488999999999999,5.922383226045212
3.52,0.55,5.942714378373385
3.52704,0.5510999999999999,5.963096425730705
3.5340800000000003,0.5522,5.983529466402061
3.5411200000000003,0.5533,6.004013598972393
3.54816,0.5544,6.024548921939977
3.5552,0.5555,6.045135533976108
3.56224,0.5566,6.065773533854609
3.56928,0.5577,6.086463020608289
3.57632,0.5588,6.107204093217512
3.5833600000000003,0.5599,6.127996850927889
3.5904000000000003,0.561,6.148841393001692
3.59744,0.5621,6.169737818950627
3.60448,0.5631999999999999,6.190686228079098
3.61152,0.5642999999999999,6.2116867202217305
3.61856,0.5654,6.232739395178832
3.6256,0.5665,6.25384435265924
3.6326400000000003,0.5676,6.275001692841215
3.6396800000000002,0.5687,6.29621151569696
3.64672,0.5698,6.317473921614666
3.65376,0.5709,6.338789010784535
3.6608,0.572,6.360156883710559
3.66784,0.5730999999999999,6.381577641019546
3.67488,0.5741999999999999,6.403051383324877
3.6819200000000003,0.5753,6.424578211397548
3.6889600000000002,0.5764,6.446158226145867
3.696,0.5775,6.467791528622883
3.70304,0.5786,6.489478219907202
3.71008,0.5797,6.511218401212155
3.71712,0.5808,6.533012173814957
3.72416,0.5819,6.554859639171562
3.7312000000000003,0.5830000000000001,6.5767608988939985
3.7382400000000002,0.5841,6.598716054526558
3.74528,0.5851999999999999,6.620725207844656
3.75232,0.5862999999999999,6.642788460630761
3.75936,0.5874,6.664905914905926
3.7664,0.5884999999999999,6.687077672641193
3.7734400000000003,0.5896,6.709303836108323
3.7804800000000003,0.5907,6.731584507420351
3.78752,0.5918,6.753919788913046
3.79456,0.5929,6.776309782979315
3.8016,0.594,6.7987545922733235
3.80864,0.5951,6.821254319395361
3.81568,0.5962,6.84380906703699
3.8227200000000003,0.5973,6.866418938009526
3.8297600000000003,0.5984,6.889084035159976
3.8368,0.5995,6.9118044616064
3.84384,0.6005999999999999,6.9345803203988625
3.85088,0.6017,6.957411714619351
3.85792,0.6028,6.980298747646691
3.86496,0.6039,7.003241522697215
3.8720000000000003,0.605,7.02624014341634
3.8790400000000003,0.6061,7.049294713214405
3.88608,0.6072,7.072405335678745
3.89312,0.6083000000000001,7.095572114586009
3.90016,0.6093999999999999,7.118795153734299
3.9072,0.6104999999999999,7.14207455681178
3.91424,0.6115999999999999,7.165410427957559
3.9212800000000003,0.6127,7.188802871197871
3.9283200000000003,0.6138,7.212251990461049
3.93536,0.6149,7.235757890141467
3.9424,0.616,7.259320674407612
3.94944,0.6171,7.282940447648981
3.95648,0.6182,7.306617314198346
3.96352,0.6193,7.330351378744153
3.9705600000000003,0.6204000000000001,7.354142745691522
3.9776000000000002,0.6214999999999999,7.377991519722119
3.98464,0.6225999999999999,7.401897805580124
3.99168,0.6237,7.425861708105982
3.99872,0.6248,7.449883332102601
4.00576,0.6259,7.473962782558699
4.0128,0.627,7.498100164471874
4.01984,0.6281,7.522295582849634
4.02688,0.6292,7.546549142905423
4.03392,0.6303,7.570860949868674
4.04096,0.6314,7.595231108973968
4.048,0.6325,7.6196597256342375
4.05504,0.6335999999999999,7.644146905187766
4.06208,0.6346999999999999,7.668692753122144
4.06912,0.6357999999999999,7.693297375037226
4.07616,0.6368999999999999,7.717960876496875
4.0832,0.6379999999999999,7.742683363076318
4.0902400000000005,0.6391,7.767464940631261
4.0972800000000005,0.6402000000000001,7.7923057148437485
4.10432,0.6413,7.81720579164294
4.11136,0.6424,7.842165276906075
4.1184,0.6435,7.867184276481391
4.12544,0.6446000000000001,7.8922628965164545
4.13248,0.6456999999999999,7.917401243049561
4.13952,0.6467999999999999,7.942599422168044
4.14656,0.6478999999999999,7.967857540030716
4.1536,0.649,7.993175702933644
4.16064,0.6500999999999999,8.01855401708006
4.16768,0.6511999999999999,8.043992588920712
4.17472,0.6522999999999999,8.06949152461082
4.181760000000001,0.6534000000000001,8.09505093083051
4.1888000000000005,0.6545,8.120670913873834
4.1958400000000005,0.6556000000000001,8.146351580412123
4.20288,0.6567000000000001,8.172093036891019
4.20992,0.6578,8.197895390040955
4.21696,0.6588999999999999,8.223758746458499
4.224,0.66,8.249683212844063
4.23104,0.6611,8.275668895992197
4.23808,0.6622,8.301715902657273
4.24512,0.6632999999999999,8.32782433968678
4.25216,0.6644,8.353994313978587
4.2592,0.6655,8.38022593246172
4.26624,0.6666,8.406519302050615
4.27328,0.6676999999999998,8.432874529730885
4.280320000000001,0.6688000000000001,8.4592917225669
4.2873600000000005,0.6699,8.48577098765211
4.2944,0.671,8.512312432035714
4.30144,0.6721,8.538916162889345
4.30848,0.6732,8.56558228734608
4.31552,0.6743,8.592310912698881
4.32256,0.6754,8.619102146116148
4.3296,0.6765,8.645956094848252
4.33664,0.6776,8.672872866339656
4.34368,0.6787,8.699852567819786
4.35072,0.6798,8.726895306609588
4.35776,0.6809,8.754001190143569
4.3648,0.6819999999999999,8.781170325887999
4.37184,0.6830999999999999,8.808402821281636
4.3788800000000005,0.6842,8.835698783761227
4.3859200000000005,0.6853,8.863058320793098
4.39296,0.6864,8.890481539995507
4.4,0.6875,8.917968548832729
4.40704,0.6886,8.94551945497979
4.41408,0.6897,8.973134365965034
4.42112,0.6908,9.000813389355267
4.42816,0.6919,9.028556632901825
4.4352,0.693,9.05636420418764
4.44224,0.6940999999999999,9.08423621087133
4.44928,0.6951999999999999,9.112172760748775
4.45632,0.6962999999999999,9.14017396140154
4.46336,0.6973999999999999,9.168239920700735
4.470400000000001,0.6985000000000001,9.196370746262929
4.4774400000000005,0.6996,9.224566545982135
4.4844800000000005,0.7007,9.25282742754783
4.49152,0.7018,9.281153498794971
4.49856,0.7029000000000001,9.309544867511969
4.5056,0.7040000000000001,9.338001641470463
4.51264,0.7051000000000001,9.366523928582657
4.51968,0.7061999999999999,9.395111836703464
4.52672,0.7072999999999999,9.423765473650485
4.53376,0.7083999999999999,9.452484947268193
4.5408,0.7094999999999999,9.481270365453305
4.54784,0.7105999999999999,9.510121836068592
4.55488,0.7117,9.539039467023716
4.56192,0.7128,9.568023366236627
4.568960000000001,0.7139,9.597073641692274
4.5760000000000005,0.715,9.62619040105161
4.5830400000000004,0.7161,9.655373752435318
4.59008,0.7172000000000001,9.684623803760331
4.59712,0.7183,9.713940662857935
4.60416,0.7194,9.743324437729509
4.6112,0.7205,9.772775236186527
4.61824,0.7216,9.802293166395307
4.62528,0.7226999999999999,9.831878336043824
4.63232,0.7237999999999999,9.861530853212548
4.63936,0.7248999999999999,9.891250825776206
4.6464,0.7259999999999999,9.921038361662571
4.65344,0.7271,9.950893568859296
4.66048,0.7282,9.980816555282114
4.667520000000001,0.7293000000000001,10.010807428792495
4.6745600000000005,0.7303999999999999,10.040866297439953
4.6816,0.7314999999999999,10.070993269006246
4.68864,0.7326,10.101188451433872
4.69568,0.7337,10.131451952670346
4.70272,0.7348,10.161783880598298
4.70976,0.7359,10.192184343167835
4.7168,0.737,10.222653448206103
4.72384,0.7381,10.253191303679875
4.73088,0.7391999999999999,10.283798017320422
4.73792,0.7402999999999998,10.314473697121212
4.74496,0.7414,10.345218450989469
4.752,0.7424999999999999,10.37603238654881
4.759040000000001,0.7436,10.406915611741578
4.7660800000000005,0.7447,10.437868234499868
4.7731200000000005,0.7458000000000001,10.468890362526741
4.78016,0.7468999999999999,10.49998210362842
4.7872,0.748,10.531143565627783
4.79424,0.7491,10.562374856287036
4.80128,0.7502,10.593676083375753
4.80832,0.7513,10.625047354570508
4.81536,0.7524,10.656488777729534
4.8224,0.7535,10.688000460415887
4.82944,0.7546,10.71958251046312
4.83648,0.7556999999999998,10.751235035457224
4.84352,0.7567999999999999,10.782958143077497
4.85056,0.7578999999999999,10.814751941103347
4.857600000000001,0.759,10.846616536957887
4.8646400000000005,0.7601000000000001,10.87855203831582
4.8716800000000005,0.7612000000000001,10.910558552826366
4.87872,0.7623000000000001,10.942636188101048
4.88576,0.7634,10.974785051487807
4.8928,0.7645,11.007005250712673
4.89984,0.7656,11.039296893123803
4.90688,0.7666999999999999,11.071660086354584
4.91392,0.7677999999999999,11.104094937792784
4.92096,0.7689,11.136601554825297
4.928,0.77,11.169180044975139
4.93504,0.7711,11.201830515543609
4.94208,0.7721999999999999,11.23455307397484
4.94912,0.7732999999999999,11.267347827487876
4.956160000000001,0.7744,11.300214883527648
4.9632000000000005,0.7755000000000001,11.333154349342713
4.97024,0.7766000000000001,11.366166332112675
4.97728,0.7777000000000001,11.39925093922608
4.98432,0.7788,11.432408277758523
4.99136,0.7798999999999999,11.46563845489525
4.9984,0.7809999999999999,11.49894157792529
5.00544,0.7820999999999999,11.532317753863648
5.01248,0.7831999999999999,11.565767089751242
5.01952,0.7843,11.599289692709535
5.02656,0.7854,11.632885669823606
5.0336,0.7865,11.666555128109144
5.04064,0.7876,11.700298174386011
5.047680000000001,0.7887,11.734114915709062
5.0547200000000005,0.7898,11.768005458988036
5.0617600000000005,0.7909,11.801969911076105
5.0688,0.792,11.836008378807467
5.07584,0.7931,11.870120969032012
5.08288,0.7942,11.904307788496505
5.08992,0.7953,11.938568943936989
5.09696,0.7963999999999999,11.972904542105365
5.104,0.7974999999999999,12.007314689576708
5.11104,0.7985999999999999,12.041799493124405
5.11808,0.7997,12.076359059231288
5.12512,0.8008,12.110993494541507
5.13216,0.8019,12.145702905496027
5.1392,0.8029999999999999,12.180487398714918
5.146240000000001,0.8040999999999999,12.215347080593423
5.1532800000000005,0.8052,12.25028205749893
5.1603200000000005,0.8063,12.28529243593635
5.16736,0.8074,12.32037832218218
5.1744,0.8085,12.355539822491188
5.18144,0.8096,12.390777043176632
5.18848,0.8107,12.42609009044442
5.19552,0.8118000000000001,12.46147907048173
5.20256,0.8128999999999998,12.496944089471139
5.2096,0.8139999999999998,12.532485253526332
5.21664,0.8150999999999999,12.568102668694578
5.22368,0.8161999999999999,12.60379644093308
5.23072,0.8172999999999999,12.639566676317658
5.23776,0.8183999999999999,12.675413480706077
5.244800000000001,0.8195000000000001,12.711336960104893
5.2518400000000005,0.8206000000000001,12.747337220293456
5.25888,0.8217,12.783414367058448
5.26592,0.8228,12.819568506279277
5.27296,0.8239,12.855799743550687
5.28,0.825,12.892108184661305
5.28704,0.8261,12.928493935147918
5.29408,0.8272,12.964957100715615
5.30112,0.8283,13.001497786906853
5.30816,0.8294,13.03811609910851
5.3152,0.8304999999999999,13.074812142824534
5.32224,0.8315999999999999,13.111586023569528
5.32928,0.8326999999999999,13.148437846658767
5.336320000000001,0.8338000000000001,13.18536771735674
5.3433600000000006,0.8349000000000001,13.222375740965957
5.3504000000000005,0.8360000000000001,13.259462022829558
5.35744,0.8371000000000001,13.29662666793409
5.36448,0.8382,13.333869781466893
5.37152,0.8392999999999999,13.371191468634295
5.37856,0.8403999999999999,13.408591834389691
5.3856,0.8414999999999999,13.446070983694641
5.39264,0.8426,13.483629021523551
5.39968,0.8437,13.521266052844654
5.40672,0.8448,13.558982182436777
5.41376,0.8459,13.596777514990222
5.4208,0.8469999999999999,13.634652155423892
5.42784,0.8480999999999999,13.67260620829069
5.434880000000001,0.8492000000000001,13.710639778387419
5.4419200000000005,0.8503000000000001,13.748752970212823
5.4489600000000005,0.8514,13.786945888305075
5.456,0.8525,13.825218637155373
5.46304,0.8536,13.863571321275192
5.47008,0.8546999999999999,13.902004045082895
5.47712,0.8557999999999999,13.940516912733495
5.48416,0.8569,13.979110028737308
5.4912,0.858,14.017783497214012
5.49824,0.8591,14.056537422309223
5.50528,0.8602,14.095371908206136
5.51232,0.8613,14.134287059129587
5.51936,0.8623999999999999,14.173282978834195
5.5264,0.8634999999999998,14.212359771476029
5.533440000000001,0.8646,14.251517540985766
5.5404800000000005,0.8657,14.290756391092795
5.5475200000000005,0.8668,14.330076425746716
5.55456,0.8679,14.369477748663163
5.5616,0.869,14.408960463554923
5.56864,0.8701000000000001,14.448524674065306
5.57568,0.8711999999999999,14.48817048380914
5.58272,0.8723,14.527897996307432
5.58976,0.8734,14.56770731502713
5.5968,0.8744999999999999,14.607598543476996
5.60384,0.8755999999999999,14.647571784946836
5.61088,0.8766999999999999,14.687627142855234
5.61792,0.8777999999999999,14.727764720317264
5.624960000000001,0.8789,14.767984620723698
5.632000000000001,0.88,14.808286947163737
5.6390400000000005,0.8811,14.848671802683441
5.64608,0.8822,14.8891392904297
5.65312,0.8833,14.929689513322424
5.66016,0.8844000000000001,14.97032257430657
5.6672,0.8855000000000001,15.011038576231725
5.67424,0.8866,15.051837621920964
5.68128,0.8876999999999999,15.092719814210227
5.68832,0.8887999999999999,15.133685255699687
5.69536,0.8898999999999999,15.174734049104053
5.7024,0.8909999999999999,15.215866297001778
5.70944,0.8920999999999999,15.257082101856517
5.71648,0.8932,15.298381566238252
5.723520000000001,0.8943000000000001,15.33976479253467
5.7305600000000005,0.8954,15.381231882992541
5.7376000000000005,0.8965,15.422782940087627
5.74464,0.8976,15.464418066009728
5.75168,0.8986999999999999,15.506137362802487
5.75872,0.8998,15.547940932752654
5.76576,0.9009,15.58982887784975
5.7728,0.902,15.63180130005896
5.77984,0.9031,15.67385830146129
5.78688,0.9041999999999999,15.715999983826377
5.79392,0.9052999999999999,15.75822644902772
5.80096,0.9063999999999999,15.800537798841107
5.808,0.9074999999999999,15.842934134877192
5.81504,0.9086,15.88541555892072
5.822080000000001,0.9097000000000001,15.927982172556156
5.8291200000000005,0.9108,15.970634077204778
5.8361600000000005,0.9118999999999999,16.01337137440407
5.8432,0.9129999999999999,16.056194165525444
5.85024,0.9140999999999999,16.099102551956975
5.85728,0.9152,16.142096634985386
5.86432,0.9163,16.18517651584157
5.87136,0.9174,16.228342295699296
5.8784,0.9185,16.27159407560715
5.88544,0.9196,16.314931956685093
5.89248,0.9206999999999999,16.358356039856137
5.89952,0.9217999999999998,16.401866426067805
5.90656,0.9228999999999998,16.44546321616639
5.913600000000001,0.924,16.48914651098684
5.920640000000001,0.9251,16.532916411240087
5.9276800000000005,0.9262,16.5767730176565
5.93472,0.9273000000000001,16.620716430800414
5.94176,0.9283999999999999,16.664746751229565
5.9488,0.9294999999999999,16.708864079497786
5.95584,0.9306,16.753068515994034
5.96288,0.9317,16.797360161105257
5.96992,0.9328,16.84173911509877
5.97696,0.9339,16.886205478235688
5.984,0.9349999999999999,16.930759350745443
5.99104,0.9361,16.975400832757337
5.99808,0.9371999999999998,17.020130024250307
6.00512,0.9382999999999998,17.064947025333158
6.012160000000001,0.9394,17.10985193584377
6.0192000000000005,0.9405,17.154844855677215
6.0262400000000005,0.9416,17.1999258846948
6.03328,0.9427000000000001,17.245095122691925
6.04032,0.9438000000000001,17.290352669193204
6.04736,0.9449,17.335698623900804
6.0544,0.946,17.38113308640044
6.06144,0.9470999999999999,17.42665615620793
6.06848,0.9481999999999999,17.472267932767064
6.07552,0.9492999999999999,17.517968515369436
6.08256,0.9503999999999999,17.563758003380602
6.0896,0.9515,17.6096364960264
6.09664,0.9526,17.65560409253453
6.103680000000001,0.9537,17.70166089198476
6.110720000000001,0.9548,17.747806993557873
6.1177600000000005,0.9559,17.794042496048636
6.1248000000000005,0.957,17.84036749849138
6.13184,0.9581000000000001,17.886782099803455
6.13888,0.9592,17.93328639864933
6.14592,0.9603,17.979880493994152
6.15296,0.9613999999999999,18.02656448426461
6.16,0.9624999999999999,18.07333846827906
6.16704,0.9635999999999999,18.120202544484528
6.17408,0.9646999999999999,18.16715681139779
6.18112,0.9657999999999999,18.214201367416532
6.18816,0.9669,18.261336310974578
6.1952,0.968,18.308561740354136
6.202240000000001,0.9691000000000001,18.355877753753365
6.209280000000001,0.9702,18.403284449383328
6.2163200000000005,0.9712999999999999,18.450781925337687
6.2233600000000004,0.9724,18.498370279587718
6.2304,0.9735,18.546049610218194
6.23744,0.9746,18.593820015084223
6.24448,0.9757,18.64168159203222
6.25152,0.9768,18.689634438992368
6.25856,0.9778999999999999,18.737678653531713
6.2656,0.9789999999999999,18.785814333378834
6.27264,0.9800999999999999,18.83404157610188
6.27968,0.9811999999999999,18.882360479216025
6.28672,0.9823,18.93077114035159
6.29376,0.9833999999999999,18.97927365672234
6.300800000000001,0.9845,19.027868125703208
6.307840000000001,0.9856000000000001,19.076554644685697
6.3148800000000005,0.9866999999999999,19.12533331081581
6.32192,0.9878,19.174204221167866
6.32896,0.9889,19.22316747299953
6.336,0.99,19.272223163202746
6.34304,0.9911,19.321371388832944
6.35008,0.9922,19.370612246654215
6.35712,0.9933,19.419945833610903
6.36416,0.9944000000000001,19.469372246466488
6.3712,0.9954999999999998,19.51889158186101
6.37824,0.9965999999999999,19.568503936463998
6.38528,0.9976999999999999,19.618209406903055
6.392320000000001,0.9988,19.66800808962851
6.399360000000001,0.9999,19.717900081121723
6.4064000000000005,1.,19.702529714420724
6.4134400000000005,1.,19.68282056229308
6.42048,1.,19.664935048523553
6.42752,1.,19.648397025360456
6.43456,1.,19.632867186431984
6.4416,1.,19.61810345020767
6.44864,1.,19.603932830131413
6.45568,1.,19.5902314535422
6.46272,1.,19.576910367866148
6.46976,1.,19.563905455474334
6.4768,1.,19.551170267777472
6.48384,1.,19.538670933771144
6.490880000000001,1.,19.526382541283017
6.497920000000001,1.,19.514286565182278
6.5049600000000005,1.,19.502369040156704
6.5120000000000005,1.,19.490619260522205
6.51904,1.,19.47902885650771
6.52608,1.,19.46759113735602
6.53312,1.,19.456300623503715
6.54016,1.,19.445152713702726
6.5472,1.,19.43414344842933
6.55424,1.,19.42326934024483
6.56128,1.,19.412527253403884
6.56832,1.,19.401914317938168
6.57536,1.,19.391427867414745
6.5824,1.,19.381065394703207
6.589440000000001,1.,19.370824520032272
6.596480000000001,1.,19.36070296807021
6.6035200000000005,1.,19.350698550384315
6.61056,1.,19.340809153873263
6.6176,1.,19.331032730780027
6.62464,1.,19.321367292438005
6.63168,1.,19.311810903460874
6.63872,1.,19.302361678145143
6.64576,1.,19.293017776858385
6.6528,1.,19.283777403698075
6.65984,1.,19.27463880410979
6.66688,1.,19.265600263273964
6.67392,1.,19.256660104454635
6.680960000000001,1.,19.247816687487678
6.688000000000001,1.,19.23906840769865
6.6950400000000005,1.,19.23041369472688
6.7020800000000005,1.,19.221851011425763
6.70912,1.,19.213378852943066
6.71616,1.,19.204995745746967
6.7232,1.,19.19670024687029
6.73024,1.,19.188490942835802
6.73728,1.,19.180366449283042
6.74432,1.,19.172325409714304
6.75136,1.,19.16436649528508
6.7584,1.,19.156488403603692
6.76544,1.,19.14868985841102
6.77248,1.,19.1409696089039
6.779520000000001,1.,19.133326428808036
6.786560000000001,1.,19.125759116312917
6.7936000000000005,1.,19.11826649289785
6.8006400000000005,1.,19.110847403101502
6.80768,1.,19.103500714067195
6.81472,1.,19.096225314656685
6.82176,1.,19.08902011525697
6.8288,1.,19.08188404720368
6.83584,1.,19.07481606205101
6.84288,1.,19.067815131608185
6.84992,1.,19.060880246967468
6.85696,1.,19.05401041839493
6.864,1.,19.04720467462864
6.87104,1.,19.040462062831953
6.878080000000001,1.,19.033781647920005
6.885120000000001,1.,19.02716251211506
6.8921600000000005,1.,19.020603754785316
6.8992,1.,19.014104491929146
6.90624,1.,19.007663855839866
6.91328,1.,19.001280994751223
6.92032,1.,18.994955072525446
6.92736,1.,18.988685268233837
6.9344,1.,18.982470775959122
6.94144,1.,18.976310804436856
6.94848,1.,18.970204576537636
6.95552,1.,18.964151329368498
6.96256,1.,18.958150313636935
6.969600000000001,1.,18.952200793483094
6.976640000000001,1.,18.946302046284416
6.9836800000000006,1.,18.94045336221074
6.9907200000000005,1.,18.93465404408331
6.99776,1.,18.928903407081126
7.0048,1.,18.92320077852366
7.01184,1.,18.917545497503436
7.01888,1.,18.91193691482398
7.02592,1.,18.906374392627242
7.03296,1.,18.900857304197284
7.04,0.,0.