File: Module2/strain02.txt
SAMPLE PARAMETERS
Gauge length [mm]: 23.8203
Area [mm2]: 79.8048
EXPERIMENTAL PARAMETERS
Time [s]: 0.22
Number of steps: 1000
Displacement (0) or force control (1): 0
Schedule ID: 0
Point 1,0.,0.
Point 2,0.2,1.
Point 3,0.22,1.
RESULTS
Time [s],Displacement [mm],Force [N]
0.,0.,0.
0.00022,0.0011,0.015552680681233446
0.00044,0.0022,0.031040541847580507
0.00066,0.0033000000000000004,0.04646491757718131
0.00088,0.0044,0.061827114313463105
0.0011,0.0055000000000000005,0.07712841222530581
0.00132,0.006600000000000001,0.09237006552044003
0.0015400000000000001,0.007700000000000001,0.10755330383081659
0.00176,0.0088,0.122679332672603
0.00198,0.0099,0.13774933436914072
0.0022,0.011000000000000001,0.1527644688050135
0.0024200000000000003,0.0121,0.1677258741098729
0.00264,0.013200000000000002,0.1826346674455421
0.00286,0.014300000000000002,0.19749194551661897
0.0030800000000000003,0.015400000000000002,0.21229878571995642
0.0033,0.0165,0.22705624589277987
0.00352,0.0176,0.24176536604463092
0.0037400000000000003,0.0187,0.2564271679420092
0.00396,0.0198,0.27104265626066715
0.0041800000000000006,0.020900000000000002,0.2856128192471311
0.0044,0.022000000000000002,0.30013862881190967
0.00462,0.0231,0.3146210413658439
0.0048400000000000006,0.0242,0.32906099818974627
0.00506,0.0253,0.3434594261100807
0.00528,0.026400000000000003,0.35781723773258184
0.0055000000000000005,0.0275,0.37213533215716743
0.00572,0.028600000000000004,0.38641459517868937
0.00594,0.0297,0.4006558999731342
0.0061600000000000005,0.030800000000000004,0.4148601072163951
0.00638,0.031900000000000005,0.42902806576127833
0.0066,0.033,0.4431606128897992
0.0068200000000000005,0.034100000000000005,0.45725857494930816
0.00704,0.0352,0.47132276705047604
0.00726,0.0363,0.4853539942955296
0.0074800000000000005,0.0374,0.4993530513921714
0.0077,0.0385,0.513320723612851
0.00792,0.0396,0.5272577864648192
0.00814,0.0407,0.5411650066668983
0.008360000000000001,0.041800000000000004,0.5550431418815559
0.00858,0.04290000000000001,0.5688929411308253
0.0088,0.044000000000000004,0.5827151456397945
0.00902,0.0451,0.5965104883045753
0.00924,0.0462,0.6102796944455096
0.00946,0.0473,0.6240234818406342
0.009680000000000001,0.0484,0.6377425611184504
0.0099,0.0495,0.65143763599028
0.01012,0.0506,0.6651094033195802
0.01034,0.0517,0.6787585536474224
0.01056,0.05280000000000001,0.6923857710155898
0.01078,0.0539,0.7059917334023372
0.011000000000000001,0.055,0.7195771130129696
0.01122,0.0561,0.733142576252052
0.01144,0.05720000000000001,0.7466887839459969
0.01166,0.058300000000000005,0.760216392026565
0.01188,0.0594,0.7737260506154143
0.0121,0.0605,0.7872184052407826
0.012320000000000001,0.06160000000000001,0.8006940966466546
0.01254,0.0627,0.8141537607094083
0.01276,0.06380000000000001,0.8275980289174691
0.01298,0.0649,0.8410275283348723
0.0132,0.066,0.8544428817217014
0.01342,0.0671,0.8678447080123537
0.013640000000000001,0.06820000000000001,0.8812336218409015
0.01386,0.0693,0.894610234179681
0.01408,0.0704,0.9079751523406765
0.0143,0.07150000000000001,0.9213289797200934
0.01452,0.0726,0.9346723166019679
0.014740000000000001,0.07370000000000002,0.9480057597416264
0.014960000000000001,0.0748,0.9613299024488157
0.01518,0.07590000000000001,0.9746453350872923
0.0154,0.077,0.9879526446633707
0.01562,0.0781,1.0012524154951545
0.01584,0.0792,1.0145452288253565
0.01606,0.08030000000000001,1.0278316629423159
0.01628,0.0814,1.041112293651024
0.0165,0.0825,1.0543876937803462
0.016720000000000002,0.08360000000000001,1.0676584339009336
0.01694,0.0847,1.080925081809041
0.01716,0.08580000000000002,1.0941882028821062
0.01738,0.0869,1.107448360078106
0.0176,0.08800000000000001,1.12070611415257
0.01782,0.0891,1.1339620235005021
0.01804,0.0902,1.147216644137591
0.018260000000000002,0.0913,1.1604705302580403
0.01848,0.0924,1.173724233620802
0.0187,0.09350000000000001,1.186978304005904
0.01892,0.0946,1.200233289245071
0.01914,0.09570000000000001,1.2134897351414122
0.019360000000000002,0.0968,1.226748185640252
0.01958,0.0979,1.2400091825278914
0.0198,0.099,1.2532732659726489
0.02002,0.1001,1.2665409741937725
0.02024,0.1012,1.2798128437584102
0.02046,0.10229999999999999,1.293089409308761
0.02068,0.1034,1.3063712037127462
0.020900000000000002,0.10450000000000001,1.3196587584576922
0.02112,0.10560000000000001,1.3329526029533707
0.02134,0.1067,1.3462532650835675
0.02156,0.1078,1.3595612712333747
0.02178,0.1089,1.3728771460166938
0.022000000000000002,0.11,1.3862014124664355
0.02222,0.1111,1.3995345920101714
0.02244,0.1122,1.4128772047750595
0.02266,0.1133,1.426229768990859
0.02288,0.11440000000000002,1.4395928015493435
0.023100000000000002,0.1155,1.4529668177369044
0.02332,0.11660000000000001,1.4663523314207236
0.023540000000000002,0.11770000000000001,1.4797498548872512
0.02376,0.1188,1.4931598989300894
0.02398,0.1199,1.506582973031752
0.0242,0.121,1.5200195850817182
0.02442,0.1221,1.5334702413215797
0.024640000000000002,0.12320000000000002,1.546935446734704
0.02486,0.1243,1.5604157051104162
0.02508,0.1254,1.5739115182208638
0.0253,0.1265,1.5874233867336311
0.02552,0.12760000000000002,1.6009518098903472
0.025740000000000002,0.1287,1.6144972853233577
0.02596,0.1298,1.6280603093704191
0.026180000000000002,0.13090000000000002,1.6416413768437943
0.0264,0.132,1.6552409811952487
0.02662,0.1331,1.668859614201217
0.02684,0.1342,1.6824977665455698
0.02706,0.1353,1.6961559272696967
0.027280000000000002,0.13640000000000002,1.70983458385913
0.0275,0.13749999999999998,1.7235342223762704
0.02772,0.1386,1.7372553279473013
0.02794,0.1397,1.750998383293808
0.02816,0.1408,1.7647638704841662
0.028380000000000002,0.1419,1.7785522696652425
0.0286,0.14300000000000002,1.7923640597742043
0.028820000000000002,0.1441,1.8061997181404472
0.02904,0.1452,1.820059720435675
0.02926,0.1463,1.8339445412656832
0.029480000000000003,0.14740000000000003,1.8478546533767464
0.0297,0.1485,1.8617905280675777
0.029920000000000002,0.1496,1.8757526351368379
0.03014,0.1507,1.889741443129584
0.03036,0.15180000000000002,1.903757418550346
0.03058,0.15289999999999998,1.9178010268623018
0.0308,0.154,1.9318727316279236
0.031020000000000002,0.15510000000000002,1.9459729950538869
0.03124,0.1562,1.960102277596952
0.03146,0.1573,1.9742610386149255
0.03168,0.1584,1.988449735271507
0.0319,0.15949999999999998,2.0026688235319976
0.03212,0.16060000000000002,2.0169187575672303
0.03234,0.16169999999999998,2.031199990246605
0.03256,0.1628,2.0455129724532086
0.032780000000000004,0.16390000000000002,2.0598581536061125
0.033,0.165,2.074235981706694
0.03322,0.1661,2.088646902717561
0.033440000000000004,0.16720000000000002,2.103091361225828
0.03366,0.1683,2.1175698002443997
0.03388,0.1694,2.1320826607796772
0.0341,0.17049999999999998,2.146630382440565
0.03432,0.17160000000000003,2.161213403153992
0.03454,0.1727,2.175832159075189
0.03476,0.1738,2.1904870845920765
0.034980000000000004,0.17490000000000003,2.2051786124560144
0.0352,0.17600000000000002,2.2199071738790406
0.03542,0.17709999999999998,2.234673198048119
0.03564,0.1782,2.249477112572685
0.03586,0.17930000000000001,2.2643193433626005
0.03608,0.1804,2.2792003144973
0.0363,0.1815,2.294120448295088
0.036520000000000004,0.1826,2.3090801654353754
0.03674,0.1837,2.324079884602422
0.03696,0.1848,2.3391200228871454
0.037180000000000005,0.1859,2.3542009955507512
0.0374,0.18700000000000003,2.3693232160497897
0.03762,0.1881,2.3844870960711106
0.03784,0.1892,2.3996930452941965
0.038060000000000004,0.19030000000000002,2.4149414718920497
0.03828,0.19140000000000001,2.430232781996439
0.0385,0.19249999999999998,2.445567379952623
0.038720000000000004,0.1936,2.4609456683228426
0.03894,0.1947,2.4763680477533856
0.03916,0.1958,2.4918349170185343
0.03938,0.1969,2.5073466732620644
0.0396,0.198,2.522903711398419
0.03982,0.19910000000000003,2.538506424800064
0.04004,0.2002,2.5541552046937936
0.040260000000000004,0.2013,2.569850440579312
0.04048,0.2024,2.585592520056108
0.0407,0.20350000000000001,2.6013818288191377
0.04092,0.20459999999999998,2.617218750613935
0.04114,0.2057,2.6331036673896007
0.04136,0.2068,2.6490369591617298
0.04158,0.2079,2.6650190038014587
0.041800000000000004,0.20900000000000002,2.6810501776239395
0.04202,0.2101,2.697130854719165
0.04224,0.21120000000000003,2.7132614074051573
0.042460000000000005,0.21230000000000004,2.7294422060948724
0.04268,0.2134,2.74567361911108
0.0429,0.2145,2.761956013025954
0.04312,0.2156,2.778289752224195
0.043340000000000004,0.21670000000000003,2.7946751994770236
0.04356,0.2178,2.8111127152164928
0.04378,0.21889999999999998,2.8276026582229927
0.044000000000000004,0.22,2.844145385175613
0.04422,0.22110000000000002,2.860741250837077
0.04444,0.2222,2.877390607906778
0.04466,0.22329999999999997,2.8940938072810143
0.04488,0.2244,2.9108511978475136
0.0451,0.2255,2.927663126441498
0.04532,0.2266,2.944529938044814
0.045540000000000004,0.2277,2.9614519753577095
0.04576,0.22880000000000003,2.9784295795054683
0.04598,0.2299,2.9954630894325907
0.046200000000000005,0.231,3.0125528421068823
0.04642,0.2321,3.029699172540376
0.04664,0.23320000000000002,3.046902413739223
0.04686,0.2343,3.064162896711501
0.047080000000000004,0.23540000000000003,3.0814809505177525
0.0473,0.2365,3.098856902236377
0.04752,0.2376,3.1162910769819905
0.047740000000000005,0.23870000000000002,3.1337837976875274
0.04796,0.2398,3.151335385581345
0.04818,0.24089999999999998,3.1689461597729567
0.0484,0.242,3.186616437294726
0.048620000000000003,0.2431,3.2043465333214334
0.04884,0.2442,3.222136760943189
0.04906,0.2453,3.2399874313137125
0.049280000000000004,0.24640000000000004,3.2578988537041598
0.0495,0.24750000000000003,3.2758713351850064
0.04972,0.2486,3.2939051809495132
0.049940000000000005,0.2497,3.312000694108276
0.05016,0.2508,3.3301581761056522
0.05038,0.2519,3.3483779260733146
0.0506,0.253,3.3666602411167807
0.050820000000000004,0.2541,3.385005416761373
0.05104,0.25520000000000004,3.403413746011014
0.05126,0.25630000000000003,3.4218855205115077
0.051480000000000005,0.2574,3.4404210292861306
0.0517,0.2585,3.4590205599133395
0.05192,0.2596,3.477684397626789
0.05214,0.2607,3.49641282592976
0.052360000000000004,0.26180000000000003,3.5152061262764716
0.05258,0.26289999999999997,3.534064578173771
0.0528,0.264,3.552988459201612
0.053020000000000005,0.2651,3.571978044769673
0.05324,0.2662,3.5910336085479444
0.05346,0.2673,3.6101554222275345
0.05368,0.2684,3.6293437555857073
0.0539,0.2695,3.6485988762195083
0.05412,0.2706,3.6679210501222874
0.05434,0.2717,3.6873105409908966
0.054560000000000004,0.27280000000000004,3.706767610936796
0.05478,0.27390000000000003,3.7262925198352375
0.055,0.27499999999999997,3.745885525810705
0.055220000000000005,0.2761,3.765546884986346
0.05544,0.2772,3.7852768515230735
0.05566,0.2783,3.80507567789956
0.05588,0.2794,3.8249436142811737
0.056100000000000004,0.2805,3.8448809093654166
0.05632,0.2816,3.864887809591391
0.05654,0.2827,3.884964559679794
0.056760000000000005,0.2838,3.905111402351622
0.05698,0.2849,3.925328578599093
0.0572,0.28600000000000003,3.9456163273303035
0.05742,0.28709999999999997,3.965974885600448
0.057640000000000004,0.2882,3.986404488700156
0.05786,0.2893,4.006905370021096
0.05808,0.2904,4.027477761073491
0.058300000000000005,0.29150000000000004,4.048121891319302
0.05852,0.2926,4.068837988649163
0.05874,0.29369999999999996,4.089626279010262
0.058960000000000005,0.29480000000000006,4.110486986371106
0.05918,0.2959,4.131420333062849
0.0594,0.297,4.152426539365746
0.05962,0.29810000000000003,4.173505823911515
0.059840000000000004,0.2992,4.1946584033506795
0.06006,0.3003,4.215884492615068
0.06028,0.3014,4.237184304962533
0.060500000000000005,0.3025,4.25855805148307
0.06072,0.30360000000000004,4.280005941623188
0.06094,0.3047,4.3015281833507375
0.06116,0.30579999999999996,4.323124982287089
0.061380000000000004,0.3069,4.344796542622866
0.0616,0.308,4.366543066813392
0.06182,0.3091,4.388364755379944
0.062040000000000005,0.31020000000000003,4.410261806981368
0.06226,0.31129999999999997,4.43223441884494
0.06248,0.3124,4.454282786148526
0.0627,0.31350000000000006,4.476407102546932
0.06292,0.3146,4.498607559758965
0.06314,0.31570000000000004,4.520884347895658
0.06336,0.3168,4.543237655316488
0.06358,0.31789999999999996,4.565667668596551
0.0638,0.31899999999999995,4.588174572805576
0.06402000000000001,0.3201,4.610758551103105
0.06424,0.32120000000000004,4.633419784932954
0.06446,0.32230000000000003,4.6561584542883265
0.06468,0.32339999999999997,4.678974737222478
0.0649,0.3245,4.701868810108588
0.06512,0.3256,4.72484084794705
0.06534000000000001,0.32670000000000005,4.7478910238415395
0.06556000000000001,0.32780000000000004,4.7710195092140415
0.06578,0.3289,4.794226473933877
0.066,0.33,4.817512086322153
0.06622,0.3311,4.8408765127557905
0.06644,0.3322,4.864319918413849
0.06666,0.3333,4.887842466429079
0.06688000000000001,0.33440000000000003,4.911444318692016
0.0671,0.3355,4.935125635271253
0.06732,0.3366,4.958886574729686
0.06754,0.33770000000000006,4.982727293915212
0.06776,0.3388,5.006647948401801
0.06798,0.3399,5.030648691804593
0.0682,0.34099999999999997,5.054729676511014
0.06842000000000001,0.3421,5.078891053100856
0.06864,0.34320000000000006,5.103132970924066
0.06886,0.3443,5.127455577314892
0.06908,0.3454,5.1518590185675235
0.0693,0.34650000000000003,5.176343439139361
0.06952,0.3476,5.200908982108124
0.06974,0.34869999999999995,5.225555789077965
0.06996000000000001,0.34980000000000006,5.250283999980842
0.07018,0.3509,5.275093753463795
0.0704,0.35200000000000004,5.299985186596115
0.07062,0.3531,5.32495843496226
0.07084,0.35419999999999996,5.350013632761579
0.07106,0.3553,5.37515091266612
0.07128,0.3564,5.400370405823441
0.07150000000000001,0.35750000000000004,5.425672242270762
0.07172,0.35860000000000003,5.45105655022303
0.07194,0.3597,5.476523456642819
0.07216,0.3608,5.5020730871150905
0.07238,0.3619,5.527705565805983
0.0726,0.363,5.553421015444717
0.07282,0.3641,5.579219557509323
0.07304000000000001,0.3652,5.605101311813063
0.07326,0.3663,5.631066397062964
0.07348,0.3674,5.657114930583761
0.0737,0.3685,5.683247028270381
0.07392,0.3696,5.709462804515009
0.07414,0.3707,5.735762372864997
0.07436000000000001,0.3718,5.762145844960768
0.07458000000000001,0.37290000000000006,5.788613331620343
0.0748,0.37400000000000005,5.815164941950958
0.07502,0.3751,5.841800784153578
0.07524,0.3762,5.868520964860381
0.07546,0.37729999999999997,5.895325589327041
0.07568,0.3784,5.922214761938351
0.07590000000000001,0.37950000000000006,5.949188585546194
0.07612000000000001,0.38060000000000005,5.976247161753185
0.07634,0.38170000000000004,6.003390590877316
0.07656,0.38280000000000003,6.030618972433293
0.07678,0.3839,6.057932404032261
0.077,0.38499999999999995,6.085330982420039
0.07722,0.38609999999999994,6.112814803336442
0.07744000000000001,0.3872,6.140383960940171
0.07766,0.3883000000000001,6.168038548413115
0.07788,0.3894,6.195778657839937
0.0781,0.3905,6.22360437971713
0.07832,0.3916,6.2515158039147245
0.07854,0.3927,6.279513018842622
0.07876,0.3938,6.307596111820272
0.07898000000000001,0.39490000000000003,6.335765169092955
0.0792,0.396,6.3640202757056645
0.07942,0.39710000000000006,6.3923615156121345
0.07964,0.39820000000000005,6.420788971677465
0.07986,0.3993,6.4493027256687405
0.08008,0.4004,6.477902858297289
0.0803,0.40149999999999997,6.506589449088593
0.08052000000000001,0.4026,6.5353625766256265
0.08074,0.4037,6.564222318340903
0.08096,0.4048,6.5931687506559475
0.08118,0.40590000000000004,6.622201949016464
0.0814,0.40700000000000003,6.651321987668136
0.08162,0.4081,6.680528940040297
0.08184,0.40919999999999995,6.709822878341958
0.08206000000000001,0.41030000000000005,6.739203873939969
0.08228,0.4114,6.768671997191772
0.0825,0.4125,6.798227317302959
0.08272,0.4136,6.8278699027845855
0.08294,0.4147,6.857599820882717
0.08316,0.4158,6.887417138048406
0.08338000000000001,0.41690000000000005,6.917321919811601
0.08360000000000001,0.41800000000000004,6.947314230714071
0.08382,0.41910000000000003,6.977394134428737
0.08404,0.4202,7.00756169353649
0.08426,0.42129999999999995,7.037816969907112
0.08448,0.42240000000000005,7.06816002431756
0.0847,0.4235,7.098590916932995
0.08492000000000001,0.4246000000000001,7.129109706702476
0.08514000000000001,0.4257,7.159716451933237
0.08536,0.4268,7.190411209959995
0.08558,0.4279,7.221194037352814
0.0858,0.429,7.252064989762616
0.08602,0.4301,7.283024121940055
0.08624,0.4312,7.314071488031812
0.08646000000000001,0.4323000000000001,7.345207141145625
0.08668000000000001,0.43340000000000006,7.376431133657372
0.0869,0.43450000000000005,7.407743517121022
0.08712,0.4356,7.4391443424652985
0.08734,0.4367,7.47063365953158
0.08756,0.43779999999999997,7.502211517570119
0.08778,0.43889999999999996,7.5338779651382835
0.08800000000000001,0.44,7.56563304995041
0.08822,0.44110000000000005,7.597476818935355
0.08844,0.44220000000000004,7.629409318202119
0.08866,0.4433,7.661430593522033
0.08888,0.4444,7.693540689575794
0.0891,0.44549999999999995,7.7257396502989
0.08932,0.44659999999999994,7.758027519291335
0.08954000000000001,0.4477,7.7904043391685
0.08976,0.4488,7.822870151868042
0.08998,0.4499,7.8554249987731
0.0902,0.451,7.888068920547662
0.09042,0.4521,7.920801957273945
0.09064,0.4532,7.953624148212442
0.09086,0.4543,7.986535532157527
0.09108000000000001,0.4554,8.019536147278073
0.0913,0.4565,8.05262603094756
0.09152,0.45760000000000006,8.085805220062312
0.09174,0.45870000000000005,8.119073750939712
0.09196,0.4598,8.152431659219369
0.09218,0.4609,8.18587897993436
0.09240000000000001,0.462,8.219415747825492
0.09262000000000001,0.4631,8.253041996617041
0.09284,0.4642,8.286757759787776
0.09306,0.4653,8.320563070111154
0.09328,0.46640000000000004,8.354457960091574
0.0935,0.4675,8.388442461277979
0.09372,0.4686,8.422516604969143
0.09394000000000001,0.46970000000000006,8.456680421936856
0.09416000000000001,0.47080000000000005,8.490933942353532
0.09438,0.4719,8.525277196040689
0.0946,0.473,8.559710212176459
0.09482,0.47409999999999997,8.594233019456686
0.09504,0.4752,8.62884564613651
0.09526,0.4763,8.66354812018443
0.09548000000000001,0.47740000000000005,8.698340468860483
0.09570000000000001,0.47850000000000004,8.733222719051865
0.09592,0.4796,8.768194897288092
0.09614,0.4807,8.80325702945911
0.09636,0.48179999999999995,8.838409141352528
0.09658,0.48289999999999994,8.873651258089339
0.0968,0.484,8.908983404524763
0.09702000000000001,0.4851000000000001,8.944405604878801
0.09724000000000001,0.4862,8.979917883348438
0.09746,0.4873,9.015520263398429
0.09768,0.4884,9.051212768318235
0.0979,0.4895,9.086995420952938
0.09812,0.4906,9.122868243921548
0.09834,0.4917,9.158831259197711
0.09856000000000001,0.49280000000000007,9.194884488764778
0.09878,0.49390000000000006,9.231027954014024
0.099,0.49500000000000005,9.267261676155972
0.09922,0.4961,9.303585675893471
0.09944,0.4972,9.339999973861971
0.09966,0.49829999999999997,9.376504590307578
0.09988000000000001,0.4994,9.413099545032829
0.10010000000000001,0.5005000000000001,9.449784857666103
0.10032,0.5016,9.486560547612871
0.10054,0.5027,9.523426633920101
0.10076,0.5038,9.56038313537063
0.10098,0.5049,9.597430070479273
0.1012,0.506,9.634567457560712
0.10142000000000001,0.5071,9.67179531461422
0.10164000000000001,0.5082,9.709113659571807
0.10186,0.5093,9.746522509761139
0.10208,0.5104000000000001,9.78402188271751
0.1023,0.5115000000000001,9.821611795500628
0.10252,0.5126000000000001,9.859292265009982
0.10274,0.5136999999999999,9.897063308058337
0.10296000000000001,0.5148,9.934924941066901
0.10318000000000001,0.5159,9.972877180374983
0.1034,0.517,10.01092004210971
0.10362,0.5181,10.04905354228819
0.10384,0.5192,10.087277696665684
0.10406,0.5203,10.125592520995689
0.10428,0.5214,10.163998030590088
0.10450000000000001,0.5225000000000001,10.202494240958197
0.10472000000000001,0.5236000000000001,10.241081167151144
0.10494,0.5247,10.27975882427547
0.10516,0.5257999999999999,10.31852722736256
0.10538,0.5269,10.357386391112449
0.1056,0.528,10.396336330223171
0.10582,0.5291,10.435377059380786
0.10604000000000001,0.5302,10.474508592953907
0.10626000000000001,0.5313,10.513730945363575
0.10648,0.5324,10.55304413095474
0.1067,0.5335,10.59244816387298
0.10692,0.5346,10.631943058287414
0.10714,0.5357000000000001,10.671528828252844
0.10736,0.5368,10.711205487747286
0.10758000000000001,0.5379,10.750973050768984
0.1078,0.539,10.790831531160416
0.10802,0.5401,10.830780942764184
0.10824,0.5412,10.870821299386385
0.10846,0.5423,10.910952614767748
0.10868,0.5434,10.951174902637817
0.10890000000000001,0.5445,10.991488176622514
0.10912000000000001,0.5456000000000001,11.03189245055682
0.10934,0.5467000000000001,11.072387738053806
0.10956,0.5478000000000001,11.112974052747775
0.10978,0.5489,11.15365140835072
0.11,0.5499999999999999,11.194419818450307
0.11022,0.5510999999999999,11.235279296772484
0.11044000000000001,0.5522,11.276229856982232
0.11066000000000001,0.5533,11.317271512788103
0.11088,0.5544,11.358404277875607
0.1111,0.5555,11.399628166192082
0.11132,0.5566,11.440943191291556
0.11154,0.5577,11.48234936704931
0.11176,0.5588,11.523846707486474
0.11198000000000001,0.5599000000000001,11.565435226418582
0.11220000000000001,0.561,11.607114937856243
0.11242,0.5621,11.648885855818907
0.11264,0.5632,11.690747994481235
0.11286,0.5643,11.732701367959708
0.11308,0.5654,11.774745990421643
0.1133,0.5665,11.816881876362972
0.11352000000000001,0.5676,11.859109040123471
0.11374000000000001,0.5687,11.901427496221338
0.11396,0.5698,11.943837259157478
0.11418,0.5709000000000001,11.986338343715023
0.1144,0.5720000000000001,12.028930764663862
0.11462,0.5731,12.071614536903448
0.11484,0.5741999999999999,12.114389675404516
0.11506000000000001,0.5753,12.157256195334309
0.11528000000000001,0.5764,12.20021411192523
0.1155,0.5775,12.243263440447487
0.11572,0.5786,12.286404196498411
0.11594,0.5797,12.329636395588691
0.11616,0.5808,12.372960053607162
0.11638,0.5819,12.416375186299037
0.11660000000000001,0.5830000000000001,12.45988180983009
0.11682000000000001,0.5841000000000001,12.503479940175763
0.11704,0.5852,12.547169593944606
0.11726,0.5862999999999999,12.590950787396618
0.11748,0.5873999999999999,12.634823537271112
0.1177,0.5885,12.678787860278527
0.11792000000000001,0.5896000000000001,12.722843773466348
0.11814000000000001,0.5907,12.766991293937126
0.11836,0.5918,12.811230439102218
0.11858,0.5929,12.855561226290524
0.1188,0.594,12.899983673105734
0.11902,0.5951,12.9444977975198
0.11924,0.5962000000000001,12.989103617575696
0.11946000000000001,0.5973,13.03380115128326
0.11968000000000001,0.5984,13.078590417360067
0.1199,0.5995,13.123471434138098
0.12012,0.6006,13.168444220469492
0.12034,0.6017,13.213508795475658
0.12056,0.6028,13.258665178250833
0.12078,0.6039,13.303913388029134
0.12100000000000001,0.605,13.349253444690415
0.12122000000000001,0.6061000000000001,13.394685367940648
0.12144,0.6072000000000001,13.44020917779177
0.12166,0.6083000000000001,13.485824894577778
0.12188,0.6094,13.531532538792904
0.1221,0.6104999999999999,13.577332130948879
0.12232,0.6115999999999999,13.623223692131207
0.12254000000000001,0.6127,13.669207243453377
0.12276000000000001,0.6138,13.71528280629452
0.12298,0.6149000000000001,13.761450402163723
0.1232,0.616,13.807710053061456
0.12342,0.6171,13.854061780930309
0.12364,0.6182,13.900505608231505
0.12386,0.6193,13.94704155743255
0.12408000000000001,0.6204000000000001,13.993669651318818
0.12430000000000001,0.6215,14.040389913027008
0.12452,0.6225999999999999,14.087202365730569
0.12474,0.6237,14.134107033074905
0.12496,0.6248,14.18110393883781
0.12518,0.6259000000000001,14.228193107064568
0.1254,0.6270000000000001,14.275374562008578
0.12562,0.6281,14.32264832831004
0.12584,0.6292,14.370014430770972
0.12606,0.6303,14.417472894375123
0.12628,0.6314000000000001,14.465023744602076
0.1265,0.6325000000000001,14.51266700703126
0.12672,0.6336,14.560402707439737
0.12694,0.6346999999999999,14.608230872027338
0.12716,0.6357999999999999,14.656151527264644
0.12738,0.6368999999999999,14.704164699735895
0.1276,0.6379999999999999,14.7522704164057
0.12782000000000002,0.6391000000000001,14.800468704577833
0.12804000000000001,0.6402,14.848759591556691
0.12826,0.6413000000000001,14.897143105315365
0.12848,0.6424000000000001,14.945619273790314
0.1287,0.6435000000000001,14.99418812525927
0.12892,0.6446000000000001,15.042849688401894
0.12914,0.6457,15.091603992117296
0.12936,0.6467999999999999,15.140451065490609
0.12958,0.6478999999999999,15.189390937991623
0.1298,0.649,15.238423639341836
0.13002,0.6501,15.287549199524621
0.13024,0.6512,15.336767648861475
0.13046,0.6523,15.386079017931216
0.13068000000000002,0.6534000000000001,15.435483337507085
0.13090000000000002,0.6545000000000001,15.484980638843691
0.13112000000000001,0.6556000000000001,15.534570953352468
0.13134,0.6567000000000001,15.584254312736013
0.13156,0.6578,15.634030748976476
0.13178,0.6589,15.683900294357114
0.132,0.66,15.733862981476765
0.13222,0.6611,15.783918843310563
0.13244,0.6622,15.834067912860888
0.13266,0.6633,15.884310223752596
0.13288,0.6644,15.934645809600598
0.1331,0.6655,15.985074704511261
0.13332,0.6666,16.035596942720584
0.13354,0.6677,16.086212559007027
0.13376000000000002,0.6688000000000001,16.136921588118792
0.13398000000000002,0.6699,16.187724065396772
0.1342,0.671,16.238620026246473
0.13442,0.6721,16.289609506594278
0.13464,0.6732,16.340692542303117
0.13486,0.6743,16.391869169933067
0.13508,0.6754000000000001,16.443139426005335
0.1353,0.6765,16.494503347620437
0.13552,0.6776,16.5459609719988
0.13574,0.6787,16.597512336543865
0.13596,0.6798,16.649157479289734
0.13618,0.6809,16.700896438248243
0.1364,0.6819999999999999,16.752729251843558
0.13662,0.6830999999999999,16.804655958881433
0.13684000000000002,0.6842,16.856676598137618
0.13706000000000002,0.6853000000000001,16.908791209169806
0.13728,0.6864000000000001,16.960999831414966
0.1375,0.6875000000000001,17.01330250472744
0.13772,0.6886,17.065699269424798
0.13794,0.6897,17.118190165762755
0.13816,0.6908,17.170775234489472
0.13838,0.6919,17.22345451683011
0.1386,0.6930000000000001,17.276228053914437
0.13882,0.6941,17.329095887351844
0.13904,0.6952,17.382058059156993
0.13926,0.6962999999999999,17.43511461133255
0.13948,0.6973999999999999,17.488265586391332
0.13970000000000002,0.6985000000000001,17.541511027164933
0.13992000000000002,0.6996000000000001,17.594850976614815
0.14014000000000001,0.7007,17.648285478063855
0.14036,0.7018,17.70181457497923
0.14058,0.7029000000000001,17.75543831145431
0.1408,0.7040000000000001,17.809156731457968
0.14102,0.7051000000000001,17.862969879460675
0.14124,0.7062,17.91687780014271
0.14146,0.7073,17.97088053853385
0.14168,0.7083999999999999,18.024978139894845
0.1419,0.7095,18.079170649759885
0.14212,0.7106,18.13345811386116
0.14234,0.7117,18.18784057836592
0.14256,0.7128,18.242318089659634
0.14278000000000002,0.7139000000000001,18.29689069432164
0.14300000000000002,0.7150000000000001,18.351558439139165
0.14322000000000001,0.7161000000000001,18.406321371380386
0.14344,0.7172000000000001,18.461179538539074
0.14366,0.7183,18.516132988210714
0.14388,0.7194,18.571181768401647
0.1441,0.7205,18.62632592730399
0.14432,0.7216,18.681565513392094
0.14454,0.7227,18.73690057548311
0.14476,0.7238,18.792331162547676
0.14498,0.7249,18.847857323868546
0.1452,0.726,18.903479109017326
0.14542,0.7271,18.959196567653386
0.14564,0.7282,19.015009749901726
0.14586000000000002,0.7293000000000001,19.07091870595146
0.14608000000000002,0.7304,19.12692348653304
0.1463,0.7315,19.18302414230209
0.14652,0.7326,19.239220724295105
0.14674,0.7337,19.295513283892717
0.14696,0.7348,19.35190187255088
0.14718,0.7359000000000001,19.408386542103454
0.1474,0.737,19.464967344401025
0.14762,0.7381,19.52164433192535
0.14784,0.7392,19.578417557046635
0.14806,0.7403,19.635287072593165
0.14828,0.7414,19.69225293144705
0.1485,0.7424999999999999,19.74931518684785
0.14872000000000002,0.7436,19.80647389230577
0.14894000000000002,0.7447,19.863729101412794
0.14916000000000001,0.7458000000000001,19.921080868051444
0.14938,0.7469,19.978529246357855
0.1496,0.7480000000000001,20.036074290828243
0.14982,0.7491,20.09371605593459
0.15004,0.7502,20.15145459636625
0.15026,0.7513000000000001,20.209289967302205
0.15048,0.7524,20.26722222404329
0.1507,0.7535000000000001,20.325251421892155
0.15092,0.7545999999999999,20.383377616558167
0.15114,0.7557,20.44160086395022
0.15136,0.7568,20.49992122017924
0.15158,0.7578999999999999,20.55833874165283
0.15180000000000002,0.7590000000000001,20.616853484580098
0.15202000000000002,0.7601000000000001,20.675465506108274
0.15224000000000001,0.7612000000000001,20.73417486282278
0.15246,0.7623,20.792981611973055
0.15268,0.7634000000000001,20.851885810907294
0.1529,0.7645,20.910887517132622
0.15312,0.7656000000000001,20.96998678843165
0.15334,0.7667,21.029183682588496
0.15356,0.7678,21.088478257854266
0.15378,0.7689,21.147870572481143
0.154,0.7699999999999999,21.207360684927536
0.15422,0.7711,21.266948653802697
0.15444,0.7721999999999999,21.32663453820915
0.15466,0.7733,21.386418396983093
0.15488000000000002,0.7744,21.446300289444792
0.15510000000000002,0.7755000000000001,21.506280274917405
0.15532,0.7766000000000002,21.566358413012757
0.15554,0.7777000000000001,21.62653476361405
0.15576,0.7788,21.68680938637643
0.15598,0.7799,21.74718234164172
0.1562,0.781,21.80765368960183
0.15642,0.7820999999999999,21.868223490624786
0.15664,0.7832,21.928891805338914
0.15686,0.7843000000000001,21.989658694565403
0.15708,0.7854,22.05052421918853
0.1573,0.7865,22.111488440204926
0.15752,0.7876,22.172551418952057
0.15774000000000002,0.7887000000000002,22.233713216745063
0.15796000000000002,0.7898000000000001,22.29497389515107
0.15818000000000002,0.7909,22.356333515913935
0.1584,0.792,22.417792140682465
0.15862,0.7931,22.47934983161646
0.15884,0.7942000000000001,22.54100665078859
0.15906,0.7953,22.60276266033276
0.15928,0.7964000000000001,22.664617922833937
0.1595,0.7975,22.726572500754823
0.15972,0.7986,22.78862645669274
0.15994,0.7997,22.8507798535388
0.16016,0.8008,22.91303275425849
0.16038,0.8019000000000001,22.975385221824364
0.1606,0.8029999999999999,23.037837319479387
0.16082000000000002,0.8041000000000001,23.10038911046036
0.16104000000000002,0.8052,23.163040658248804
0.16126000000000001,0.8063000000000001,23.225792026360743
0.16148,0.8074,23.28864327850525
0.1617,0.8085000000000001,23.351594478479104
0.16192,0.8096,23.41464569012461
0.16214,0.8107,23.477796977462393
0.16236,0.8118000000000001,23.541048404652525
0.16258,0.8129,23.604400035914708
0.1628,0.8140000000000001,23.667851935463876
0.16302,0.8150999999999999,23.731404167809195
0.16324,0.8162,23.795056797424913
0.16346,0.8172999999999999,23.858809888991548
0.16368,0.8183999999999999,23.92266350727147
0.16390000000000002,0.8195,23.986617716975378
0.16412000000000002,0.8206000000000001,24.05067258296417
0.16434,0.8217000000000001,24.11482817027346
0.16456,0.8228,24.179084544122357
0.16478,0.8239000000000001,24.243441769480626
0.165,0.825,24.307899911655497
0.16522,0.8261000000000001,24.3724590360296
0.16544,0.8272,24.43711920803125
0.16566,0.8283,24.501880492943947
0.16588,0.8294,24.56674295646858
0.1661,0.8304999999999999,24.631706664190997
0.16632,0.8316,24.696771681918253
0.16654,0.8326999999999999,24.761938075131653
0.16676000000000002,0.8338000000000001,24.827205909858368
0.16698000000000002,0.8349,24.89257525205842
0.16720000000000002,0.8360000000000001,24.958046167487996
0.16742,0.8371000000000002,25.023618722275234
0.16764,0.8382000000000001,25.089292982488036
0.16786,0.8393,25.155069014146378
0.16808,0.8404,25.220946883429786
0.1683,0.8415,25.286926656612536
0.16852,0.8425999999999999,25.353008399977924
0.16874,0.8437,25.419192179842504
0.16896,0.8448000000000001,25.48547806252028
0.16918,0.8459,25.551866114392716
0.1694,0.847,25.61835640193302
0.16962,0.8481,25.684948991621706
0.16984000000000002,0.8492000000000002,25.751643949902654
0.17006000000000002,0.8503000000000001,25.818441343422812
0.17028000000000001,0.8514,25.885341238796794
0.1705,0.8525,25.95234370247766
0.17072,0.8536,26.019448801187636
0.17094,0.8547000000000001,26.086656601465187
0.17116,0.8558,26.1539671701489
0.17138,0.8569000000000001,26.22138057391047
0.1716,0.858,26.288896879387632
0.17182,0.8591,26.356516153394985
0.17204,0.8602,26.42423846259791
0.17226,0.8613,26.49206387383911
0.17248,0.8624,26.559992453831487
0.1727,0.8634999999999999,26.62802426953499
0.17292000000000002,0.8646000000000001,26.696159387423815
0.17314000000000002,0.8657,26.764397874645145
0.17336000000000001,0.8668000000000001,26.832739797701166
0.17358,0.8679,26.90118522354618
0.1738,0.8690000000000001,26.969734218919143
0.17402,0.8701,27.038386850686578
0.17424,0.8712,27.10714318553574
0.17446,0.8723000000000001,27.176003290305086
0.17468,0.8734,27.24496723176748
0.1749,0.8745,27.31403507673022
0.17512,0.8755999999999999,27.383206891915876
0.17534,0.8767,27.452482744078587
0.17556,0.8777999999999999,27.521862699818527
0.17578000000000002,0.8789000000000001,27.591346825981596
0.17600000000000002,0.88,27.66093518915866
0.17622000000000002,0.8811000000000001,27.730627856028146
0.17644,0.8822000000000001,27.800424893248383
0.17666,0.8833,27.870326367366353
0.17688,0.8844000000000001,27.94033234512597
0.1771,0.8855,28.01044289286805
0.17732,0.8866,28.080658077193387
0.17754,0.8876999999999999,28.150977964646287
0.17776,0.8888,28.221402621628155
0.17798,0.8899,28.29193211455784
0.1782,0.8909999999999999,28.362566509771817
0.17842,0.8921,28.43330587365355
0.17864,0.8931999999999999,28.50415027249507
0.17886000000000002,0.8943000000000001,28.575099772519394
0.17908000000000002,0.8954,28.64615443994441
0.17930000000000001,0.8965000000000001,28.717314340975783
0.17952,0.8976,28.788579541591947
0.17974,0.8987,28.85995010791695
0.17996,0.8998,28.931426105961684
0.18018,0.9009,29.00300760165702
0.1804,0.902,29.074694661004987
0.18062,0.9030999999999999,29.146487349652904
0.18084,0.9042,29.21838573355306
0.18106,0.9053000000000001,29.290389878241225
0.18128,0.9064,29.362499849468858
0.1815,0.9075,29.434715712814906
0.18172,0.9086,29.507037533738796
0.18194000000000002,0.9097000000000002,29.57946537786425
0.18216000000000002,0.9108,29.65199931035831
0.18238000000000001,0.9119,29.724639396663193
0.1826,0.913,29.797385701986055
0.18282,0.9141,29.870238291500527
0.18304,0.9152000000000001,29.943197230286994
0.18326,0.9163,30.016262583323826
0.18348,0.9174000000000001,30.089434415652352
0.1837,0.9185,30.162712792019946
0.18392,0.9196,30.236097777193464
0.18414,0.9207,30.309589435994692
0.18436,0.9218,30.383187832838367
0.18458,0.9229,30.456893032284256
0.18480000000000002,0.924,30.53070509893914
0.18502000000000002,0.9251000000000001,30.6046240969928
0.18524000000000002,0.9262,30.678650090695864
0.18546,0.9273000000000001,30.75278314424197
0.18568,0.9284,30.827023321702583
0.1859,0.9295000000000001,30.901370687017696
0.18612,0.9306,30.975825304069755
0.18634,0.9317,31.050387236685694
0.18656,0.9328000000000001,31.125056548443283
0.18678,0.9339,31.199833303012188
0.187,0.935,31.274717563752304
0.18722,0.9360999999999999,31.34970939414464
0.18744,0.9372,31.42480885740995
0.18766,0.9382999999999999,31.500016016696677
0.18788000000000002,0.9394000000000001,31.575330935118544
0.18810000000000002,0.9405,31.650753675523344
0.18832000000000002,0.9416000000000001,31.726284300768313
0.18854,0.9427000000000001,31.80192287367983
0.18876,0.9438,31.87766945673798
0.18898,0.9449000000000001,31.95352411248207
0.1892,0.946,32.02948690331338
0.18942,0.9471,32.10555789161303
0.18964,0.9481999999999999,32.1817371392336
0.18986,0.9493,32.25802470848572
0.19008,0.9504,32.33442066109734
0.1903,0.9514999999999999,32.410925058956984
0.19052,0.9526,32.48753796375821
0.19074000000000002,0.9537000000000001,32.56425943690268
0.19096000000000002,0.9548000000000001,32.64108954000504
0.19118000000000002,0.9559,32.71802833423614
0.19140000000000001,0.9570000000000001,32.795075880740136
0.19162,0.9581,32.872232240641196
0.19184,0.9592,32.94949747474747
0.19206,0.9603,33.026871643984954
0.19228,0.9614,33.104354808908504
0.1925,0.9625,33.18194703002891
0.19272,0.9635999999999999,33.259648367689685
0.19294,0.9647,33.337458882308674
0.19316,0.9657999999999999,33.41537863378118
0.19338,0.9669,33.493407682317375
0.1936,0.968,33.57154608759729
0.19382000000000002,0.9691000000000001,33.64979390934933
0.19404000000000002,0.9702000000000002,33.728151207091045
0.19426000000000002,0.9713,33.80661804039581
0.19448000000000001,0.9724,33.885194468427116
0.1947,0.9735,33.96388055033235
0.19492,0.9746,34.04267634519821
0.19514,0.9757000000000001,34.12158191176414
0.19536,0.9768,34.20059730875755
0.19558,0.9779000000000001,34.27972259481186
0.1958,0.979,34.35895782828174
0.19602,0.9801,34.43830306746249
0.19624,0.9812,34.51775837047889
0.19646,0.9823,34.597323795289824
0.19668,0.9834,34.67699939974629
0.19690000000000002,0.9845,34.75678524135207
0.19712000000000002,0.9856000000000001,34.83668137791883
0.19734000000000002,0.9867,34.91668786646735
0.19756,0.9878000000000001,34.996804764494144
0.19778,0.9889,35.0770321290108
0.198,0.9900000000000001,35.15737001682829
0.19822,0.9911,35.23781848462049
0.19844,0.9922,35.31837758919164
0.19866,0.9933000000000001,35.399047386774576
0.19888,0.9944,35.479827933751174
0.1991,0.9955,35.56071928626744
0.19932,0.9965999999999999,35.64172150017412
0.19954,0.9977,35.722834631344
0.19976000000000002,0.9988,35.804058735387194
0.19998000000000002,0.9999000000000001,35.885393867783954
0.20020000000000002,1.,35.85247883236379
0.20042000000000001,1.,35.80843655531693
0.20064,1.,35.76471991144409
0.20086,1.,35.72132416177507
0.20108,1.,35.67824467989423
0.2013,1.,35.635476948041706
0.20152,1.,35.59301655383955
0.20174,1.,35.550859186738904
0.20196,1.,35.509000634706965
0.20218,1.,35.4674367811871
0.2024,1.,35.4261636017383
0.20262,1.,35.38517716167859
0.20284000000000002,1.,35.34447361282353
0.20306000000000002,1.,35.30404919099583
0.20328000000000002,1.,35.263900213408704
0.20350000000000001,1.,35.224023076203416
0.20372,1.,35.1844142520676
0.20394,1.,35.14507028792028
0.20416,1.,35.10598780280602
0.20438,1.,35.067163485490454
0.2046,1.,35.02859409270952
0.20482,1.,34.99027644701756
0.20504,1.,34.952207435220025
0.20526,1.,34.914384005984964
0.20548,1.,34.87680316845252
0.2057,1.,34.83946199061794
0.20592000000000002,1.,34.80235759733488
0.20614000000000002,1.,34.76548716901273
0.20636000000000002,1.,34.72884794012206
0.20658,1.,34.69243719751598
0.2068,1.,34.656252279207756
0.20702,1.,34.6202905727347
0.20724,1.,34.58454951411653
0.20746,1.,34.549026586451674
0.20768,1.,34.5137193187363
0.2079,1.,34.47862528452306
0.20812,1.,34.443742100967945
0.20834,1.,34.40906742748457
0.20856,1.,34.374598964908294
0.20878000000000002,1.,34.340334454318175
0.20900000000000002,1.,34.30627167586918
0.20922000000000002,1.,34.27240844835986
0.20944000000000002,1.,34.23874262747049
0.20966,1.,34.2052721055782
0.20988,1.,34.17199481042087
0.2101,1.,34.1389087045492
0.21032,1.,34.10601178419211
0.21054,1.,34.0733020785645
0.21076,1.,34.04077764926942
0.21098,1.,34.0084365894036
0.2112,1.,33.97627702251608
0.21142,1.,33.944297102408875
0.21164,1.,33.912495012258226
0.21186000000000002,1.,33.880868963681195
0.21208000000000002,1.,33.8494171965838
0.21230000000000002,1.,33.818137977888114
0.21252000000000001,1.,33.78702960160986
0.21274,1.,33.75609038776834
0.21296,1.,33.72531868205179
0.21318,1.,33.694712855086586
0.2134,1.,33.66427130204225
0.21362,1.,33.63399244201501
0.21384,1.,33.60387471745682
0.21406,1.,33.57391659395023
0.21428,1.,33.54411655928791
0.2145,1.,33.514473123420885
0.21472,1.,33.484984817755354
0.21494000000000002,1.,33.45565019458778
0.21516000000000002,1.,33.426467827155676
0.21538000000000002,1.,33.39743630876316
0.2156,1.,33.36855425246474
0.21582,1.,33.339820290639494
0.21604,1.,33.31123307481255
0.21626,1.,33.282791275124
0.21648,1.,33.254493579864864
0.2167,1.,33.22633869526075
0.21692,1.,33.19832534510307
0.21714,1.,33.17045227035709
0.21736,1.,33.142718228845986
0.21758,1.,33.115121994948865
0.21780000000000002,1.,33.087662359179696
0.21802000000000002,1.,33.06033812816741
0.21824000000000002,1.,33.03314812393308
0.21846000000000002,1.,33.006091183885715
0.21868,1.,32.97916616053254
0.2189,1.,32.95237192115582
0.21912,1.,32.925707347377916
0.21934,1.,32.89917133512451
0.21956,1.,32.87276279427758
0.21978,1.,32.846480648389594
0.22,0.,0.